Workbook
Name AddDependent_DateOfBirth: Test_Data!#REF!
Name AddDependent_EffectiveDate: Test_Data!#REF!
Name AddDependent_Gender: Test_Data!#REF!
Name AddDependent_GivenName: Test_Data!#REF!
Name AddDependent_LastName: Test_Data!#REF!
Name AddDependent_LivesWithWorker: Test_Data!#REF!
Name AddDependent_LivingWithWorkerEffectiveDate: Test_Data!#REF!
Name AddDependent_NationalIDCountry: Test_Data!#REF!
Name AddDependent_NationalIDType: Test_Data!#REF!
Name AddDependent_Relationship: Test_Data!#REF!
Name AddProbationPeriod_ProbationEndDate: Test_Data!$E$38
Name AddProbationPeriod_ProbationEndDate2: Automation_Lookups!$AN$2:$AN$4
Name AssignCollectiveAgreement_CollectiveAgreement: Test_Data!$E$51
Name AssignCollectiveAgreement_Level: Test_Data!$E$53
Name AssignCollectiveAgreement_ProfessionalCategory: Test_Data!$E$52
Name AssignPayGroup_ProposedPayGroup: Test_Data!$E$36
Name AssignPayGroup_ProposedPayGroup: Automation_Lookups!$T$2:$T$20
Name AssignPayGroup_ProposedPayGroup2: Automation_Lookups!$T$2
Name AssignPayGroup_ProposedPayGroupFinal: Test_Data!$E$37
Name AssignPayGroup_ProposedPayGroupInitial: Test_Data!$E$36
Name Automation_Ref: Test_Data!$G$13:$H$13
Name AutomationComments: Test_Data!$E$10
Name ChangeMyEmergencyContacts_City: Test_Data!#REF!
Name ChangeMyEmergencyContacts_EmailAddress: Test_Data!#REF!
Name ChangeMyEmergencyContacts_FamilyName: Test_Data!#REF!
Name ChangeMyEmergencyContacts_GivenName: Test_Data!#REF!
Name ChangeMyEmergencyContacts_PhoneDevice: Test_Data!#REF!
Name ChangeMyEmergencyContacts_PhoneDevice2: Automation_Lookups!$AJ$2:$AJ$3
Name ChangeMyEmergencyContacts_PhoneNumber: Test_Data!#REF!
Name ChangeMyEmergencyContacts_PostalCode: Test_Data!#REF!
Name ChangeMyEmergencyContacts_Relationship: Test_Data!#REF!
Name ChangeMyEmergencyContacts_Relationship2: Automation_Lookups!$AI$2:$AI$5
Name ChangeMyEmergencyContacts_StreetName: Test_Data!#REF!
Name ChangeMyGovernmentIDs_NationalIDs_AddEditID: Test_Data!#REF!
Name ChangeMyGovernmentIDs_NationalIDs_AddEditID1: Test_Data!#REF!
Name ChangeMyGovernmentIDs_NationalIDs_AddEditID2: Test_Data!#REF!
Name ChangeMyGovernmentIDs_NationalIDs_AddEditID3: Test_Data!#REF!
Name ChangeMyGovernmentIDs_NationalIDs_Country1: Test_Data!#REF!
Name ChangeMyGovernmentIDs_NationalIDs_Country2: Test_Data!#REF!
Name ChangeMyGovernmentIDs_NationalIDs_Country3: Test_Data!#REF!
Name ChangeMyGovernmentIDs_NationalIDs_NationalIDType1: Test_Data!#REF!
Name ChangeMyGovernmentIDs_NationalIDs_NationalIDType12: Automation_Lookups!$AT$2
Name ChangeMyGovernmentIDs_NationalIDs_NationalIDType2: Test_Data!#REF!
Name ChangeMyGovernmentIDs_NationalIDs_NationalIDType2: Automation_Lookups!$AK$2:$AK$4
Name ChangeMyGovernmentIDs_NationalIDs_NationalIDType22: Automation_Lookups!$AU$2
Name ChangeMyGovernmentIDs_NationalIDs_NationalIDType3: Test_Data!#REF!
Name ChangeMyPersonalInformation_CitizenshipStatus: Test_Data!#REF!
Name ChangeMyPersonalInformation_CityOfBirth: Test_Data!#REF!
Name ChangeMyPersonalInformation_CountryTerritoryOfBirth: Test_Data!#REF!
Name ChangeMyPersonalInformation_DateOfBirth: Test_Data!#REF!
Name ChangeMyPersonalInformation_Gender: Test_Data!#REF!
Name ChangeMyPersonalInformation_MaritalStatus: Test_Data!#REF!
Name ChangeMyPersonalInformation_MaritalStatus2: Automation_Lookups!$AH$2:$AH$4
Name ChangeMyPersonalInformation_MaritalStatusDate: Test_Data!#REF!
Name ChangeMyPersonalInformation_PrimaryNationality: Test_Data!#REF!
Name ChangeMyPersonalInformation_RegionOfBirth: Test_Data!#REF!
Name ChangeOrganizationAssignments_CostCenter: Test_Data!$E$34
Name ChangeOrganizationAssignments_DepartmentSection: Test_Data!$E$35
Name ChangeOrganizationAssignments_DepartmentSection2: Automation_Lookups!$S$2
Name ChangeOrganizationAssignments_Other_Organizations: Test_Data!$E$35

Sheet Information
A1: Version | F1: Info
A6: Version | B6: 0.3 | F6: Info
F7: Dates | G7: For Czech all dates to be entered in format of DD/MM/YYYY
A8: History | F8: Unhighlighted fields | G8: Only data in unhighlighted fields can be changed.
A9: Date | B9: Version | C9: Details | F9: Red highlighted fields | G9: Indicates fields where unique data is required otherwise automation will throw errors
A10: 44061 | B10: 0.3 | C10: Initial Release | F10: Grey highlighted fields | G10: Indicates fields that cannot be changed
F11: Last Run Status / Last Run Error Message | G11: When automation has run for a particular test, we need to check the status is set to Passed and no error messages are present for each test before the automation run for that particular test is considered valid

Sheet Test_Data
A1: Version_Number | C1: Test_ID | D1: =SUBSTITUTE(C1," ","") -> Test_ID | E1: =D1&2 -> Test_ID2 | F1: Notes | G1: Test_1 | H1: Test_2 | I1: Test_3 | J1: Test_4 | K1: Test_5 | L1: Test_6 | M1: Test_7 | N1: Test_8 | O1: Test_9 | P1: Test_10 | Q1: Test_11 | R1: Test_12 | S1: Test_13 | T1: Test_14
A2: =Information!B6 -> 0.3 | C2: Reporting_ID | G2: 1 | H2: 2 | I2: 3 | J2: 4 | K2: 5 | L2: 6 | M2: 7 | N2: 8 | O2: 9 | P2: 10 | Q2: 11 | R2: 12 | S2: 13 | T2: 14
C3: Process | D3: =SUBSTITUTE(C3," ","") -> Process | E3: =D3&2 -> Process2 | F3: If a manager hire and new role is required then select "New Role and New Hire" otherwise select "New Hire | G3: ReHire | H3: ReHireManagerNewRole | I3: ReHireManagerNewRole | J3: ReHireManagerNewRole | K3: ReHireManagerNewRole | L3: ReHire | M3: ReHire | N3: ReHire | O3: ReHire | P3: ReHire | Q3: ReHire | R3: ReHire | S3: ReHire | T3: ReHire
C4: Execution Flag | D4: =SUBSTITUTE(C4," ","") -> ExecutionFlag | E4: =D4&2 -> ExecutionFlag2 | F4: If set to No will not execute in next automation run | G4: No | H4: No | I4: No | J4: No | K4: No | L4: No | M4: No | N4: No | O4: No | P4: No | Q4: No | R4: No | S4: No | T4: No
C5: Country Name | D5: =SUBSTITUTE(C5," ","") -> CountryName | E5: =D5&2 -> CountryName2 | F5: Name of Country | G5: Italy | H5: Italy | I5: Italy | J5: Italy | K5: Italy | L5: Italy | M5: Italy | N5: Italy | O5: Italy | P5: Italy | Q5: Italy | R5: Italy | S5: Italy | T5: Italy
C6: Last Run Time and Status | D6: =SUBSTITUTE(C6," ","") -> LastRunTimeandStatus | E6: =D6&2 -> LastRunTimeandStatus2 | F6: Once test is executed the Execution Timestamp and Pass/Fail status will be recorded here | G6: 12/09/2023 16:11:23 Passed | H6: 12/09/2023 17:49:35 Passed | I6: 13/09/2023 16:36:26 Passed | J6: 13/09/2023 16:59:39 Passed | K6: 13/09/2023 17:27:31 Passed | L6: 13/09/2023 17:48:07 Passed
C7: Last Run Employee No | D7: =SUBSTITUTE(C7," ","") -> LastRunEmployeeNo | E7: =D7&2 -> LastRunEmployeeNo2 | F7: The newly created employee number will be recorded here
C8: Last Run Error Message | D8: =SUBSTITUTE(C8," ","") -> LastRunErrorMessage | E8: =D8&2 -> LastRunErrorMessage2 | F8: If Automation throws errors, the details will be placed here
C9: Defect Description | D9: =SUBSTITUTE(C9," ","") -> DefectDescription | E9: =D9&2 -> DefectDescription2 | F9: After error investigation by the automation team, the defect description will be completed here
C10: Automation Comments | D10: =SUBSTITUTE(C10," ","") -> AutomationComments | E10: =D10&2 -> AutomationComments2 | F10: Automation team free text field
C11: QA Comments | D11: =SUBSTITUTE(C11," ","") -> QAComments | E11: =D11&2 -> QAComments2 | F11: QA team free text field
A13: Screen | B13: Subscreen | C13: Field | D13: Automation Ref | E13: Lookups Ref | F13: Notes | G13: Test_1 | H13: Test_2 | I13: Test_3 | J13: Test_4 | K13: Test_5 | L13: Test_6 | M13: Test_7 | N13: Test_8 | O13: Test_9 | P13: Test_10 | Q13: Test_11 | R13: Test_12 | S13: Test_13 | T13: Test_14
A14: Login | B14: N/A | C14: Username | D14: =SUBSTITUTE(A14," ","") & "_" & SUBSTITUTE(IF(B14="N/A","",B14& "_")," ","") & SUBSTITUTE(SUBSTITUTE(C14," ",""),"/","") -> Login_Username | E14: =D14&2 -> Login_Username2 | F14: QA user login | G14: 90002195 | H14: 90002195 | I14: 90002195 | J14: 90002195 | K14: 90002195 | L14: 90002195 | M14: 90002195 | N14: 90002195 | O14: 90002195 | P14: 90002195 | Q14: 90002195 | R14: 90002195 | S14: 90002195 | T14: 90002195
A15: Login | B15: N/A | C15: Password | D15: =SUBSTITUTE(A15," ","") & "_" & SUBSTITUTE(IF(B15="N/A","",B15& "_")," ","") & SUBSTITUTE(SUBSTITUTE(C15," ",""),"/","") -> Login_Password | E15: =D15&2 -> Login_Password2 | F15: QA user password | G15: 64a53c105ef2508b54fb94a01614a7a95ca737c20871822818d65cfc | H15: 64a53c105ef2508b54fb94a01614a7a95ca737c20871822818d65cfc | I15: 64a53c105ef2508b54fb94a01614a7a95ca737c20871822818d65cfc | J15: 64a53c105ef2508b54fb94a01614a7a95ca737c20871822818d65cfc | K15: 64a53c105ef2508b54fb94a01614a7a95ca737c20871822818d65cfc | L15: 64a53c105ef2508b54fb94a01614a7a95ca737c20871822818d65cfc | M15: 64a53c105ef2508b54fb94a01614a7a95ca737c20871822818d65cfc | N15: 64a53c105ef2508b54fb94a01614a7a95ca737c20871822818d65cfc | O15: 64a53c105ef2508b54fb94a01614a7a95ca737c20871822818d65cfc | P15: 64a53c105ef2508b54fb94a01614a7a95ca737c20871822818d65cfc | Q15: 64a53c105ef2508b54fb94a01614a7a95ca737c20871822818d65cfc | R15: 64a53c105ef2508b54fb94a01614a7a95ca737c20871822818d65cfc | S15: 64a53c105ef2508b54fb94a01614a7a95ca737c20871822818d65cfc | T15: 64a53c105ef2508b54fb94a01614a7a95ca737c20871822818d65cfc
A16: Legal Name Information | B16: N/A | C16: Country | D16: LegalNameInformation_Country | E16: LegalNameInformation_Country2 | F16: Test country to be placed here | G16: Italy | H16: Italy | I16: Italy | J16: Italy | K16: Italy | L16: Italy | M16: Italy | N16: Italy | O16: Italy | P16: Italy | Q16: Italy | R16: Italy | S16: Italy | T16: Italy
A17: Legal Name Information | B17: N/A | C17: Given Name | D17: LegalNameInformation_GivenName | E17: LegalNameInformation_GivenName2 | F17: Automation will throw error if not unique | G17: ItalyManagedFour | H17: ItalyNonManagedFive | I17: ItalyIDMTestD | J17: ItalyNonMKABB | K17: ItalyManagedABB | L17: ItalyNonMKAXY | M17: HireSevenAP | N17: HireEightAP | O17: HireNineAP | P17: HireTenAP | Q17: HireElevenAP | R17: HireTwelveAP | S17: HireSixteenAP | T17: HireFourteenAP
A18: Legal Name Information | B18: N/A | C18: First Last Name | D18: LegalNameInformation_FirstLastName | E18: LegalNameInformation_FirstLastName2 | F18: Automation will throw error if not unique | G18: =G19 -> TestJmnu | H18: =H19 -> Brennnan | I18: TestJmnu | J18: Brennnan | K18: TestJmnu | L18: Brennnan | M18: Brennnan | N18: TestJmnu | O18: BrennnanKK | P18: TestJmnuKK | Q18: ItalyMK | R18: ItalyMK | S18: ItalyMK | T18: ItalyMK
A19: Legal Name Information | B19: N/A | C19: Family Name | D19: LegalNameInformation_FamilyName | E19: LegalNameInformation_FamilyName2 | F19: Automation will throw error if not unique | G19: TestJmnu | H19: Brennnan | I19: TestJmnu | J19: Brennnan | K19: TestJmnu | L19: Brennnan | M19: Brennnan | N19: TestJmnu | O19: BrennnanKK | P19: TestJmnuKK | Q19: ItalyMK | R19: ItalyMK | S19: ItalyMK | T19: ItalyMK | U19: ItalyMK | V19: ItalyMK | W19: ItalyMK | X19: ItalyMK | Y19: ItalyMK | Z19: ItalyMK | AA19: ItalyMK
A20: Supervisory Organisation | B20: N/A | C20: Supervisory Organisation | D20: =SUBSTITUTE(A20," ","") & "_" & SUBSTITUTE(IF(B20="N/A","",B20& "_")," ","") & SUBSTITUTE(SUBSTITUTE(C20," ",""),"/","") -> SupervisoryOrganisation_SupervisoryOrganisation | E20: =D20&2 -> SupervisoryOrganisation_SupervisoryOrganisation2 | G20: 275 Recruitment (Jacok Sozeto (10196188)) | H20: 275 AM Group 1 (Tucev Rypafe (10144587) (Inherited)) | I20: 275 AM Group 1 (Tucev Rypafe (10144587) (Inherited)) | J20: 275 AM Group 1 (Tucev Rypafe (10144587) (Inherited)) | K20: 275 AM Group 1 (Tucev Rypafe (10144587) (Inherited)) | L20: 275 Recruitment (Jacok Sozeto (10196188)) | M20: 870 Retail Team 1 (Cofuc Jajuhi (9581610) (Inherited)) | N20: 275 Recruitment (Jacok Sozeto (10196188)) | O20: 870 Retail Team 1 (Cofuc Jajuhi (9581610) (Inherited)) | P20: 870 Retail Team 1 (Cofuc Jajuhi (9581610) (Inherited)) | Q20: 870 Retail Team 1 (Cofuc Jajuhi (9581610) (Inherited)) | R20: 870 Retail Team 1 (Cofuc Jajuhi (9581610) (Inherited)) | S20: 870 Retail Team 1 (Cofuc Jajuhi (9581610) (Inherited)) | T20: 870 Retail Team 1 (Cofuc Jajuhi (9581610) (Inherited))
A21: Supervisory Organisation | B21: N/A | C21: Existing PreHire | D21: =SUBSTITUTE(A21," ","") & "_" & SUBSTITUTE(IF(B21="N/A","",B21& "_")," ","") & SUBSTITUTE(SUBSTITUTE(C21," ",""),"/","") -> SupervisoryOrganisation_ExistingPreHire | E21: =D21&2 -> SupervisoryOrganisation_ExistingPreHire2 | F21: Existing PreHire Name to be placed here | G21: =G17&" "&G18 -> ItalyManagedFour TestJmnu | H21: =H17&" "&H18 -> ItalyNonManagedFive Brennnan | I21: =I17&" "&I18 -> ItalyIDMTestD TestJmnu | J21: =J17&" "&J18 -> ItalyNonMKABB Brennnan | K21: =K17&" "&K18 -> ItalyManagedABB TestJmnu | L21: =L17&" "&L18 -> ItalyNonMKAXY Brennnan | M21: =M17&" "&M18 -> HireSevenAP Brennnan | N21: =N17&" "&N18 -> HireEightAP TestJmnu | ... T21: =T17&" "&T18 -> HireFourteenAP ItalyMK
A22: Job Details | B22: N/A | C22: Hire Date | D22: =SUBSTITUTE(A22," ","") & "_" & SUBSTITUTE(IF(B22="N/A","",B22& "_")," ","") & SUBSTITUTE(SUBSTITUTE(C22," ",""),"/","") -> JobDetails_HireDate | E22: =D22&2 -> JobDetails_HireDate2 | G22: =TODAY() -> 45182 | H22: =TODAY() -> 45182 | I22: =TODAY() -> 45182 | J22: =TODAY() -> 45182 | K22: =TODAY() -> 45182 | L22: =TODAY() -> 45182 | M22: =TODAY() -> 45182 | N22: =TODAY() -> 45182 | ... T22: =TODAY() -> 45182
A23: Job Details | B23: N/A | C23: Reason | D23: =SUBSTITUTE(A23," ","") & "_" & SUBSTITUTE(IF(B23="N/A","",B23& "_")," ","") & SUBSTITUTE(SUBSTITUTE(C23," ",""),"/","") -> JobDetails_Reason | E23: =D23&2 -> JobDetails_Reason2 | G23: ReHire | H23: ReHire | I23: ReHire | J23: ReHire | K23: ReHire | L23: ReHire | M23: ReHire | N23: ReHire | O23: ReHire | P23: ReHire | Q23: ReHire | R23: ReHire | S23: ReHire | T23: ReHire
A24: Job Details | B24: N/A | C24: Position | D24: =SUBSTITUTE(A24," ","") & "_" & SUBSTITUTE(IF(B24="N/A","",B24& "_")," ","") & SUBSTITUTE(SUBSTITUTE(C24," ",""),"/","") -> JobDetails_Position | E24: =D24&2 -> JobDetails_Position2 | F24: If Process is set to "New Role and New Hire" (Row 2) this position name will be ignored and replaced with the newly created name. | G24: No | H24: Auto 12092023 172248 | I24: Auto 13092023 161854 | J24: Auto 13092023 164313 | K24: Auto 13092023 171337 | L24: No | M24: No | N24: No | O24: No | P24: No | Q24: No | R24: No | S24: No | T24: No
A25: Job Details | B25: N/A | C25: Employee Type | D25: =SUBSTITUTE(A25," ","") & "_" & SUBSTITUTE(IF(B25="N/A","",B25& "_")," ","") & SUBSTITUTE(SUBSTITUTE(C25," ",""),"/","") -> JobDetails_EmployeeType | E25: =D25&2 -> JobDetails_EmployeeType2 | F25: If Fixed Term ensure contract end date below is populated and not N/A | G25: Permanent | H25: Fixed Term | I25: Fixed Term | J25: Permanent | K25: Permanent | L25: Fixed Term | M25: Permanent | N25: Permanent | O25: Permanent | P25: Agreement | Q25: Permanent | R25: Fixed Term | S25: Permanent | T25: Fixed Term
A26: Job Details | B26: N/A | C26: Job Profile | D26: =SUBSTITUTE(A26," ","") & "_" & SUBSTITUTE(IF(B26="N/A","",B26& "_")," ","") & SUBSTITUTE(SUBSTITUTE(C26," ",""),"/","") -> JobDetails_JobProfile | E26: =D26&2 -> JobDetails_JobProfile2 | G26: Retail Assistant | H26: Assistant Manager | I26: Assistant Manager | J26: Assistant Manager | K26: Assistant Manager | L26: Retail Assistant | M26: Retail Assistant_New | N26: Retail Assistant | O26: Retail Assistant Stockroom_NEW | P26: Retail Assistant Special Contracts_NEW | Q26: In-Store P&C Supervisor_NEW | R26: In-Store P&C Assistant_NEW | S26: Visual Merchandiser_NEW | T26: Operational Support_NEW
A27: Job Details | B27: N/A | C27: Time Type | D27: =SUBSTITUTE(A27," ","") & "_" & SUBSTITUTE(IF(B27="N/A","",B27& "_")," ","") & SUBSTITUTE(SUBSTITUTE(C27," ",""),"/","") -> JobDetails_TimeType | E27: =D27&2 -> JobDetails_TimeType2 | G27: Full Time | H27: Full Time | I27: Full Time | J27: Full Time | K27: Full Time | L27: Full Time | M27: Full Time | N27: Full Time | O27: Part Time | P27: Full Time | Q27: Full Time | R27: Full Time | S27: Part Time | T27: Part Time
A28: Job Details | B28: N/A | C28: Location | D28: =SUBSTITUTE(A28," ","") & "_" & SUBSTITUTE(IF(B28="N/A","",B28& "_")," ","") & SUBSTITUTE(SUBSTITUTE(C28," ",""),"/","") -> JobDetails_Location | E28: =D28&2 -> JobDetails_Location2 | G28: 275 | H28: 275 | I28: 275 | J28: 275 | K28: 275 | L28: 275 | M28: 870 | N28: 275 | O28: 870 | P28: 870 | Q28: 870 | R28: 870 | S28: 870 | T28: 870
A29: Job Details | B29: Additional Information | C29: Scheduled Weekly Hours | D29: =SUBSTITUTE(A29," ","") & "_" & SUBSTITUTE(IF(B29="N/A","",B29& "_")," ","") & SUBSTITUTE(SUBSTITUTE(C29," ",""),"/","") -> JobDetails_AdditionalInformation_ScheduledWeeklyHours | E29: =D29&2 -> JobDetails_AdditionalInformation_ScheduledWeeklyHours2 | G29: 40 | H29: 40 | I29: 40 | J29: 40 | K29: 40 | L29: 40 | M29: 38.75 | N29: 40 | O29: 25 | P29: 38.75 | Q29: 38.75 | R29: 38.75 | S29: 25 | T29: 20
A30: Job Details | B30: Additional Information | C30: Additional Job Classifications | D30: =SUBSTITUTE(A30," ","") & "_" & SUBSTITUTE(IF(B30="N/A","",B30& "_")," ","") & SUBSTITUTE(SUBSTITUTE(C30," ",""),"/","") -> JobDetails_AdditionalInformation_AdditionalJobClassifications | E30: =D30&2 -> JobDetails_AdditionalInformation_AdditionalJobClassifications2 | G30: 1@661 | H30: 1@661 | I30: 1@661 | J30: 1@661 | K30: 1@661 | L30: 1@661 | M30: 2 - 2 (Italy Degree of Labour Difficulty-Italy)@5249999 | N30: 1@661 | O30: 2 - 2 (Italy Degree of Labour Difficulty-Italy)@5249999 | P30: 2 - 2 (Italy Degree of Labour Difficulty-Italy)@5249999 | Q30: 2 - 2 (Italy Degree of Labour Difficulty-Italy)@5249999 | R30: 2 - 2 (Italy Degree of Labour Difficulty-Italy)@5249999 | S30: 2 - 2 (Italy Degree of Labour Difficulty-Italy)@5249999 | T30: 2 - 2 (Italy Degree of Labour Difficulty-Italy)@5249999
A31: Job Details | B31: Additional Information | C31: Work Shift | D31: =SUBSTITUTE(A31," ","") & "_" & SUBSTITUTE(IF(B31="N/A","",B31& "_")," ","") & SUBSTITUTE(SUBSTITUTE(C31," ",""),"/","") -> JobDetails_AdditionalInformation_WorkShift | E31: =D31&2 -> JobDetails_AdditionalInformation_WorkShift2 | G31: Default Work Shift (Italy) | H31: Default Work Shift (Italy) | I31: Default Work Shift (Italy) | J31: Default Work Shift (Italy) | K31: Default Work Shift (Italy) | L31: Default Work Shift (Italy) | M31: 5 Days (Italy) | N31: Default Work Shift (Italy) | O31: 5 Days (Italy) | P31: 5 Days (Italy) | Q31: 5 Days (Italy) | R31: 5 Days (Italy) | S31: 5 Days (Italy) | T31: 4 Days (Italy)
A32: Job Details | B32: Additional Information | C32: End Employment Date | D32: =SUBSTITUTE(A32," ","") & "_" & SUBSTITUTE(IF(B32="N/A","",B32& "_")," ","") & SUBSTITUTE(SUBSTITUTE(C32," ",""),"/","") -> JobDetails_AdditionalInformation_EndEmploymentDate | E32: =D32&2 -> JobDetails_AdditionalInformation_EndEmploymentDate2 | F32: Set to N/A when field not present otherwise automation will throw error | G32: N/A | H32: =TODAY()+365 -> 45547 | I32: =TODAY()+365 -> 45547 | J32: N/A | K32: N/A | L32: =TODAY()+365 -> 45547 | M32: N/A | N32: N/A | O32: N/A | P32: =TODAY()+365 -> 45547 | Q32: N/A | R32: =TODAY()+365 -> 45547 | S32: N/A | T32: =TODAY()+365 -> 45547
A33: Job Details | B33: Additional Information | C33: Comments | D33: =SUBSTITUTE(A33," ","") & "_" & SUBSTITUTE(IF(B33="N/A","",B33& "_")," ","") & SUBSTITUTE(SUBSTITUTE(C33," ",""),"/","") -> JobDetails_AdditionalInformation_Comments | E33: =D33&2 -> JobDetails_AdditionalInformation_Comments2 | G33: Automation Comments here…. | H33: Automation Comments here…. | I33: Automation Comments here…. | J33: Automation Comments here…. | K33: Automation Comments here…. | L33: Automation Comments here…. | M33: Automation Comments here…. | N33: Automation Comments here…. | O33: Automation Comments here…. | P33: Automation Comments here…. | Q33: Automation Comments here…. | R33: Automation Comments here…. | S33: Automation Comments here…. | T33: Automation Comments here….
A34: Change Organization Assignments | B34: N/A | C34: Cost Center | D34: =SUBSTITUTE(A34," ","") & "_" & SUBSTITUTE(IF(B34="N/A","",B34& "_")," ","") & SUBSTITUTE(SUBSTITUTE(C34," ",""),"/","") -> ChangeOrganizationAssignments_CostCenter | E34: =D34&2 -> ChangeOrganizationAssignments_CostCenter2 | G34: 94 Retail Operative | H34: 92 | I34: 92 | J34: 92 | K34: 92 | L34: 94 Retail Operative | M34: 94 | N34: 94 Retail Operative | O34: 94 | P34: 94 | Q34: 94 | R34: 94 | S34: 94 | T34: 94
A35: Change Organization Assignments | B35: N/A | C35: Department Section | D35: =SUBSTITUTE(A35," ","") & "_" & SUBSTITUTE(IF(B35="N/A","",B35& "_")," ","") & SUBSTITUTE(SUBSTITUTE(C35," ",""),"/","") -> ChangeOrganizationAssignments_DepartmentSection | E35: =D35&2 -> ChangeOrganizationAssignments_DepartmentSection2 | G35: 06 Menswear | H35: 251 Management Retail | I35: 251 Management Retail | J35: 251 Management Retail | K35: 251 Management Retail | L35: 06 Menswear | M35: 261 Tills | N35: 06 Menswear | O35: 255 Stockroom | P35: 261 Tills | Q35: 250 Human Resources Retail | R35: 250 Human Resources Retail | S35: 256 Visual Merchandising | T35: 261
A36: Assign Pay Group | B36: N/A | C36: Proposed Pay Group Initial | D36: =SUBSTITUTE(A36," ","") & "_" & SUBSTITUTE(IF(B36="N/A","",B36& "_")," ","") & SUBSTITUTE(SUBSTITUTE(C36," ",""),"/","") -> AssignPayGroup_ProposedPayGroupInitial | E36: =D36&2 -> AssignPayGroup_ProposedPayGroupInitial2 | G36: Please select a Italy Pay Group | H36: Please select a Italy Pay Group | I36: Please select a Italy Pay Group | J36: Please select a Italy Pay Group | K36: Please select a Italy Pay Group | L36: Please select a Italy Pay Group | M36: Please select a Italy Pay Group | N36: Please select a Italy Pay Group | O36: Please select a Italy Pay Group | P36: Please select a Italy Pay Group | Q36: Please select a Italy Pay Group | R36: Please select a Italy Pay Group | S36: Please select a Italy Pay Group | T36: Please select a Italy Pay Group
A37: Assign Pay Group | B37: N/A | C37: Proposed Pay Group Final | D37: =SUBSTITUTE(A37," ","") & "_" & SUBSTITUTE(IF(B37="N/A","",B37& "_")," ","") & SUBSTITUTE(SUBSTITUTE(C37," ",""),"/","") -> AssignPayGroup_ProposedPayGroupFinal | E37: =D37&2 -> AssignPayGroup_ProposedPayGroupFinal2 | G37: ITA Monthly | H37: ITA Monthly | I37: ITA Monthly | J37: ITA Monthly | K37: ITA Monthly | L37: ITA Monthly | M37: SK Monthly | N37: ITA Monthly | O37: SK Monthly | P37: SK Monthly | Q37: SK Monthly | R37: SK Monthly | S37: SK Monthly | T37: SK Monthly
A38: Add Probation Period | B38: N/A | C38: Probation End Date | D38: =SUBSTITUTE(A38," ","") & "_" & SUBSTITUTE(IF(B38="N/A","",B38& "_")," ","") & SUBSTITUTE(SUBSTITUTE(C38," ",""),"/","") -> AddProbationPeriod_ProbationEndDate | E38: =D38&2 -> AddProbationPeriod_ProbationEndDate2 | G38: Defaulted | H38: Defaulted | I38: Defaulted | J38: Defaulted | K38: Defaulted | L38: Defaulted | M38: Defaulted | N38: Defaulted | O38: Defaulted | P38: Defaulted | Q38: Defaulted | R38: Defaulted | S38: Defaulted | T38: Defaulted
A39: Maintain Employee Contract | B39: N/A | C39: ContractStartDate | D39: =SUBSTITUTE(A39," ","") & "_" & SUBSTITUTE(IF(B39="N/A","",B39& "_")," ","") & SUBSTITUTE(SUBSTITUTE(C39," ",""),"/","") -> MaintainEmployeeContract_ContractStartDate | E39: =D39&2 -> MaintainEmployeeContract_ContractStartDate2 | F39: Set to N/A when field not present otherwise automation will throw error | G39: Defaulted | H39: Defaulted | I39: Defaulted | J39: Defaulted | K39: Defaulted | L39: Defaulted | M39: Defaulted | N39: Defaulted | O39: Defaulted | P39: Defaulted | Q39: Defaulted | R39: Defaulted | S39: Defaulted | T39: Defaulted
A40: Maintain Employee Contract | B40: N/A | C40: Date Employee Signed | D40: =SUBSTITUTE(A40," ","") & "_" & SUBSTITUTE(IF(B40="N/A","",B40& "_")," ","") & SUBSTITUTE(SUBSTITUTE(C40," ",""),"/","") -> MaintainEmployeeContract_DateEmployeeSigned | E40: =D40&2 -> MaintainEmployeeContract_DateEmployeeSigned2 | G40: =TODAY()-1 -> 45181 | H40: =TODAY()-1 -> 45181 | I40: =TODAY()-1 -> 45181 | J40: =TODAY()-1 -> 45181 | K40: =TODAY()-1 -> 45181 | L40: =TODAY()-1 -> 45181 | M40: =TODAY()-1 -> 45181 | N40: =TODAY()-1 -> 45181 | ... T40: =TODAY()-1 -> 45181
A41: Maintain Employee Contract | B41: N/A | C41: Reason | D41: =SUBSTITUTE(A41," ","") & "_" & SUBSTITUTE(IF(B41="N/A","",B41& "_")," ","") & SUBSTITUTE(SUBSTITUTE(C41," ",""),"/","") -> MaintainEmployeeContract_Reason | E41: =D41&2 -> MaintainEmployeeContract_Reason2 | F41: Set to N/A when field not present otherwise automation will throw error | G41: Main | H41: Main | I41: Main | J41: Main | K41: Main | L41: Main | M41: Main | N41: Main | O41: Main | P41: Agreement to Perform Work (DPC) | Q41: Main | R41: Main | S41: Main | T41: Main
...

Sheet Defects
B2: Batch 1 - Summary | E2: Batch 2 - Summary | H2: Batch 3 - Summary | K2: All E2E Cycle 1 - Summary
B3: Description | C3: Total | E3: Description | F3: Total | H3: Description | I3: Total | K3: Description | L3: Total No. | M3: %
B4: Passed | C4: 35 | E4: Passed | F4: 141 | H4: Passed | I4: 0 | K4: Passed | L4: =C4+F4+I4 -> 176 | M4: =L4/L8*100 -> 72.131148
B5: Failed | C5: 17 | E5: Failed | F5: 27 | H5: Failed | I5: 24 | K5: Failed | L5: =C5+F5+I5 -> 68 | M5: =L5/L8*100 -> 27.868852
B6: Not Run | C6: 0 | E6: Not Run | F6: 0 | H6: Not Run | I6: 0 | K6: Not Run | L6: =C6+F6+I6 -> 0 | M6: =L6/L8*100 -> 0
B7: Executed | C7: 52 | E7: Executed | F7: 168 | H7: Executed | I7: 24 | K7: Executed | L7: =C7+F7+I7 -> 244 | M7: =L7/L8*100 -> 100
B8: Total | C8: 52 | E8: Total | F8: 168 | H8: Total | I8: 24 | K8: Total | L8: =C8+F8+I8 -> 244 | M8: =M4+M5+M6 -> 100
B10: Batch 1 - Defects | E10: Batch 2 - Defects | H10: Batch 3 - Defects | K10: All E2E Cycle 1 - Defects
B11: Failed Tests Description | C11: Total | E11: Failed Tests Description | F11: Total | H11: Failed Tests Description | I11: Total | K11: Failed Tests Description | L11: Total No. | M11: %
B12: P&C Salary Assistant/Supervisor Salary Configuration missing | C12: 12 | E12: Grade Profile not populated causing salary to remain blank | F12: 24 | H12: Data issue - Rerun scheduled | I12: 24 | K12: Personal Information Change Approval Email missing after 2nd and final proxy into HR Manager | L12: 44 | M12: =L12/L17*100 -> 35.2
B13: Automation issue with Maiden Name - Gary to discuss with Shane/Andre | C13: 5 | E13: GC - Under Investigation | F13: 3 | H13: Total | I13: 24 | K13: Open button not available to assign paygroup for payroll. Approval required by David Bradley... | L13: 20 | M13: =L13/L17*100 -> 16
B14: Total | C14: =C12+C13 -> 17 | E14: Total | F14: 27 | K14: Grade Profile not populated causing salary to remain blank | L14: 34 | M14: =L14/L17*100 -> 27.2
K15: Data issue - Rerun scheduled | L15: 24 | M15: =L15/L17*100 -> 19.2
K16: GC - Under Investigation | L16: 3 | M16: =L16/L17*100 -> 2.4
K17: Total | L17: =SUM(L12:L16) -> 125 | M17: =SUM(M12:M16) -> 100

Sheet Automation_Lookups
A1: Process2 | B1: ExecutionFlag2 | C1: SupervisoryOrganisation_SupervisoryOrganisation2 | D1: LegalNameInformation_Country2 | E1: ContactInformation_Phone_CountryPhoneCode2 | F1: ContactInformation_Phone_PhoneDevice2 | G1: ContactInformation_Phone_Type2 | H1: ContactInformation_Address_Type2 | I1: ContactInformation_Email_Type2 | J1: JobDetails_HireDate2 | K1: JobDetails_Reason2 | L1: JobDetails_Position2 | M1: JobDetails_EmployeeType2 | N1: JobDetails_JobProfile2 | O1: JobDetails_TimeType2 | P1: JobDetails_Location2 | Q1: JobDetails_AdditionalInformation_WorkShift2 | R1: JobDetails_AdditionalInformation_EndEmploymentDate2 | S1: ChangeOrganizationAssignments_DepartmentSection2 | T1: AssignPayGroup_ProposedPayGroup2 | U1: Proxy_ProxyNumber2 | V1: Proxy_OnBehalfOf2 | W1: MaintainEmployeeContract_Reason2 | X1: MaintainEmployeeContract_Status2 | Y1: MaintainEmployeeContract_ContractType2 | Z1: MaintainEmployeeContract_ContractEndDate2 | AA1: ProposeCompensationHire_GradeProfile2 | AB1: ProposeCompensationHire_Step2 | AC1: EditPassportsandVisas_Country2 | AD1: EditPassportsandVisas_PassportIDType2 | AE1: EditPassportsandVisas_IdentificationNo2 | AF1: EditPassportsandVisas_IssuedDate2 | AG1: EditPassportsandVisas_ExpirationDate2 | AH1: ChangeMyPersonalInformation_MaritalStatus2 | AI1: ChangeMyEmergencyContacts_Relationship2 | AJ1: ChangeMyEmergencyContacts_PhoneDevice2 | AK1: ChangeMyGovernmentIDs_NationalIDs_NationalIDType2 | AL1: PaymentElectionOption_AccountType2 | AM1: SkillsAndExperience_AddEducation_School2 | AN1: AddProbationPeriod_ProbationEndDate2 | AO1: EditAdditionalData_PayrollTaxDeduction | AP1: HealthCareProvider_MealVoucher2 | AQ1: School1 | AR1: School2 | AS1: ContactInformation_Address_Province2 | AT1: ChangeMyGovernmentIDs_NationalIDs_NationalIDType12 | AU1: ChangeMyGovernmentIDs_NationalIDs_NationalIDType22 | AV1: EditAdditionalData_EstadolIRPF2
A2: New Hire | B2: Yes | C2: 362 Recruitment (Carolina De La Barrera Crespo (375)) | D2: Czechia | E2: Czechia (+420) | F2: Mobile | G2: Home | H2: Home | I2: Home | J2: =IF(MONTH(TODAY())<10,"0"&MONTH(TODAY())&"/",MONTH(TODAY())&"/") & IF(DAY(TODAY())<10,"0"&DAY(TODAY())&"/",DAY(TODAY())&"/") & YEAR(TODAY()) -> 09/13/2023 | K2: ReHire | L2: Assistant Manager-2 | M2: Fixed Term | N2: DPP/DPC | O2: Full time | P2: 362 Algeciras | Q2: 1 Day | R2: =IF(MONTH(TODAY())<10,"0"&MONTH(TODAY())&"/",MONTH(TODAY())&"/") & IF(DAY(TODAY())<10,"0"&DAY(TODAY())&"/",DAY(TODAY())&"/") & YEAR(TODAY()) -> 09/13/2023 | S2: Accessories | T2: Please select a Romania Pay Group | U2: 10223439 | V2: Iwona Chrostowska (10223439) | W2: for the purposes of performing any work of casual or seasonal nature | X2: 1st Fixed Term Contract | Y2: Employment Agreement | Z2: =IF(MONTH(TODAY())<10,"0"&MONTH(TODAY())&"/",MONTH(TODAY())&"/") & IF(DAY(TODAY())<10,"0"&DAY(TODAY())&"/",DAY(TODAY())&"/") & YEAR(TODAY()) -> 09/13/2023 | AA2: Defaulted | AB2: Defaulted | AH2: Single | AI2: Father | AJ2: Mobile/Cell | AK2: Social Security Identification | AL2: Savings | AM2: N/A | AN2: =IF(MONTH(TODAY()+100)<10,"0"&MONTH(TODAY()+100)&"/",MONTH(TODAY()+100)&"/") & IF(DAY(TODAY()+100)<10,"0"&DAY(TODAY()+100)&"/",DAY(TODAY()+100)&"/") & YEAR(TODAY()+100) -> 12/22/2023 | AO2: Yes | AP2: Yes | AQ2: Střední bez maturity či výučního listu | AR2: stredni bez maturity ci vyucniho listu | AS2: Madrid | AT2: Social Security Number (NSS) | AU2: ID Card (DNI) Number | AV2: Soltero/a, viudo/a, divorciado/a o separado/a legalmente con hijos solteros menores de 18 años o incapacitados judicialmente que conviven exclusivamente con Vd., sin convivir también con el otro progenitor Soltero/a, viudo/a, divorciado/a o separado/a legalmente con hijos solteros menores de 18 años o incapacitados judicialmente que conviven exclusivamente con Vd., sin convivir también con el otro progenitor
A3: New Role & New Hire | B3: No | C3: 895 Store Management (Male Teststmanager (10224969)) | D3: Czechia | E3: Czechia (+420) | F3: Landline | G3: Work | H3: Work | I3: Work | J3: =IF(MONTH(TODAY()-10)<10,"0"&MONTH(TODAY()-10)&"/",MONTH(TODAY()-10))&"/" & IF(DAY(TODAY()-10)<10,"0"&DAY(TODAY()-10)&"/",DAY(TODAY()-10)&"/") & YEAR(TODAY()-10) -> 09//03/2023 | L3: Assistant Manager-3 | M3: Intern | N3: Retail Assistant | O3: Part time | P3: 420 Lisbon - UBBO | Q3: 2 Days | R3: =IF(MONTH(TODAY()+100)<10,"0"&MONTH(TODAY()+100)&"/",MONTH(TODAY()+100)&"/") & IF(DAY(TODAY()+100)<10,"0"&DAY(TODAY()+100)&"/",DAY(TODAY()+100)&"/") & YEAR(TODAY()+100) -> 12/22/2023 | T3: PT Monthly | U3: 10225553 | V3: Kocour Mikeš (10225553) | W3: for the purposes of performing work during the term of office | X3: 2nd Fixed Term Contract | Y3: Agreement to perform work | Z3: =IF(MONTH(TODAY()+100)<10,"0"&MONTH(TODAY()+100)&"/",MONTH(TODAY()+100)&"/") & IF(DAY(TODAY()+100)<10,"0"&DAY(TODAY()+100)&"/",DAY(TODAY()+100)&"/") & YEAR(TODAY()+100) -> 12/22/2023 | AH3: Married | AI3: Mother | AJ3: Telephone - Landline | AK3: Taxpayer ID | AL3: Checking | AM3: Vseobecne stredni s maturitou | AN3: =IF(MONTH(TODAY()+1000)<10,"0"&MONTH(TODAY()+1000)&"/",MONTH(TODAY()+1000)&"/") & IF(DAY(TODAY()+1000)<10,"0"&DAY(TODAY()+1000)&"/",DAY(TODAY()+1000)&"/") & YEAR(TODAY()+1000) -> 06/09/2026 | AO3: No | AP3: No | AQ3: Střední odborné vzdělání s výučním listem | AR3: stredni odborne vzdelani s vyucnim listem
C4: 880 Store Management (Wozun Fedofe (10285793)) | D4: Poland | E4: Poland (+48) | J4: =IF(MONTH(TODAY()+10)<10,"0"&MONTH(TODAY()+10)&"/",MONTH(TODAY()+10)&"/") & IF(DAY(TODAY()+10)<10,"0"&DAY(TODAY()+10)&"/",DAY(TODAY()+10)&"/") & YEAR(TODAY()+10) -> 09/23/2023 | L4: Test Store Manager-2 | M4: Permanent | N4: Department Manager | P4: 880 Bucharest East Park Lake | Q4: 3 Days | R4: =IF(MONTH(TODAY()+1000)<10,"0"&MONTH(TODAY()+1000)&"/",MONTH(TODAY()+1000)&"/") & IF(DAY(TODAY()+1000)<10,"0"&DAY(TODAY()+1000)&"/",DAY(TODAY()+1000)&"/") & YEAR(TODAY()+1000) -> 06/09/2026 | W4: for the purposes of substituting an employee during his/her excused absence at work | X4: 3rd Fixed Term Contract | Y4: Agreement to complete a job | Z4: =IF(MONTH(TODAY()+1000)<10,"0"&MONTH(TODAY()+1000)&"/",MONTH(TODAY()+1000)&"/") & IF(DAY(TODAY()+1000)<10,"0"&DAY(TODAY()+1000)&"/",DAY(TODAY()+1000)&"/") & YEAR(TODAY()+1000) -> 06/09/2026 | AH4: Not Disclosed | AI4: Spouse | AK4: ID Number | AN4: N/A | AQ4: Všeobecné střední s maturitou | AR4: vseobecne stredni s maturitou
D5: Poland | E5: Poland (+48) | L5: Store Manager | M5: Students | N5: Senior Department Manager | P5: 870 | Q5: 4 Days | R5: N/A | W5: No reason necessary | X5: Active | Z5: N/A | AI5: Partner | AQ5: Vysokoškolské Bc. | AR5: Vysokoskolske Bc
L6: Supervisor | N6: Supervisor | Q6: 5 Days | X6: Inactive | AQ6: Vysokoškolské MUDr., JUDr., Mgr., MgA., Ing. | AR6: vysokoskolske MUDR., JUDr., Mgr., MgA., Ing.
L7: Retail Assistant | N7: P&C Supervisor | AQ7: Vysokoškolské PhDr, PhD, JUDr, MUDr | AR7: vysokoskolske PhDr, PhD, JUDr, MUDr
L8: N/A | N8: P&C Assistant | AQ8: vyšší odborné DiS | AR8: vyssi odborne DiS
N9: Trainee Manager | AQ9: Základní | AR9: Zakladni
N10: Assistant Manager
N11: P&C Manager
N12: Store Manager
N13: Visual Merchandiser Manager
B14: ReHire | N14: Visual Merchandising Supervisor
B15: ReHireManagerNewRole | N15: Visual Merchandising Assistant
K21: Rehire | U21: 8701839 | V21: Lisanne Kluinhaar (8701839) | W21: Defined contract end date (Determined) | AP21: Netherlands Retail Assistant
C22: 701 Recruitment (Lisanne Kluinhaar (8701839)) | D22: Netherlands | E22: Netherlands (+31) | K22: Seasonal | W22: Undefined contract end date (Undetermined) | Y22: Part-time( PT ) | AP22: Netherlands Retail Assistant Cash Office | AQ22: Retail Assistant (18)
W23: Intern | Y23: Full-time( FT. ) | AQ23: Retail Assistant (19)
C24: Retail - Central & Eastern Europe (Stephen Regan (9910010) (Inherited) | D24: Poland | E24: Poland (+48) | AQ24: Retail Assistant (20)
C25: Retail Poland Area: Central Poland (Stephen Regan (9910010) (Inherited)) | D25: Poland | E25: Poland (+48) | AQ25: Retail Assistant (21)
AQ26: Retail Assistant (22)
AQ27: Retail Assistant (23+)
AQ28: Retail Assistant (Under 18)

Sheet RC. No
A1: D.O.B | B1: 35139 | C1: 33054 | D1: 31390 | F1: r col b | G1: r col c | H1: r col d
B2: 9603150007 | C2: 9006300006 | D2: 8512090004 | F2: =B2/11 -> 873013637 | G2: =C2/11 -> 818754546 | H2: =D2/11 -> 773826364
B3: =B2+11 -> 9603150018 | C3: =C2+11 -> 9006300017 | D3: =D2+11 -> 8512090015 | F3: =B3/11 -> 873013638 | G3: =C3/11 -> 818754547 | H3: =D3/11 -> 773826365
B4: =B3+11 -> 9603150029 | C4: =C3+11 -> 9006300028 | D4: =D3+11 -> 8512090026 | F4: =B4/11 -> 873013639 | G4: =C4/11 -> 818754548 | H4: =D4/11 -> 773826366
B5: =B4+11 -> 9603150040 | C5: =C4+11 -> 9006300039 | D5: =D4+11 -> 8512090037 | F5: =B5/11 -> 873013640 | G5: =C5/11 -> 818754549 | H5: =D5/11 -> 773826367
B6: =B5+11 -> 9603150051 | C6: =C5+11 -> 9006300050 | D6: =D5+11 -> 8512090048 | F6: =B6/11 -> 873013641 | G6: =C6/11 -> 818754550 | H6: =D6/11 -> 773826368
B7: =B6+11 -> 9603150062 | C7: =C6+11 -> 9006300061 | D7: =D6+11 -> 8512090059 | F7: =B7/11 -> 873013642 | G7: =C7/11 -> 818754551 | H7: =D7/11 -> 773826369
B8: =B7+11 -> 9603150073 | C8: =C7+11 -> 9006300072 | D8: =D7+11 -> 8512090070 | F8: =B8/11 -> 873013643 | G8: =C8/11 -> 818754552 | H8: =D8/11 -> 773826370
B9: =B8+11 -> 9603150084 | C9: =C8+11 -> 9006300083 | D9: =D8+11 -> 8512090081 | F9: =B9/11 -> 873013644 | G9: =C9/11 -> 818754553 | H9: =D9/11 -> 773826371
B10: =B9+11 -> 9603150095 | C10: =C9+11 -> 9006300094 | D10: =D9+11 -> 8512090092 | F10: =B10/11 -> 873013645 | G10: =C10/11 -> 818754554 | H10: =D10/11 -> 773826372
B11: =B10+11 -> 9603150106 | C11: =C10+11 -> 9006300105 | D11: =D10+11 -> 8512090103 | F11: =B11/11 -> 873013646 | G11: =C11/11 -> 818754555 | H11: =D11/11 -> 773826373
B12: =B11+11 -> 9603150117 | C12: =C11+11 -> 9006300116 | D12: =D11+11 -> 8512090114 | F12: =B12/11 -> 873013647 | G12: =C12/11 -> 818754556 | H12: =D12/11 -> 773826374
B13: =B12+11 -> 9603150128 | C13: =C12+11 -> 9006300127 | D13: =D12+11 -> 8512090125 | F13: =B13/11 -> 873013648 | G13: =C13/11 -> 818754557 | H13: =D13/11 -> 773826375
B14: =B13+11 -> 9603150139 | C14: =C13+11 -> 9006300138 | D14: =D13+11 -> 8512090136 | F14: =B14/11 -> 873013649 | G14: =C14/11 -> 818754558 | H14: =D14/11 -> 773826376
... B28: =B27+11 -> 9603150293 | C28: =C27+11 -> 9006300292 | D28: =D27+11 -> 8512090290 | F28: =B28/11 -> 873013663 | G28: =C28/11 -> 818754572 | H28: =D28/11 -> 773826390
B29: =B28+11 -> 9603150304
B30: =B29+11 -> 9603150315
B31: =B30+11 -> 9603150326
B32: =B31+11 -> 9603150337
B33: =B32+11 -> 9603150348
B34: =B33+11 -> 9603150359
B35: =B34+11 -> 9603150370
B36: =B35+11 -> 9603150381
B37: =B36+11 -> 9603150392
B38: =B37+11 -> 9603150403
B39: =B38+11 -> 9603150414
B40: =B39+11 -> 9603150425
... B75: =B74+11 -> 9603150810
B76: =B75+11 -> 9603150821 | X76: New RC Numbers
B77: =B76+11 -> 9603150832 | X77: 9202101337
B78: =B77+11 -> 9603150843 | X78: =SUM(X77)+11 -> 9202101348
B79: =B78+11 -> 9603150854 | X79: =SUM(X78)+11 -> 9202101359
B80: =B79+11 -> 9603150865 | X80: =SUM(X79)+11 -> 9202101370
B81: =B80+11 -> 9603150876 | X81: =SUM(X80)+11 -> 9202101381
B82: =B81+11 -> 9603150887 | X82: =SUM(X81)+11 -> 9202101392
B83: =B82+11 -> 9603150898 | X83: =SUM(X82)+11 -> 9202101403
B84: =B83+11 -> 9603150909 | X84: =SUM(X83)+11 -> 9202101414
B85: =B84+11 -> 9603150920 | X85: =SUM(X84)+11 -> 9202101425
B86: =B85+11 -> 9603150931 | D86: 9603170269 | X86: =SUM(X85)+11 -> 9202101436
D87: =D86+11 -> 9603170280 | F87: 9603170280 | H87: 9603170280 | I87: 9603170291 | J87: 9603170302 | K87: 9603170313 | L87: 9603170324 | M87: 9603170335 | N87: 9603170346 | O87: 9603170357 | P87: 9603170368 | Q87: 9603170379 | R87: 9603170390 | S87: 9603170401 | T87: 9603170412 | X87: =SUM(X86)+11 -> 9202101447
...

Sheet Code_11122019_1000
B1: Variable Row | C1: Variable Row Combined | D1: Variable Value | E1: Variable Value Combined | F1: Row Number Declaration --------------------------------- intRowProcess = comExcelWorksheet.Range("Process").Row | G1: Value Declaration ------------------------ strProcess = comExcelWorksheet.Cells(intRowProcess, intColTestColumn).Value | H1: Getters
A2: =Test_Data!D3 -> Process | B2: ="intRow" & A2 & ", " -> intRowProcess, | C2: =B2 -> intRowProcess, | D2: ="str" & A2 & ", " -> strProcess, | E2: =D2 -> strProcess, | F2: ="intRow" & A2 & " = comExcelWorksheet.Range(""" & A2 & """).Row" -> intRowProcess = comExcelWorksheet.Range("Process").Row | G2: ="str" & A2 & " = comExcelWorksheet.Cells(intRow" & A2 & ", intColTestColumn).Value" -> strProcess = comExcelWorksheet.Cells(intRowProcess, intColTestColumn).Value | H2: ="Public Property Get get" & A2 & "() : get" & A2 & " = str" & A2 & " : End Property" -> Public Property Get getProcess() : getProcess = strProcess : End Property
A3: =Test_Data!D4 -> ExecutionFlag | B3: ="intRow" & A3 & ", " -> intRowExecutionFlag, | C3: =C2 &B3 -> intRowProcess, intRowExecutionFlag, | D3: ="str" & A3 & ", " -> strExecutionFlag, | E3: =E2 &D3 -> strProcess, strExecutionFlag, | F3: ="intRow" & A3 & " = comExcelWorksheet.Range(""" & A3 & """).Row" -> intRowExecutionFlag = comExcelWorksheet.Range("ExecutionFlag").Row | G3: ="str" & A3 & " = comExcelWorksheet.Cells(intRow" & A3 & ", intColTestColumn).Value" -> strExecutionFlag = comExcelWorksheet.Cells(intRowExecutionFlag, intColTestColumn).Value | H3: ="Public Property Get get" & A3 & "() : get" & A3 & " = str" & A3 & " : End Property" -> Public Property Get getExecutionFlag() : getExecutionFlag = strExecutionFlag : End Property
A4: =Test_Data!D6 -> LastRunTimeandStatus | B4: ="intRow" & A4 & ", " -> intRowLastRunTimeandStatus, | C4: =C3 &B4 -> intRowProcess, intRowExecutionFlag, intRowLastRunTimeandStatus, | D4: ="str" & A4 & ", " -> strLastRunTimeandStatus, | E4: =E3 &D4 -> strProcess, strExecutionFlag, strLastRunTimeandStatus, | F4: ="intRow" & A4 & " = comExcelWorksheet.Range(""" & A4 & """).Row" -> intRowLastRunTimeandStatus = comExcelWorksheet.Range("LastRunTimeandStatus").Row | G4: ="str" & A4 & " = comExcelWorksheet.Cells(intRow" & A4 & ", intColTestColumn).Value" -> strLastRunTimeandStatus = comExcelWorksheet.Cells(intRowLastRunTimeandStatus, intColTestColumn).Value | H4: ="Public Property Get get" & A4 & "() : get" & A4 & " = str" & A4 & " : End Property" -> Public Property Get getLastRunTimeandStatus() : getLastRunTimeandStatus = strLastRunTimeandStatus : End Property
A5: =Test_Data!D7 -> LastRunEmployeeNo | B5: ="intRow" & A5 & ", " -> intRowLastRunEmployeeNo, | C5: =C4 &B5 -> intRowProcess, intRowExecutionFlag, intRowLastRunTimeandStatus, intRowLastRunEmployeeNo, | D5: ="str" & A5 & ", " -> strLastRunEmployeeNo, | E5: =E4 &D5 -> strProcess, strExecutionFlag, strLastRunTimeandStatus, strLastRunEmployeeNo, | F5: ="intRow" & A5 & " = comExcelWorksheet.Range(""" & A5 & """).Row" -> intRowLastRunEmployeeNo = comExcelWorksheet.Range("LastRunEmployeeNo").Row | G5: ="str" & A5 & " = comExcelWorksheet.Cells(intRow" & A5 & ", intColTestColumn).Value" -> strLastRunEmployeeNo = comExcelWorksheet.Cells(intRowLastRunEmployeeNo, intColTestColumn).Value | H5: ="Public Property Get get" & A5 & "() : get" & A5 & " = str" & A5 & " : End Property" -> Public Property Get getLastRunEmployeeNo() : getLastRunEmployeeNo = strLastRunEmployeeNo : End Property
A6: =Test_Data!D8 -> LastRunErrorMessage | B6: ="intRow" & A6 & ", " -> intRowLastRunErrorMessage, | C6: =C5 &B6 -> intRowProcess, intRowExecutionFlag, intRowLastRunTimeandStatus, intRowLastRunEmployeeNo, intRowLastRunErrorMessage, | D6: ="str" & A6 & ", " -> strLastRunErrorMessage, | E6: =E5 &D6 -> strProcess, strExecutionFlag, strLastRunTimeandStatus, strLastRunEmployeeNo, strLastRunErrorMessage, | F6: ="intRow" & A6 & " = comExcelWorksheet.Range(""" & A6 & """).Row" -> intRowLastRunErrorMessage = comExcelWorksheet.Range("LastRunErrorMessage").Row | G6: ="str" & A6 & " = comExcelWorksheet.Cells(intRow" & A6 & ", intColTestColumn).Value" -> strLastRunErrorMessage = comExcelWorksheet.Cells(intRowLastRunErrorMessage, intColTestColumn).Value | H6: ="Public Property Get get" & A6 & "() : get" & A6 & " = str" & A6 & " : End Property" -> Public Property Get getLastRunErrorMessage() : getLastRunErrorMessage = strLastRunErrorMessage : End Property
A7: =Test_Data!D9 -> DefectDescription | B7: ="intRow" & A7 & ", " -> intRowDefectDescription, | C7: =C6 &B7 -> intRowProcess, intRowExecutionFlag, intRowLastRunTimeandStatus, intRowLastRunEmployeeNo, intRowLastRunErrorMessage, intRowDefectDescription, | D7: ="str" & A7 & ", " -> strDefectDescription, | E7: =E6 &D7 -> strProcess, strExecutionFlag, strLastRunTimeandStatus, strLastRunEmployeeNo, strLastRunErrorMessage, strDefectDescription, | F7: ="intRow" & A7 & " = comExcelWorksheet.Range(""" & A7 & """).Row" -> intRowDefectDescription = comExcelWorksheet.Range("DefectDescription").Row | G7: ="str" & A7 & " = comExcelWorksheet.Cells(intRow" & A7 & ", intColTestColumn).Value" -> strDefectDescription = comExcelWorksheet.Cells(intRowDefectDescription, intColTestColumn).Value | H7: ="Public Property Get get" & A7 & "() : get" & A7 & " = str" & A7 & " : End Property" -> Public Property Get getDefectDescription() : getDefectDescription = strDefectDescription : End Property
A8: =Test_Data!D10 -> AutomationComments | B8: ="intRow" & A8 & ", " -> intRowAutomationComments, | C8: =C7 &B8 -> intRowProcess, intRowExecutionFlag, intRowLastRunTimeandStatus, intRowLastRunEmployeeNo, intRowLastRunErrorMessage, intRowDefectDescription, intRowAutomationComments, | D8: ="str" & A8 & ", " -> strAutomationComments, | E8: =E7 &D8 -> strProcess, strExecutionFlag, strLastRunTimeandStatus, strLastRunEmployeeNo, strLastRunErrorMessage, strDefectDescription, strAutomationComments, | F8: ="intRow" & A8 & " = comExcelWorksheet.Range(""" & A8 & """).Row" -> intRowAutomationComments = comExcelWorksheet.Range("AutomationComments").Row | G8: ="str" & A8 & " = comExcelWorksheet.Cells(intRow" & A8 & ", intColTestColumn).Value" -> strAutomationComments = comExcelWorksheet.Cells(intRowAutomationComments, intColTestColumn).Value | H8: ="Public Property Get get" & A8 & "() : get" & A8 & " = str" & A8 & " : End Property" -> Public Property Get getAutomationComments() : getAutomationComments = strAutomationComments : End Property
A9: =Test_Data!D11 -> QAComments | B9: ="intRow" & A9 & ", " -> intRowQAComments, | C9: =C8 &B9 -> intRowProcess, intRowExecutionFlag, intRowLastRunTimeandStatus, intRowLastRunEmployeeNo, intRowLastRunErrorMessage, intRowDefectDescription, intRowAutomationComments, intRowQAComments, | D9: ="str" & A9 & ", " -> strQAComments, | E9: =E8 &D9 -> strProcess, strExecutionFlag, strLastRunTimeandStatus, strLastRunEmployeeNo, strLastRunErrorMessage, strDefectDescription, strAutomationComments, strQAComments, | F9: ="intRow" & A9 & " = comExcelWorksheet.Range(""" & A9 & """).Row" -> intRowQAComments = comExcelWorksheet.Range("QAComments").Row | G9: ="str" & A9 & " = comExcelWorksheet.Cells(intRow" & A9 & ", intColTestColumn).Value" -> strQAComments = comExcelWorksheet.Cells(intRowQAComments, intColTestColumn).Value | H9: ="Public Property Get get" & A9 & "() : get" & A9 & " = str" & A9 & " : End Property" -> Public Property Get getQAComments() : getQAComments = strQAComments : End Property
A10: =Test_Data!D12 -> 0 | B10: ="intRow" & A10 & ", " -> intRow0, | C10: =C9 &B10 -> intRowProcess, intRowExecutionFlag, intRowLastRunTimeandStatus, intRowLastRunEmployeeNo, intRowLastRunErrorMessage, intRowDefectDescription, intRowAutomationComments, intRowQAComments, intRow0, | D10: ="str" & A10 & ", " -> str0, | E10: =E9 &D10 -> strProcess, strExecutionFlag, strLastRunTimeandStatus, strLastRunEmployeeNo, strLastRunErrorMessage, strDefectDescription, strAutomationComments, strQAComments, str0, | F10: ="intRow" & A10 & " = comExcelWorksheet.Range(""" & A10 & """).Row" -> intRow0 = comExcelWorksheet.Range("0").Row | G10: ="str" & A10 & " = comExcelWorksheet.Cells(intRow" & A10 & ", intColTestColumn).Value" -> str0 = comExcelWorksheet.Cells(intRow0, intColTestColumn).Value | H10: ="Public Property Get get" & A10 & "() : get" & A10 & " = str" & A10 & " : End Property" -> Public Property Get get0() : get0 = str0 : End Property
A11: =Test_Data!D13 -> Automation Ref | B11: ="intRow" & A11 & ", " -> intRowAutomation Ref, | C11: =C10 &B11 -> intRowProcess, intRowExecutionFlag, intRowLastRunTimeandStatus, intRowLastRunEmployeeNo, intRowLastRunErrorMessage, intRowDefectDescription, intRowAutomationComments, intRowQAComments, intRow0, intRowAutomation Ref, | D11: ="str" & A11 & ", " -> strAutomation Ref, | E11: =E10 &D11 -> strProcess, strExecutionFlag, strLastRunTimeandStatus, strLastRunEmployeeNo, strLastRunErrorMessage, strDefectDescription, strAutomationComments, strQAComments, str0, strAutomation Ref, | F11: ="intRow" & A11 & " = comExcelWorksheet.Range(""" & A11 & """).Row" -> intRowAutomation Ref = comExcelWorksheet.Range("Automation Ref").Row | G11: ="str" & A11 & " = comExcelWorksheet.Cells(intRow" & A11 & ", intColTestColumn).Value" -> strAutomation Ref = comExcelWorksheet.Cells(intRowAutomation Ref, intColTestColumn).Value | H11: ="Public Property Get get" & A11 & "() : get" & A11 & " = str" & A11 & " : End Property" -> Public Property Get getAutomation Ref() : getAutomation Ref = strAutomation Ref : End Property
A12: =Test_Data!D14 -> Login_Username | B12: ="intRow" & A12 & ", " -> intRowLogin_Username, | C12: =C11 &B12 -> intRowProcess, intRowExecutionFlag, intRowLastRunTimeandStatus, intRowLastRunEmployeeNo, intRowLastRunErrorMessage, intRowDefectDescription, intRowAutomationComments, intRowQAComments, intRow0, intRowAutomation Ref, intRowLogin_Username, | D12: ="str" & A12 & ", " -> strLogin_Username, | E12: =E11 &D12 -> strProcess, strExecutionFlag, strLastRunTimeandStatus, strLastRunEmployeeNo, strLastRunErrorMessage, strDefectDescription, strAutomationComments, strQAComments, str0, strAutomation Ref, strLogin_Username, | F12: ="intRow" & A12 & " = comExcelWorksheet.Range(""" & A12 & """).Row" -> intRowLogin_Username = comExcelWorksheet.Range("Login_Username").Row | G12: ="str" & A12 & " = comExcelWorksheet.Cells(intRow" & A12 & ", intColTestColumn).Value" -> strLogin_Username = comExcelWorksheet.Cells(intRowLogin_Username, intColTestColumn).Value | H12: ="Public Property Get get" & A12 & "() : get" & A12 & " = str" & A12 & " : End Property" -> Public Property Get getLogin_Username() : getLogin_Username = strLogin_Username : End Property
A13: =Test_Data!D15 -> Login_Password | B13: ="intRow" & A13 & ", " -> intRowLogin_Password, | C13: =C12 &B13 -> intRowProcess, intRowExecutionFlag, intRowLastRunTimeandStatus, intRowLastRunEmployeeNo, intRowLastRunErrorMessage, intRowDefectDescription, intRowAutomationComments, intRowQAComments, intRow0, intRowAutomation Ref, intRowLogin_Username, intRowLogin_Password, | D13: ="str" & A13 & ", " -> strLogin_Password, | E13: =E12 &D13 -> strProcess, strExecutionFlag, strLastRunTimeandStatus, strLastRunEmployeeNo, strLastRunErrorMessage, strDefectDescription, strAutomationComments, strQAComments, str0, strAutomation Ref, strLogin_Username, strLogin_Password, | F13: ="intRow" & A13 & " = comExcelWorksheet.Range(""" & A13 & """).Row" -> intRowLogin_Password = comExcelWorksheet.Range("Login_Password").Row | G13: ="str" & A13 & " = comExcelWorksheet.Cells(intRow" & A13 & ", intColTestColumn).Value" -> strLogin_Password = comExcelWorksheet.Cells(intRowLogin_Password, intColTestColumn).Value | H13: ="Public Property Get get" & A13 & "() : get" & A13 & " = str" & A13 & " : End Property" -> Public Property Get getLogin_Password() : getLogin_Password = strLogin_Password : End Property
A14: =Test_Data!D20 -> SupervisoryOrganisation_SupervisoryOrganisation | B14: ="intRow" & A14 & ", " -> intRowSupervisoryOrganisation_SupervisoryOrganisation, | C14: =C13 &B14 -> intRowProcess, intRowExecutionFlag, intRowLastRunTimeandStatus, intRowLastRunEmployeeNo, intRowLastRunErrorMessage, intRowDefectDescription, intRowAutomationComments, intRowQAComments, intRow0, intRowAutomation Ref, intRowLogin_Username, intRowLogin_Password, intRowSupervisoryOrganisation_SupervisoryOrganisation, | D14: ="str" & A14 & ", " -> strSupervisoryOrganisation_SupervisoryOrganisation, | E14: =E13 &D14 -> strProcess, strExecutionFlag, strLastRunTimeandStatus, strLastRunEmployeeNo, strLastRunErrorMessage, strDefectDescription, strAutomationComments, strQAComments, str0, strAutomation Ref, strLogin_Username, strLogin_Password, strSupervisoryOrganisation_SupervisoryOrganisation, | F14: ="intRow" & A14 & " = comExcelWorksheet.Range(""" & A14 & """).Row" -> intRowSupervisoryOrganisation_SupervisoryOrganisation = comExcelWorksheet.Range("SupervisoryOrganisation_SupervisoryOrganisation").Row | G14: ="str" & A14 & " = comExcelWorksheet.Cells(intRow" & A14 & ", intColTestColumn).Value" -> strSupervisoryOrganisation_SupervisoryOrganisation = comExcelWorksheet.Cells(intRowSupervisoryOrganisation_SupervisoryOrganisation, intColTestColumn).Value | H14: ="Public Property Get get" & A14 & "() : get" & A14 & " = str" & A14 & " : End Property" -> Public Property Get getSupervisoryOrganisation_SupervisoryOrganisation() : getSupervisoryOrganisation_SupervisoryOrganisation = strSupervisoryOrganisation_SupervisoryOrganisation : End Property
A15: =Test_Data!#REF! -> #REF! | B15: ="intRow" & A15 & ", " -> #REF! | C15: =C14 &B15 -> #REF! | D15: ="str" & A15 & ", " -> #REF! | E15: =E14 &D15 -> #REF! | F15: ="intRow" & A15 & " = comExcelWorksheet.Range(""" & A15 & """).Row" -> #REF! | G15: ="str" & A15 & " = comExcelWorksheet.Cells(intRow" & A15 & ", intColTestColumn).Value" -> #REF! | H15: ="Public Property Get get" & A15 & "() : get" & A15 & " = str" & A15 & " : End Property" -> #REF!
A16: =Test_Data!#REF! -> #REF! | B16: ="intRow" & A16 & ", " -> #REF! | C16: =C15 &B16 -> #REF! | D16: ="str" & A16 & ", " -> #REF! | E16: =E15 &D16 -> #REF! | F16: ="intRow" & A16 & " = comExcelWorksheet.Range(""" & A16 & """).Row" -> #REF! | G16: ="str" & A16 & " = comExcelWorksheet.Cells(intRow" & A16 & ", intColTestColumn).Value" -> #REF! | H16: ="Public Property Get get" & A16 & "() : get" & A16 & " = str" & A16 & " : End Property" -> #REF!
A17: =Test_Data!#REF! -> #REF! | B17: ="intRow" & A17 & ", " -> #REF! | C17: =C16 &B17 -> #REF! | D17: ="str" & A17 & ", " -> #REF! | E17: =E16 &D17 -> #REF! | F17: ="intRow" & A17 & " = comExcelWorksheet.Range(""" & A17 & """).Row" -> #REF! | G17: ="str" & A17 & " = comExcelWorksheet.Cells(intRow" & A17 & ", intColTestColumn).Value" -> #REF! | H17: ="Public Property Get get" & A17 & "() : get" & A17 & " = str" & A17 & " : End Property" -> #REF!
A18: =Test_Data!#REF! -> #REF! | B18: ="intRow" & A18 & ", " -> #REF! | C18: =C17 &B18 -> #REF! | D18: ="str" & A18 & ", " -> #REF! | E18: =E17 &D18 -> #REF! | F18: ="intRow" & A18 & " = comExcelWorksheet.Range(""" & A18 & """).Row" -> #REF! | G18: ="str" & A18 & " = comExcelWorksheet.Cells(intRow" & A18 & ", intColTestColumn).Value" -> #REF! | H18: ="Public Property Get get" & A18 & "() : get" & A18 & " = str" & A18 & " : End Property" -> #REF!
A19: =Test_Data!#REF! -> #REF! | B19: ="intRow" & A19 & ", " -> #REF! | C19: =C18 &B19 -> #REF! | D19: ="str" & A19 & ", " -> #REF! | E19: =E18 &D19 -> #REF! | F19: ="intRow" & A19 & " = comExcelWorksheet.Range(""" & A19 & """).Row" -> #REF! | G19: ="str" & A19 & " = comExcelWorksheet.Cells(intRow" & A19 & ", intColTestColumn).Value" -> #REF! | H19: ="Public Property Get get" & A19 & "() : get" & A19 & " = str" & A19 & " : End Property" -> #REF!
A20: =Test_Data!#REF! -> #REF! | B20: ="intRow" & A20 & ", " -> #REF! | C20: =C19 &B20 -> #REF! | D20: ="str" & A20 & ", " -> #REF! | E20: =E19 &D20 -> #REF! | F20: ="intRow" & A20 & " = comExcelWorksheet.Range(""" & A20 & """).Row" -> #REF! | G20: ="str" & A20 & " = comExcelWorksheet.Cells(intRow" & A20 & ", intColTestColumn).Value" -> #REF! | H20: ="Public Property Get get" & A20 & "() : get" & A20 & " = str" & A20 & " : End Property" -> #REF!
A21: =Test_Data!#REF! -> #REF! | B21: ="intRow" & A21 & ", " -> #REF! | C21: =C20 &B21 -> #REF! | D21: ="str" & A21 & ", " -> #REF! | E21: =E20 &D21 -> #REF! | F21: ="intRow" & A21 & " = comExcelWorksheet.Range(""" & A21 & """).Row" -> #REF! | G21: ="str" & A21 & " = comExcelWorksheet.Cells(intRow" & A21 & ", intColTestColumn).Value" -> #REF! | H21: ="Public Property Get get" & A21 & "() : get" & A21 & " = str" & A21 & " : End Property" -> #REF!
A22: =Test_Data!#REF! -> #REF! | B22: ="intRow" & A22 & ", " -> #REF! | C22: =C21 &B22 -> #REF! | D22: ="str" & A22 & ", " -> #REF! | E22: =E21 &D22 -> #REF! | F22: ="intRow" & A22 & " = comExcelWorksheet.Range(""" & A22 & """).Row" -> #REF! | G22: ="str" & A22 & " = comExcelWorksheet.Cells(intRow" & A22 & ", intColTestColumn).Value" -> #REF! | H22: ="Public Property Get get" & A22 & "() : get" & A22 & " = str" & A22 & " : End Property" -> #REF!
A23: =Test_Data!#REF! -> #REF! | B23: ="intRow" & A23 & ", " -> #REF! | C23: =C22 &B23 -> #REF! | D23: ="str" & A23 & ", " -> #REF! | E23: =E22 &D23 -> #REF! | F23: ="intRow" & A23 & " = comExcelWorksheet.Range(""" & A23 & """).Row" -> #REF! | G23: ="str" & A23 & " = comExcelWorksheet.Cells(intRow" & A23 & ", intColTestColumn).Value" -> #REF! | H23: ="Public Property Get get" & A23 & "() : get" & A23 & " = str" & A23 & " : End Property" -> #REF!
A24: =Test_Data!#REF! -> #REF! | B24: ="intRow" & A24 & ", " -> #REF! | C24: =C23 &B24 -> #REF! | D24: ="str" & A24 & ", " -> #REF! | E24: =E23 &D24 -> #REF! | F24: ="intRow" & A24 & " = comExcelWorksheet.Range(""" & A24 & """).Row" -> #REF! | G24: ="str" & A24 & " = comExcelWorksheet.Cells(intRow" & A24 & ", intColTestColumn).Value" -> #REF! | H24: ="Public Property Get get" & A24 & "() : get" & A24 & " = str" & A24 & " : End Property" -> #REF!
A25: =Test_Data!#REF! -> #REF! | B25: ="intRow" & A25 & ", " -> #REF! | C25: =C24 &B25 -> #REF! | D25: ="str" & A25 & ", " -> #REF! | E25: =E24 &D25 -> #REF! | F25: ="intRow" & A25 & " = comExcelWorksheet.Range(""" & A25 & """).Row" -> #REF! | G25: ="str" & A25 & " = comExcelWorksheet.Cells(intRow" & A25 & ", intColTestColumn).Value" -> #REF! | H25: ="Public Property Get get" & A25 & "() : get" & A25 & " = str" & A25 & " : End Property" -> #REF!
A26: =Test_Data!#REF! -> #REF! | B26: ="intRow" & A26 & ", " -> #REF! | C26: =C25 &B26 -> #REF! | D26: ="str" & A26 & ", " -> #REF! | E26: =E25 &D26 -> #REF! | F26: ="intRow" & A26 & " = comExcelWorksheet.Range(""" & A26 & """).Row" -> #REF! | G26: ="str" & A26 & " = comExcelWorksheet.Cells(intRow" & A26 & ", intColTestColumn).Value" -> #REF! | H26: ="Public Property Get get" & A26 & "() : get" & A26 & " = str" & A26 & " : End Property" -> #REF!
... A32: =Test_Data!#REF! -> #REF! | B32: ="intRow" & A32 & ", " -> #REF! | C32: =C31 &B32 -> #REF! | D32: ="str" & A32 & ", " -> #REF! | E32: =E31 &D32 -> #REF! | F32: ="intRow" & A32 & " = comExcelWorksheet.Range(""" & A32 & """).Row" -> #REF! | G32: ="str" & A32 & " = comExcelWorksheet.Cells(intRow" & A32 & ", intColTestColumn).Value" -> #REF! | H32: ="Public Property Get get" & A32 & "() : get" & A32 & " = str" & A32 & " : End Property" -> #REF!
A33: =Test_Data!D22 -> JobDetails_HireDate | B33: ="intRow" & A33 & ", " -> intRowJobDetails_HireDate, | C33: =C32 &B33 -> #REF! | D33: ="str" & A33 & ", " -> strJobDetails_HireDate, | E33: =E32 &D33 -> #REF! | F33: ="intRow" & A33 & " = comExcelWorksheet.Range(""" & A33 & """).Row" -> intRowJobDetails_HireDate = comExcelWorksheet.Range("JobDetails_HireDate").Row | G33: ="str" & A33 & " = comExcelWorksheet.Cells(intRow" & A33 & ", intColTestColumn).Value" -> strJobDetails_HireDate = comExcelWorksheet.Cells(intRowJobDetails_HireDate, intColTestColumn).Value | H33: ="Public Property Get get" & A33 & "() : get" & A33 & " = str" & A33 & " : End Property" -> Public Property Get getJobDetails_HireDate() : getJobDetails_HireDate = strJobDetails_HireDate : End Property
A34: =Test_Data!D23 -> JobDetails_Reason | B34: ="intRow" & A34 & ", " -> intRowJobDetails_Reason, | C34: =C33 &B34 -> #REF! | D34: ="str" & A34 & ", " -> strJobDetails_Reason, | E34: =E33 &D34 -> #REF! | F34: ="intRow" & A34 & " = comExcelWorksheet.Range(""" & A34 & """).Row" -> intRowJobDetails_Reason = comExcelWorksheet.Range("JobDetails_Reason").Row | G34: ="str" & A34 & " = comExcelWorksheet.Cells(intRow" & A34 & ", intColTestColumn).Value" -> strJobDetails_Reason = comExcelWorksheet.Cells(intRowJobDetails_Reason, intColTestColumn).Value | H34: ="Public Property Get get" & A34 & "() : get" & A34 & " = str" & A34 & " : End Property" -> Public Property Get getJobDetails_Reason() : getJobDetails_Reason = strJobDetails_Reason : End Property
