Workbook
Name AddProbationPeriod_EndDate: Test_Data!$F$38
Name AddProbationPeriod_ProbationEndDate: Test_Data!#REF!
Name AddProbationPeriod_ProbationEndDate2: Automation_Lookups!$BB$2:$BB$4
Name AddProbationPeriod_StartDate: Test_Data!$F$37
Name AssignPayGroup_ProposedPayGroup: Test_Data!#REF!
Name AssignPayGroup_ProposedPayGroup: Automation_Lookups!$AH$2:$AH$20
Name AssignPayGroup_ProposedPayGroup2: Automation_Lookups!$AH$2
Name AssignPayGroup_ProposedPayGroupFinal: Test_Data!#REF!
Name Automation_Ref: Test_Data!#REF!
Name AutomationComments: Test_Data!$F$9
Name ChangeJob_AssignCollectiveAgreement_CollectiveAgreement: Test_Data!$F$42
Name ChangeJob_AssignCollectiveAgreement_Level: Test_Data!$F$44
Name ChangeJob_AssignCollectiveAgreement_ProfessionalCategory: Test_Data!$F$43
Name ChangeJob_Company_CostCentre: Test_Data!$F$35
Name ChangeJob_Company_Department: Test_Data!$F$36
Name ChangeJob_JobClassifications_AdditionalJobClassifications: Test_Data!$F$27
Name ChangeJob_JobClassifications_AssignmentType: Test_Data!$F$33
Name ChangeJob_JobClassifications_DefaultWeeklyHours: Test_Data!$F$31
Name ChangeJob_JobClassifications_EmployeeType: Test_Data!$F$28
Name ChangeJob_JobClassifications_EndEmploymentDate: Test_Data!$F$32
Name ChangeJob_JobClassifications_FirstDayofWork: Test_Data!$F$34
Name ChangeJob_JobClassifications_PayRateType: Test_Data!$F$30
Name ChangeJob_JobClassifications_TimeType: Test_Data!$F$29
Name ChangeJob_JobProfile_JobProfile: Test_Data!$F$22
Name ChangeJob_JobProfile_JobTitle: Test_Data!$F$23
Name ChangeJob_LocationDetails_Location: Test_Data!$F$24
Name ChangeJob_LocationDetails_ScheduledWeeklyHours: Test_Data!$F$25
Name ChangeJob_LocationDetails_WorkShift: Test_Data!$F$26
Name ChangeJob_LocationDetails_WorkShift2: Automation_Lookups!$I$2:$I$6
Name ChangeJob_Start_EffectiveDate: Test_Data!$F$16
Name ChangeJob_Start_NewLocation: Test_Data!$F$20
Name ChangeJob_Start_NewLocation2: Automation_Lookups!$G$2:$G$3
Name ChangeJob_Start_NewManager: Test_Data!$F$18
Name ChangeJob_Start_NewManager2: Automation_Lookups!$E$2:$E$3
Name ChangeJob_Start_NewTeam: Test_Data!$F$19
Name ChangeJob_Start_NewTeam2: Automation_Lookups!$F$2:$F$3
Name ChangeJob_Start_NextPayPeriod: Test_Data!$F$21
Name ChangeJob_Start_NextPayPeriod2: Automation_Lookups!$H$2:$H$3
Name ChangeJob_Start_NextPayPeriod22: Automation_Lookups!$I$2:$I$6
Name ChangeJob_Start_Reason: Test_Data!$F$17
Name ChangeJob_Start_Reason2: Automation_Lookups!$D$2:$D$3
Name ChangeMyEmergencyContacts_City: Test_Data!#REF!
Name ChangeMyEmergencyContacts_EmailAddress: Test_Data!#REF!
Name ChangeMyEmergencyContacts_FamilyName: Test_Data!#REF!
Name ChangeMyEmergencyContacts_GivenName: Test_Data!#REF!
Name ChangeMyEmergencyContacts_PhoneDevice: Test_Data!#REF!
Name ChangeMyEmergencyContacts_PhoneDevice2: Automation_Lookups!$AX$2:$AX$3
Name ChangeMyEmergencyContacts_PhoneNumber: Test_Data!#REF!
Name ChangeMyEmergencyContacts_PostalCode: Test_Data!#REF!
Name ChangeMyEmergencyContacts_Relationship: Test_Data!#REF!
Name ChangeMyEmergencyContacts_Relationship2: Automation_Lookups!$AW$2:$AW$5
Name ChangeMyEmergencyContacts_StreetName: Test_Data!#REF!
Name ChangeMyGovernmentIDs_NationalIDs_AddEditID: Test_Data!#REF!
Name ChangeMyGovernmentIDs_NationalIDs_AddEditID1: Test_Data!#REF!
Name ChangeMyGovernmentIDs_NationalIDs_AddEditID2: Test_Data!#REF!
Name ChangeMyGovernmentIDs_NationalIDs_Country1: Test_Data!#REF!
Name ChangeMyGovernmentIDs_NationalIDs_Country2: Test_Data!#REF!
Name ChangeMyGovernmentIDs_NationalIDs_NationalIDType1: Test_Data!#REF!
Name ChangeMyGovernmentIDs_NationalIDs_NationalIDType12: Automation_Lookups!$BH$2
Name ChangeMyGovernmentIDs_NationalIDs_NationalIDType2: Test_Data!#REF!

Sheet Information
A1: Version | F1: Info
A6: Version | B6: 0.3 | F6: Info
F7: Dates | G7: For Czech all dates to be entered in format of DD/MM/YYYY
A8: History | F8: Unhighlighted fields | G8: Only data in unhighlighted fields can be changed.
A9: Date | B9: Version | C9: Details | F9: Red highlighted fields | G9: Indicates fields where unique data is required otherwise automation will throw errors
A10: 44061 | B10: 0.3 | C10: Initial Release | F10: Grey highlighted fields | G10: Indicates fields that cannot be changed
F11: Last Run Status / Last Run Error Message | G11: When automation has run for a particular test, we need to check the status is set to Passed and no error messages are present for each test before the automation run for that particular test is considered valid

Sheet Test_Data
B1: Version_Number | D1: Test_ID | E1: =SUBSTITUTE(D1," ","") -> Test_ID | F1: =E1&2 -> Test_ID2 | G1: Notes | H1: Test_1 | I1: Test_2 | J1: Test_3 | K1: Test_4 | L1: Test_5 | M1: Test_6 | N1: Test_7 | O1: Test_8 | P1: Test_9 | Q1: Test_10 | R1: Test_11 | S1: Test_12 | T1: Test_13 | U1: Test_14 | V1: Test_15 | W1: Test_16 | X1: Test_17 | Y1: Test_18 | Z1: Test_19 | AA1: Test_20 | AB1: Test_21 | AC1: Test_22 | AD1: Test_23 | AE1: Test_24 | AF1: Test_25 | AG1: Test_26 | AH1: Test_27 | AI1: Test_28 | AJ1: Test_29 | AK1: Test_30 | AL1: Test_31 | AM1: Test_32 | AN1: Test_33 | AO1: Test_34 | AP1: Test_35 | AQ1: Test_36 | AR1: Test_37 | AS1: Test_38 | AT1: Test_39 | AU1: Test_40 | AV1: Test_41 | AW1: Test_42 | AX1: Test_43 | AY1: Test_44 | AZ1: Test_45 | BA1: Test_46 | BB1: Test_47 | BC1: Test_48 | BD1: Test_49 | BE1: Test_50 | BF1: Test_51 | BG1: Test_52 | BH1: Test_53 | BI1: Test_54 | BJ1: Test_55 | BK1: Test_56 | BL1: Test_57 | BM1: Test_58 | BN1: Test_59 | BO1: Test_60 | BP1: Test_61 | BQ1: Test_62 | BR1: Test_63 | BS1: Test_64 | BT1: Test_65 | BU1: Test_66 | BV1: Test_67 | BW1: Test_68 | BX1: Test_69 | BY1: Test_70 | BZ1: Test_71 | CA1: Test_72 | CB1: Test_73 | CC1: Test_74 | CD1: Test_75 | CE1: Test_76 | CF1: Test_77 | CG1: Test_78 | CH1: Test_79 | CI1: Test_80 | CJ1: Test_81 | CK1: Test_82 | CL1: Test_83 | CM1: Test_84 | CN1: Test_85 | CO1: Test_86 | CP1: Test_87 | CQ1: Test_88 | CR1: Test_89 | CS1: Test_90 | CT1: Test_91 | CU1: Test_92 | CV1: Test_93 | CW1: Test_94 | CX1: Test_95 | CY1: Test_96 | CZ1: Test_97 | DA1: Test_98 | DB1: Test_99
B2: =Information!B6 -> 0.3 | D2: Reporting_ID | H2: 1 | I2: 2 | J2: 3 | K2: 4 | L2: 5 | M2: 6 | N2: 7 | O2: 8 | P2: 9 | Q2: 10 | R2: 11 | S2: 12 | T2: 13 | U2: 14 | V2: 15 | W2: 16 | X2: 17 | Y2: 18 | Z2: 19 | AA2: 20 | AB2: 21 | AC2: 22 | AD2: 23 | AE2: 24 | AF2: 25 | AG2: 26 | AH2: 27 | AI2: 28 | AJ2: 29 | AK2: 30 | AL2: 31 | AM2: 32 | AN2: 33 | AO2: 34 | AP2: 35 | AQ2: 36 | AR2: 37 | AS2: 38 | AT2: 39 | AU2: 40 | AV2: 41 | AW2: 42 | AX2: 43 | AY2: 44 | AZ2: 45 | BA2: 46 | BB2: 47 | BC2: 48 | BD2: 49 | BE2: 50 | BF2: 51 | BG2: 52 | BH2: 53 | BI2: 54 | BJ2: 55 | BK2: 56 | BL2: 57 | BM2: 58 | BN2: 59 | BO2: 60 | BP2: 61 | BQ2: 62 | BR2: 63 | BS2: 64 | BT2: 65 | BU2: 66 | BV2: 67 | BW2: 68 | BX2: 69 | BY2: 70 | BZ2: 71 | CA2: 72 | CB2: 73 | CC2: 74 | CD2: 75 | CE2: 76 | CF2: 77 | CG2: 78 | CH2: 79 | CI2: 80 | CJ2: 81 | CK2: 82 | CL2: 83 | CM2: 84 | CN2: 85 | CO2: 86 | CP2: 87 | CQ2: 88 | CR2: 89 | CS2: 90 | CT2: 91 | CU2: 92 | CV2: 93 | CW2: 94 | CX2: 95 | CY2: 96 | CZ2: 97 | DA2: 98 | DB2: 99
D3: Process | E3: =SUBSTITUTE(D3," ","") -> Process | F3: =E3&2 -> Process2 | G3: If a manager hire and new role is required then select "New Role and New Hire" otherwise select "New Hire | H3: FullTime_To_PartTime | I3: FullTime_To_PartTime | J3: FullTime_To_PartTime | K3: FullTime_To_PartTime | L3: FullTime_To_PartTime | M3: FullTime_To_PartTime | N3: FullTime_To_PartTime | O3: FullTime_To_PartTime | P3: FullTime_To_PartTime | Q3: FullTime_To_PartTime | R3: FullTime_To_PartTime | S3: FullTime_To_PartTime | T3: FullTime_To_PartTime | U3: FullTime_To_PartTime | V3: FullTime_To_PartTime | W3: FullTime_To_PartTime | X3: FullTime_To_PartTime | Y3: FullTime_To_PartTime | Z3: FullTime_To_PartTime | AA3: FullTime_To_PartTime | AB3: FullTime_To_PartTime | AC3: FullTime_To_PartTime | AD3: FullTime_To_PartTime | AE3: FullTime_To_PartTime | AF3: FullTime_To_PartTime | AG3: FullTime_To_PartTime | AH3: FullTime_To_PartTime | AI3: FullTime_To_PartTime | AJ3: FullTime_To_PartTime | AK3: FullTime_To_PartTime | AL3: FullTime_To_PartTime | AM3: FullTime_To_PartTime | AN3: FullTime_To_PartTime | AO3: FullTime_To_PartTime | AP3: FullTime_To_PartTime | AQ3: FullTime_To_PartTime | AR3: FullTime_To_PartTime | AS3: FullTime_To_PartTime | AT3: FullTime_To_PartTime | AU3: FullTime_To_PartTime | AV3: FullTime_To_PartTime | AW3: FullTime_To_PartTime | AX3: FullTime_To_PartTime | AY3: FullTime_To_PartTime | AZ3: FullTime_To_PartTime | BA3: FullTime_To_PartTime | BB3: FullTime_To_PartTime | BC3: FullTime_To_PartTime | BD3: FullTime_To_PartTime | BE3: FullTime_To_PartTime | BF3: FullTime_To_PartTime | BG3: FullTime_To_PartTime | BH3: FullTime_To_PartTime | BI3: FullTime_To_PartTime | BJ3: FullTime_To_PartTime | BK3: FullTime_To_PartTime | BL3: FullTime_To_PartTime | BM3: FullTime_To_PartTime | BN3: FullTime_To_PartTime | BO3: FullTime_To_PartTime | BP3: FullTime_To_PartTime | BQ3: FullTime_To_PartTime | BR3: FullTime_To_PartTime | BS3: FullTime_To_PartTime | BT3: FullTime_To_PartTime | BU3: FullTime_To_PartTime | BV3: FullTime_To_PartTime | BW3: FullTime_To_PartTime | BX3: FullTime_To_PartTime | BY3: FullTime_To_PartTime | BZ3: FullTime_To_PartTime | CA3: FullTime_To_PartTime | CB3: FullTime_To_PartTime | CC3: FullTime_To_PartTime | CD3: FullTime_To_PartTime | CE3: FullTime_To_PartTime | CF3: FullTime_To_PartTime | CG3: FullTime_To_PartTime | CH3: FullTime_To_PartTime | CI3: FullTime_To_PartTime | CJ3: FullTime_To_PartTime | CK3: FullTime_To_PartTime | CL3: FullTime_To_PartTime | CM3: FullTime_To_PartTime | CN3: FullTime_To_PartTime | CO3: FullTime_To_PartTime | CP3: FullTime_To_PartTime | CQ3: FullTime_To_PartTime | CR3: FullTime_To_PartTime | CS3: FullTime_To_PartTime | CT3: FullTime_To_PartTime | CU3: FullTime_To_PartTime | CV3: FullTime_To_PartTime | CW3: FullTime_To_PartTime | CX3: FullTime_To_PartTime | CY3: FullTime_To_PartTime | CZ3: FullTime_To_PartTime | DA3: FullTime_To_PartTime | DB3: FullTime_To_PartTime
D4: Execution Flag | E4: =SUBSTITUTE(D4," ","") -> ExecutionFlag | F4: =E4&2 -> ExecutionFlag2 | G4: If set to No will not execute in next automation run | H4: Yes | I4: Yes | J4: Yes | K4: Yes | L4: Yes | M4: Yes | N4: Yes | O4: Yes | P4: Yes | Q4: Yes | R4: Yes | S4: Yes | T4: Yes | U4: Yes | V4: Yes | W4: Yes | X4: Yes | Y4: Yes | Z4: Yes | AA4: Yes | AB4: Yes | AC4: Yes | AD4: Yes | AE4: Yes | AF4: Yes | AG4: Yes | AH4: Yes | AI4: Yes | AJ4: Yes | AK4: Yes | AL4: Yes | AM4: Yes | AN4: Yes | AO4: Yes | AP4: Yes | AQ4: Yes | AR4: Yes | AS4: Yes | AT4: Yes | AU4: Yes | AV4: Yes | AW4: Yes | AX4: Yes | AY4: Yes | AZ4: Yes | BA4: Yes | BB4: Yes | BC4: Yes | BD4: Yes | BE4: Yes | BF4: Yes | BG4: Yes | BH4: Yes | BI4: Yes | BJ4: Yes | BK4: Yes | BL4: Yes | BM4: Yes | BN4: Yes | BO4: Yes | BP4: Yes | BQ4: Yes | BR4: Yes | BS4: Yes | BT4: Yes | BU4: Yes | BV4: Yes | BW4: Yes | BX4: Yes | BY4: Yes | BZ4: Yes | CA4: Yes | CB4: Yes | CC4: Yes | CD4: Yes | CE4: Yes | CF4: Yes | CG4: Yes | CH4: Yes | CI4: Yes | CJ4: Yes | CK4: Yes | CL4: Yes | CM4: Yes | CN4: Yes | CO4: Yes | CP4: Yes | CQ4: Yes | CR4: Yes | CS4: Yes | CT4: Yes | CU4: Yes | CV4: Yes | CW4: Yes | CX4: Yes | CY4: Yes | CZ4: Yes | DA4: Yes | DB4: Yes
D5: Country | E5: =SUBSTITUTE(D5," ","") -> Country | F5: =E5&2 -> Country2 | H5: Czechia | I5: Czechia | J5: Czechia | K5: Czechia | L5: Czechia | M5: Czechia | N5: Czechia | O5: Czechia | P5: Czechia | Q5: Czechia | R5: Czechia | S5: Czechia | T5: Czechia | U5: Czechia | V5: Czechia | W5: Czechia | X5: Czechia | Y5: Czechia | Z5: Czechia | AA5: Czechia | AB5: Czechia | AC5: Czechia | AD5: Czechia | AE5: Czechia | AF5: Czechia | AG5: Czechia | AH5: Czechia | AI5: Czechia | AJ5: Czechia | AK5: Czechia | AL5: Czechia | AM5: Czechia | AN5: Czechia | AO5: Czechia | AP5: Czechia | AQ5: Czechia | AR5: Czechia | AS5: Czechia | AT5: Czechia | AU5: Czechia | AV5: Czechia | AW5: Czechia | AX5: Czechia | AY5: Czechia | AZ5: Czechia | BA5: Czechia | BB5: Czechia | BC5: Czechia | BD5: Czechia | BE5: Czechia | BF5: Czechia | BG5: Czechia | BH5: Czechia | BI5: Czechia | BJ5: Czechia | BK5: Czechia | BL5: Czechia | BM5: Czechia | BN5: Czechia | BO5: Czechia | BP5: Czechia | BQ5: Czechia | BR5: Czechia | BS5: Czechia | BT5: Czechia | BU5: Czechia | BV5: Czechia | BW5: Czechia | BX5: Czechia | BY5: Czechia | BZ5: Czechia | CA5: Czechia | CB5: Czechia | CC5: Czechia | CD5: Czechia | CE5: Czechia | CF5: Czechia | CG5: Czechia | CH5: Czechia | CI5: Czechia | CJ5: Czechia | CK5: Czechia | CL5: Czechia | CM5: Czechia | CN5: Czechia | CO5: Czechia | CP5: Czechia | CQ5: Czechia | CR5: Czechia | CS5: Czechia | CT5: Czechia | CU5: Czechia | CV5: Czechia | CW5: Czechia | CX5: Czechia | CY5: Czechia | CZ5: Czechia | DA5: Czechia | DB5: Czechia
D6: Last Run Time and Status | E6: =SUBSTITUTE(D6," ","") -> LastRunTimeandStatus | F6: =E6&2 -> LastRunTimeandStatus2 | G6: Once test is executed the Execution Timestamp and Pass/Fail status will be recorded here
A7: Portugal-Fixed_To_Permanent | D7: Last Run Error Message | E7: =SUBSTITUTE(D7," ","") -> LastRunErrorMessage | F7: =E7&2 -> LastRunErrorMessage2 | G7: If Automation throws errors, the details will be placed here
D8: Defect Description | E8: =SUBSTITUTE(D8," ","") -> DefectDescription | F8: =E8&2 -> DefectDescription2 | G8: After error investigation by the automation team, the defect description will be completed here
D9: Automation Comments | E9: =SUBSTITUTE(D9," ","") -> AutomationComments | F9: =E9&2 -> AutomationComments2 | G9: Automation team free text field
D10: QA Comments | E10: =SUBSTITUTE(D10," ","") -> QAComments | F10: =E10&2 -> QAComments2 | G10: QA team free text field
B12: Screen | C12: Subscreen | D12: Field | E12: Automation Ref | F12: Lookups Ref | H12: Test_1 | I12: Test_2 | J12: Test_3 | K12: Test_4 | L12: Test_5 | M12: Test_6 | N12: Test_7 | O12: Test_8 | P12: Test_9 | Q12: Test_10 | R12: Test_11 | S12: Test_12 | T12: Test_13 | U12: Test_14 | V12: Test_15 | W12: Test_16 | X12: Test_17 | Y12: Test_18 | Z12: Test_19 | AA12: Test_20 | AB12: Test_21 | AC12: Test_22 | AD12: Test_23 | AE12: Test_24 | AF12: Test_25 | AG12: Test_26 | AH12: Test_27 | AI12: Test_28 | AJ12: Test_29 | AK12: Test_30 | AL12: Test_31 | AM12: Test_32 | AN12: Test_33 | AO12: Test_34 | AP12: Test_35 | AQ12: Test_36 | AR12: Test_37 | AS12: Test_38 | AT12: Test_39 | AU12: Test_40 | AV12: Test_41 | AW12: Test_42 | AX12: Test_43 | AY12: Test_44 | AZ12: Test_45 | BA12: Test_46 | BB12: Test_47 | BC12: Test_48 | BD12: Test_49 | BE12: Test_50 | BF12: Test_51 | BG12: Test_52 | BH12: Test_53 | BI12: Test_54 | BJ12: Test_55 | BK12: Test_56 | BL12: Test_57 | BM12: Test_58 | BN12: Test_59 | BO12: Test_60 | BP12: Test_61 | BQ12: Test_62 | BR12: Test_63 | BS12: Test_64 | BT12: Test_65 | BU12: Test_66 | BV12: Test_67 | BW12: Test_68 | BX12: Test_69 | BY12: Test_70 | BZ12: Test_71 | CA12: Test_72 | CB12: Test_73 | CC12: Test_74 | CD12: Test_75 | CE12: Test_76 | CF12: Test_77 | CG12: Test_78 | CH12: Test_79 | CI12: Test_80 | CJ12: Test_81 | CK12: Test_82 | CL12: Test_83 | CM12: Test_84 | CN12: Test_85 | CO12: Test_86 | CP12: Test_87 | CQ12: Test_88 | CR12: Test_89 | CS12: Test_90 | CT12: Test_91 | CU12: Test_92 | CV12: Test_93 | CW12: Test_94 | CX12: Test_95 | CY12: Test_96 | CZ12: Test_97 | DA12: Test_98 | DB12: Test_99
A13: Romania-Promotion, Portugal-PT_To_FT, Portugal-Fixed_To_Permanent | B13: Login | C13: N/A | D13: Username | E13: =SUBSTITUTE(B13," ","") & "_" & SUBSTITUTE(IF(C13="N/A","",C13& "_")," ","") & SUBSTITUTE(SUBSTITUTE(D13," ",""),"/","") -> Login_Username | F13: =E13&2 -> Login_Username2 | H13: 90002195 | I13: 90002195 | J13: 90002195 | K13: 90002195 | L13: 90002195 | M13: 90002195 | N13: 90002195 | O13: 90002195 | P13: 90002195 | Q13: 90002195 | R13: 90002195 | S13: 90002195 | T13: 90002195 | U13: 90002195 | V13: 90002195 | W13: 90002195 | X13: 90002195 | Y13: 90002195 | Z13: 90002195 | AA13: 90002195 | AB13: 90002195 | AC13: 90002195 | AD13: 90002195 | AE13: 90002195 | AF13: 90002195 | AG13: 90002195 | AH13: 90002195 | AI13: 90002195 | AJ13: 90002195 | AK13: 90002195 | AL13: 90002195 | AM13: 90002195 | AN13: 90002195 | AO13: 90002195 | AP13: 90002195 | AQ13: 90002195 | AR13: 90002195 | AS13: 90002195 | AT13: 90002195 | AU13: 90002195 | AV13: 90002195 | AW13: 90002195 | AX13: 90002195 | AY13: 90002195 | AZ13: 90002195 | BA13: 90002195 | BB13: 90002195 | BC13: 90002195 | BD13: 90002195 | BE13: 90002195 | BF13: 90002195 | BG13: 90002195 | BH13: 90002195 | BI13: 90002195 | BJ13: 90002195 | BK13: 90002195 | BL13: 90002195 | BM13: 90002195 | BN13: 90002195 | BO13: 90002195 | BP13: 90002195 | BQ13: 90002195 | BR13: 90002195 | BS13: 90002195 | BT13: 90002195 | BU13: 90002195 | BV13: 90002195 | BW13: 90002195 | BX13: 90002195 | BY13: 90002195 | BZ13: 90002195 | CA13: 90002195 | CB13: 90002195 | CC13: 90002195 | CD13: 90002195 | CE13: 90002195 | CF13: 90002195 | CG13: 90002195 | CH13: 90002195 | CI13: 90002195 | CJ13: 90002195 | CK13: 90002195 | CL13: 90002195 | CM13: 90002195 | CN13: 90002195 | CO13: 90002195 | CP13: 90002195 | CQ13: 90002195 | CR13: 90002195 | CS13: 90002195 | CT13: 90002195 | CU13: 90002195 | CV13: 90002195 | CW13: 90002195 | CX13: 90002195 | CY13: 90002195 | CZ13: 90002195 | DA13: 90002195 | DB13: 90002195
A14: Romania-Promotion, Portugal-PT_To_FT, Portugal-Fixed_To_Permanent | B14: Login | C14: N/A | D14: Password | E14: =SUBSTITUTE(B14," ","") & "_" & SUBSTITUTE(IF(C14="N/A","",C14& "_")," ","") & SUBSTITUTE(SUBSTITUTE(D14," ",""),"/","") -> Login_Password | F14: =E14&2 -> Login_Password2 | H14: 65b795c1bf6d6c61cb007af2857d7d25d389ffbd49fc2e3cd7e638df | I14: 65b795c1bf6d6c61cb007af2857d7d25d389ffbd49fc2e3cd7e638df | J14: 65b795c1bf6d6c61cb007af2857d7d25d389ffbd49fc2e3cd7e638df | K14: 65b795c1bf6d6c61cb007af2857d7d25d389ffbd49fc2e3cd7e638df | L14: 65b795c1bf6d6c61cb007af2857d7d25d389ffbd49fc2e3cd7e638df | M14: 65b795c1bf6d6c61cb007af2857d7d25d389ffbd49fc2e3cd7e638df | N14: 65b795c1bf6d6c61cb007af2857d7d25d389ffbd49fc2e3cd7e638df | O14: 65b795c1bf6d6c61cb007af2857d7d25d389ffbd49fc2e3cd7e638df | P14: 65b795c1bf6d6c61cb007af2857d7d25d389ffbd49fc2e3cd7e638df | Q14: 65b795c1bf6d6c61cb007af2857d7d25d389ffbd49fc2e3cd7e638df | R14: 65b795c1bf6d6c61cb007af2857d7d25d389ffbd49fc2e3cd7e638df | S14: 65b795c1bf6d6c61cb007af2857d7d25d389ffbd49fc2e3cd7e638df | T14: 65b795c1bf6d6c61cb007af2857d7d25d389ffbd49fc2e3cd7e638df | U14: 65b795c1bf6d6c61cb007af2857d7d25d389ffbd49fc2e3cd7e638df | V14: 65b795c1bf6d6c61cb007af2857d7d25d389ffbd49fc2e3cd7e638df | W14: 65b795c1bf6d6c61cb007af2857d7d25d389ffbd49fc2e3cd7e638df | X14: 65b795c1bf6d6c61cb007af2857d7d25d389ffbd49fc2e3cd7e638df | Y14: 65b795c1bf6d6c61cb007af2857d7d25d389ffbd49fc2e3cd7e638df | Z14: 65b795c1bf6d6c61cb007af2857d7d25d389ffbd49fc2e3cd7e638df | AA14: 65b795c1bf6d6c61cb007af2857d7d25d389ffbd49fc2e3cd7e638df | AB14: 65b795c1bf6d6c61cb007af2857d7d25d389ffbd49fc2e3cd7e638df | AC14: 65b795c1bf6d6c61cb007af2857d7d25d389ffbd49fc2e3cd7e638df | AD14: 65b795c1bf6d6c61cb007af2857d7d25d389ffbd49fc2e3cd7e638df | AE14: 65b795c1bf6d6c61cb007af2857d7d25d389ffbd49fc2e3cd7e638df | AF14: 65b795c1bf6d6c61cb007af2857d7d25d389ffbd49fc2e3cd7e638df | AG14: 65b795c1bf6d6c61cb007af2857d7d25d389ffbd49fc2e3cd7e638df | AH14: 65b795c1bf6d6c61cb007af2857d7d25d389ffbd49fc2e3cd7e638df | AI14: 65b795c1bf6d6c61cb007af2857d7d25d389ffbd49fc2e3cd7e638df | AJ14: 65b795c1bf6d6c61cb007af2857d7d25d389ffbd49fc2e3cd7e638df | AK14: 65b795c1bf6d6c61cb007af2857d7d25d389ffbd49fc2e3cd7e638df | AL14: 65b795c1bf6d6c61cb007af2857d7d25d389ffbd49fc2e3cd7e638df | AM14: 65b795c1bf6d6c61cb007af2857d7d25d389ffbd49fc2e3cd7e638df | AN14: 65b795c1bf6d6c61cb007af2857d7d25d389ffbd49fc2e3cd7e638df | AO14: 65b795c1bf6d6c61cb007af2857d7d25d389ffbd49fc2e3cd7e638df | AP14: 65b795c1bf6d6c61cb007af2857d7d25d389ffbd49fc2e3cd7e638df | AQ14: 65b795c1bf6d6c61cb007af2857d7d25d389ffbd49fc2e3cd7e638df | AR14: 65b795c1bf6d6c61cb007af2857d7d25d389ffbd49fc2e3cd7e638df | AS14: 65b795c1bf6d6c61cb007af2857d7d25d389ffbd49fc2e3cd7e638df | AT14: 65b795c1bf6d6c61cb007af2857d7d25d389ffbd49fc2e3cd7e638df | AU14: 65b795c1bf6d6c61cb007af2857d7d25d389ffbd49fc2e3cd7e638df | AV14: 65b795c1bf6d6c61cb007af2857d7d25d389ffbd49fc2e3cd7e638df | AW14: 65b795c1bf6d6c61cb007af2857d7d25d389ffbd49fc2e3cd7e638df | AX14: 65b795c1bf6d6c61cb007af2857d7d25d389ffbd49fc2e3cd7e638df | AY14: 65b795c1bf6d6c61cb007af2857d7d25d389ffbd49fc2e3cd7e638df | AZ14: 65b795c1bf6d6c61cb007af2857d7d25d389ffbd49fc2e3cd7e638df | BA14: 65b795c1bf6d6c61cb007af2857d7d25d389ffbd49fc2e3cd7e638df | BB14: 65b795c1bf6d6c61cb007af2857d7d25d389ffbd49fc2e3cd7e638df | BC14: 65b795c1bf6d6c61cb007af2857d7d25d389ffbd49fc2e3cd7e638df | BD14: 65b795c1bf6d6c61cb007af2857d7d25d389ffbd49fc2e3cd7e638df | BE14: 65b795c1bf6d6c61cb007af2857d7d25d389ffbd49fc2e3cd7e638df | BF14: 65b795c1bf6d6c61cb007af2857d7d25d389ffbd49fc2e3cd7e638df | BG14: 65b795c1bf6d6c61cb007af2857d7d25d389ffbd49fc2e3cd7e638df | BH14: 65b795c1bf6d6c61cb007af2857d7d25d389ffbd49fc2e3cd7e638df | BI14: 65b795c1bf6d6c61cb007af2857d7d25d389ffbd49fc2e3cd7e638df | BJ14: 65b795c1bf6d6c61cb007af2857d7d25d389ffbd49fc2e3cd7e638df | BK14: 65b795c1bf6d6c61cb007af2857d7d25d389ffbd49fc2e3cd7e638df | BL14: 65b795c1bf6d6c61cb007af2857d7d25d389ffbd49fc2e3cd7e638df | BM14: 65b795c1bf6d6c61cb007af2857d7d25d389ffbd49fc2e3cd7e638df | BN14: 65b795c1bf6d6c61cb007af2857d7d25d389ffbd49fc2e3cd7e638df | BO14: 65b795c1bf6d6c61cb007af2857d7d25d389ffbd49fc2e3cd7e638df | BP14: 65b795c1bf6d6c61cb007af2857d7d25d389ffbd49fc2e3cd7e638df | BQ14: 65b795c1bf6d6c61cb007af2857d7d25d389ffbd49fc2e3cd7e638df | BR14: 65b795c1bf6d6c61cb007af2857d7d25d389ffbd49fc2e3cd7e638df | BS14: 65b795c1bf6d6c61cb007af2857d7d25d389ffbd49fc2e3cd7e638df | BT14: 65b795c1bf6d6c61cb007af2857d7d25d389ffbd49fc2e3cd7e638df | BU14: 65b795c1bf6d6c61cb007af2857d7d25d389ffbd49fc2e3cd7e638df | BV14: 65b795c1bf6d6c61cb007af2857d7d25d389ffbd49fc2e3cd7e638df | BW14: 65b795c1bf6d6c61cb007af2857d7d25d389ffbd49fc2e3cd7e638df | BX14: 65b795c1bf6d6c61cb007af2857d7d25d389ffbd49fc2e3cd7e638df | BY14: 65b795c1bf6d6c61cb007af2857d7d25d389ffbd49fc2e3cd7e638df | BZ14: 65b795c1bf6d6c61cb007af2857d7d25d389ffbd49fc2e3cd7e638df | CA14: 65b795c1bf6d6c61cb007af2857d7d25d389ffbd49fc2e3cd7e638df | CB14: 65b795c1bf6d6c61cb007af2857d7d25d389ffbd49fc2e3cd7e638df | CC14: 65b795c1bf6d6c61cb007af2857d7d25d389ffbd49fc2e3cd7e638df | CD14: 65b795c1bf6d6c61cb007af2857d7d25d389ffbd49fc2e3cd7e638df | CE14: 65b795c1bf6d6c61cb007af2857d7d25d389ffbd49fc2e3cd7e638df | CF14: 65b795c1bf6d6c61cb007af2857d7d25d389ffbd49fc2e3cd7e638df | CG14: 65b795c1bf6d6c61cb007af2857d7d25d389ffbd49fc2e3cd7e638df | CH14: 65b795c1bf6d6c61cb007af2857d7d25d389ffbd49fc2e3cd7e638df | CI14: 65b795c1bf6d6c61cb007af2857d7d25d389ffbd49fc2e3cd7e638df | CJ14: 65b795c1bf6d6c61cb007af2857d7d25d389ffbd49fc2e3cd7e638df | CK14: 65b795c1bf6d6c61cb007af2857d7d25d389ffbd49fc2e3cd7e638df | CL14: 65b795c1bf6d6c61cb007af2857d7d25d389ffbd49fc2e3cd7e638df | CM14: 65b795c1bf6d6c61cb007af2857d7d25d389ffbd49fc2e3cd7e638df | CN14: 65b795c1bf6d6c61cb007af2857d7d25d389ffbd49fc2e3cd7e638df | CO14: 65b795c1bf6d6c61cb007af2857d7d25d389ffbd49fc2e3cd7e638df | CP14: 65b795c1bf6d6c61cb007af2857d7d25d389ffbd49fc2e3cd7e638df | CQ14: 65b795c1bf6d6c61cb007af2857d7d25d389ffbd49fc2e3cd7e638df | CR14: 65b795c1bf6d6c61cb007af2857d7d25d389ffbd49fc2e3cd7e638df | CS14: 65b795c1bf6d6c61cb007af2857d7d25d389ffbd49fc2e3cd7e638df | CT14: 65b795c1bf6d6c61cb007af2857d7d25d389ffbd49fc2e3cd7e638df | CU14: 65b795c1bf6d6c61cb007af2857d7d25d389ffbd49fc2e3cd7e638df | CV14: 65b795c1bf6d6c61cb007af2857d7d25d389ffbd49fc2e3cd7e638df | CW14: 65b795c1bf6d6c61cb007af2857d7d25d389ffbd49fc2e3cd7e638df | CX14: 65b795c1bf6d6c61cb007af2857d7d25d389ffbd49fc2e3cd7e638df | CY14: 65b795c1bf6d6c61cb007af2857d7d25d389ffbd49fc2e3cd7e638df | CZ14: 65b795c1bf6d6c61cb007af2857d7d25d389ffbd49fc2e3cd7e638df | DA14: 65b795c1bf6d6c61cb007af2857d7d25d389ffbd49fc2e3cd7e638df | DB14: 65b795c1bf6d6c61cb007af2857d7d25d389ffbd49fc2e3cd7e638df
A15: Romania-Promotion, Portugal-PT_To_FT, Portugal-Fixed_To_Permanent | B15: Proxy | C15: N/A | D15: Employee ID | E15: =SUBSTITUTE(B15," ","") & "_" & SUBSTITUTE(IF(C15="N/A","",C15& "_")," ","") & SUBSTITUTE(SUBSTITUTE(D15," ",""),"/","") -> Proxy_EmployeeID | F15: =E15&2 -> Proxy_EmployeeID2 | H15: 10543013 | I15: 10565020 | J15: 10550629 | K15: 10616945 | L15: 10628812 | M15: 10514677 | N15: 10576087 | O15: 10576250 | P15: 10581486 | Q15: 10576088 | R15: 10576897 | S15: 10509271 | T15: 10616779 | U15: 10575849 | V15: 10506533 | W15: 10576183 | X15: 10537124 | Y15: 10565049 | Z15: 10502364 | AA15: 10540543 | AB15: 10561673 | AC15: 10581485 | AD15: 10495993 | AE15: 10513485 | AF15: 10256836 | AG15: 10576095 | AH15: 10588288 | AI15: 10250271 | AJ15: 10568627 | AK15: 10568608 | AL15: 10511417 | AM15: 10513256 | AN15: 10598394 | AO15: 10543072 | AP15: 10628115 | AQ15: 10622284 | AR15: 10622213 | AS15: 10514684 | AT15: 10572404 | AU15: 10622265 | AV15: 10568803 | AW15: 10602155 | AX15: 10588040 | AY15: 10598424 | AZ15: 10580440 | BA15: 10626863 | BB15: 10250339 | BC15: 10511328 | BD15: 10602135 | BE15: 10573791 | BF15: 10561077 | BG15: 10598420 | BH15: 10572393 | BI15: 10502373 | BJ15: 10496001 | BK15: 10616941 | BL15: 10588308 | BM15: 10250345 | BN15: 10255631 | BO15: 10611180 | BP15: 10543391 | BQ15: 10540442 | BR15: 10580332 | BS15: 10573944 | BT15: 10509268 | BU15: 10576104 | BV15: 10611099 | BW15: 10594430 | BX15: 10616798 | BY15: 10596934 | BZ15: 10562732 | CA15: 10587789 | CB15: 10602117 | CC15: 10510348 | CD15: 10573948 | CE15: 10575863 | CF15: 10594588 | CG15: 10502368 | CH15: 10611139 | CI15: 10550764 | CJ15: 10581468 | CK15: 10626908 | CL15: 10647669 | CM15: 10628810 | CN15: 10602148 | CO15: 10647796 | CP15: 10626782 | CQ15: 10253414 | CR15: 10513662 | CS15: 10619279 | CT15: 10607473 | CU15: 10550601 | CV15: 10253758 | CW15: 10607744 | CX15: 10584861 | CY15: 10579983 | CZ15: 10591841 | DA15: 10562707 | DB15: 10544843
A16: Romania-Promotion, Portugal-PT_To_FT, Portugal-Fixed_To_Permanent | B16: Change Job | C16: Start | D16: Effective Date | E16: =SUBSTITUTE(B16," ","") & "_" & SUBSTITUTE(IF(C16="N/A","",C16& "_")," ","") & SUBSTITUTE(SUBSTITUTE(D16," ",""),"/","") -> ChangeJob_Start_EffectiveDate | F16: =E16&2 -> ChangeJob_Start_EffectiveDate2 | H16: 45627 | I16: 45627 | J16: 45627 | K16: 45627 | L16: 45627 | M16: 45627 | N16: 45627 | O16: 45627 | P16: 45627 | Q16: 45627 | R16: 45627 | S16: 45627 | T16: 45627 | U16: 45627 | V16: 45627 | W16: 45627 | X16: 45627 | Y16: 45627 | Z16: 45627 | AA16: 45627 | AB16: 45627 | AC16: 45627 | AD16: 45627 | AE16: 45627 | AF16: 45627 | AG16: 45627 | AH16: 45627 | AI16: 45627 | AJ16: 45627 | AK16: 45627 | AL16: 45627 | AM16: 45627 | AN16: 45627 | AO16: 45627 | AP16: 45627 | AQ16: 45627 | AR16: 45627 | AS16: 45627 | AT16: 45627 | AU16: 45627 | AV16: 45627 | AW16: 45627 | AX16: 45627 | AY16: 45627 | AZ16: 45627 | BA16: 45627 | BB16: 45627 | BC16: 45627 | BD16: 45627 | BE16: 45627 | BF16: 45627 | BG16: 45627 | BH16: 45627 | BI16: 45627 | BJ16: 45627 | BK16: 45627 | BL16: 45627 | BM16: 45627 | BN16: 45627 | BO16: 45627 | BP16: 45627 | BQ16: 45627 | BR16: 45627 | BS16: 45627 | BT16: 45627 | BU16: 45627 | BV16: 45627 | BW16: 45627 | BX16: 45627 | BY16: 45627 | BZ16: 45627 | CA16: 45627 | CB16: 45627 | CC16: 45627 | CD16: 45627 | CE16: 45627 | CF16: 45627 | CG16: 45627 | CH16: 45627 | CI16: 45627 | CJ16: 45627 | CK16: 45627 | CL16: 45627 | CM16: 45627 | CN16: 45627 | CO16: 45627 | CP16: 45627 | CQ16: 45627 | CR16: 45627 | CS16: 45627 | CT16: 45627 | CU16: 45627 | CV16: 45627 | CW16: 45627 | CX16: 45627 | CY16: 45627 | CZ16: 45627 | DA16: 45627 | DB16: 45627
A17: Romania-Promotion, Portugal-PT_To_FT, Portugal-Fixed_To_Permanent | B17: Change Job | C17: Start | D17: Reason | E17: =SUBSTITUTE(B17," ","") & "_" & SUBSTITUTE(IF(C17="N/A","",C17& "_")," ","") & SUBSTITUTE(SUBSTITUTE(D17," ",""),"/","") -> ChangeJob_Start_Reason | F17: =E17&2 -> ChangeJob_Start_Reason2 | G17: Choice of Contractual Change/Promotion | H17: Change of Hours, Employee Type, Time Type, End Employment Date | I17: Change of Hours, Employee Type, Time Type, End Employment Date | J17: Change of Hours, Employee Type, Time Type, End Employment Date | K17: Change of Hours, Employee Type, Time Type, End Employment Date | L17: Change of Hours, Employee Type, Time Type, End Employment Date | M17: Change of Hours, Employee Type, Time Type, End Employment Date | N17: Change of Hours, Employee Type, Time Type, End Employment Date | O17: Change of Hours, Employee Type, Time Type, End Employment Date | P17: Change of Hours, Employee Type, Time Type, End Employment Date | Q17: Change of Hours, Employee Type, Time Type, End Employment Date | R17: Change of Hours, Employee Type, Time Type, End Employment Date | S17: Change of Hours, Employee Type, Time Type, End Employment Date | T17: Change of Hours, Employee Type, Time Type, End Employment Date | U17: Change of Hours, Employee Type, Time Type, End Employment Date | V17: Change of Hours, Employee Type, Time Type, End Employment Date | W17: Change of Hours, Employee Type, Time Type, End Employment Date | X17: Change of Hours, Employee Type, Time Type, End Employment Date | Y17: Change of Hours, Employee Type, Time Type, End Employment Date | Z17: Change of Hours, Employee Type, Time Type, End Employment Date | AA17: Change of Hours, Employee Type, Time Type, End Employment Date | AB17: Change of Hours, Employee Type, Time Type, End Employment Date | AC17: Change of Hours, Employee Type, Time Type, End Employment Date | AD17: Change of Hours, Employee Type, Time Type, End Employment Date | AE17: Change of Hours, Employee Type, Time Type, End Employment Date | AF17: Change of Hours, Employee Type, Time Type, End Employment Date | AG17: Change of Hours, Employee Type, Time Type, End Employment Date | AH17: Change of Hours, Employee Type, Time Type, End Employment Date | AI17: Change of Hours, Employee Type, Time Type, End Employment Date | AJ17: Change of Hours, Employee Type, Time Type, End Employment Date | AK17: Change of Hours, Employee Type, Time Type, End Employment Date | AL17: Change of Hours, Employee Type, Time Type, End Employment Date | AM17: Change of Hours, Employee Type, Time Type, End Employment Date | AN17: Change of Hours, Employee Type, Time Type, End Employment Date | AO17: Change of Hours, Employee Type, Time Type, End Employment Date | AP17: Change of Hours, Employee Type, Time Type, End Employment Date | AQ17: Change of Hours, Employee Type, Time Type, End Employment Date | AR17: Change of Hours, Employee Type, Time Type, End Employment Date | AS17: Change of Hours, Employee Type, Time Type, End Employment Date | AT17: Change of Hours, Employee Type, Time Type, End Employment Date | AU17: Change of Hours, Employee Type, Time Type, End Employment Date | AV17: Change of Hours, Employee Type, Time Type, End Employment Date | AW17: Change of Hours, Employee Type, Time Type, End Employment Date | AX17: Change of Hours, Employee Type, Time Type, End Employment Date | AY17: Change of Hours, Employee Type, Time Type, End Employment Date | AZ17: Change of Hours, Employee Type, Time Type, End Employment Date | BA17: Change of Hours, Employee Type, Time Type, End Employment Date | BB17: Change of Hours, Employee Type, Time Type, End Employment Date | BC17: Change of Hours, Employee Type, Time Type, End Employment Date | BD17: Change of Hours, Employee Type, Time Type, End Employment Date | BE17: Change of Hours, Employee Type, Time Type, End Employment Date | BF17: Change of Hours, Employee Type, Time Type, End Employment Date | BG17: Change of Hours, Employee Type, Time Type, End Employment Date | BH17: Change of Hours, Employee Type, Time Type, End Employment Date | BI17: Change of Hours, Employee Type, Time Type, End Employment Date | BJ17: Change of Hours, Employee Type, Time Type, End Employment Date | BK17: Change of Hours, Employee Type, Time Type, End Employment Date | BL17: Change of Hours, Employee Type, Time Type, End Employment Date | BM17: Change of Hours, Employee Type, Time Type, End Employment Date | BN17: Change of Hours, Employee Type, Time Type, End Employment Date | BO17: Change of Hours, Employee Type, Time Type, End Employment Date | BP17: Change of Hours, Employee Type, Time Type, End Employment Date | BQ17: Change of Hours, Employee Type, Time Type, End Employment Date | BR17: Change of Hours, Employee Type, Time Type, End Employment Date | BS17: Change of Hours, Employee Type, Time Type, End Employment Date | BT17: Change of Hours, Employee Type, Time Type, End Employment Date | BU17: Change of Hours, Employee Type, Time Type, End Employment Date | BV17: Change of Hours, Employee Type, Time Type, End Employment Date | BW17: Change of Hours, Employee Type, Time Type, End Employment Date | BX17: Change of Hours, Employee Type, Time Type, End Employment Date | BY17: Change of Hours, Employee Type, Time Type, End Employment Date | BZ17: Change of Hours, Employee Type, Time Type, End Employment Date | CA17: Change of Hours, Employee Type, Time Type, End Employment Date | CB17: Change of Hours, Employee Type, Time Type, End Employment Date | CC17: Change of Hours, Employee Type, Time Type, End Employment Date | CD17: Change of Hours, Employee Type, Time Type, End Employment Date | CE17: Change of Hours, Employee Type, Time Type, End Employment Date | CF17: Change of Hours, Employee Type, Time Type, End Employment Date | CG17: Change of Hours, Employee Type, Time Type, End Employment Date | CH17: Change of Hours, Employee Type, Time Type, End Employment Date | CI17: Change of Hours, Employee Type, Time Type, End Employment Date | CJ17: Change of Hours, Employee Type, Time Type, End Employment Date | CK17: Change of Hours, Employee Type, Time Type, End Employment Date | CL17: Change of Hours, Employee Type, Time Type, End Employment Date | CM17: Change of Hours, Employee Type, Time Type, End Employment Date | CN17: Change of Hours, Employee Type, Time Type, End Employment Date | CO17: Change of Hours, Employee Type, Time Type, End Employment Date | CP17: Change of Hours, Employee Type, Time Type, End Employment Date | CQ17: Change of Hours, Employee Type, Time Type, End Employment Date | CR17: Change of Hours, Employee Type, Time Type, End Employment Date | CS17: Change of Hours, Employee Type, Time Type, End Employment Date | CT17: Change of Hours, Employee Type, Time Type, End Employment Date | CU17: Change of Hours, Employee Type, Time Type, End Employment Date | CV17: Change of Hours, Employee Type, Time Type, End Employment Date | CW17: Change of Hours, Employee Type, Time Type, End Employment Date | CX17: Change of Hours, Employee Type, Time Type, End Employment Date | CY17: Change of Hours, Employee Type, Time Type, End Employment Date | CZ17: Change of Hours, Employee Type, Time Type, End Employment Date | DA17: Change of Hours, Employee Type, Time Type, End Employment Date | DB17: Change of Hours, Employee Type, Time Type, End Employment Date
A18: Romania-Promotion | B18: Change Job | C18: Start | D18: New Manager | E18: =SUBSTITUTE(B18," ","") & "_" & SUBSTITUTE(IF(C18="N/A","",C18& "_")," ","") & SUBSTITUTE(SUBSTITUTE(D18," ",""),"/","") -> ChangeJob_Start_NewManager | F18: =E18&2 -> ChangeJob_Start_NewManager2 | G18: Only needed if promoted to manager. Otherwise N/A | H18: N/A | I18: N/A | J18: N/A | K18: N/A | L18: N/A | M18: N/A | N18: N/A | O18: N/A | P18: N/A | Q18: N/A | R18: N/A | S18: N/A | T18: N/A | U18: N/A | V18: N/A | W18: N/A | X18: N/A | Y18: N/A | Z18: N/A | AA18: N/A | AB18: N/A | AC18: N/A | AD18: N/A | AE18: N/A | AF18: N/A | AG18: N/A | AH18: N/A | AI18: N/A | AJ18: N/A | AK18: N/A | AL18: N/A | AM18: N/A | AN18: N/A | AO18: N/A | AP18: N/A | AQ18: N/A | AR18: N/A | AS18: N/A | AT18: N/A | AU18: N/A | AV18: N/A | AW18: N/A | AX18: N/A | AY18: N/A | AZ18: N/A | BA18: N/A | BB18: N/A | BC18: N/A | BD18: N/A | BE18: N/A | BF18: N/A | BG18: N/A | BH18: N/A | BI18: N/A | BJ18: N/A | BK18: N/A | BL18: N/A | BM18: N/A | BN18: N/A | BO18: N/A | BP18: N/A | BQ18: N/A | BR18: N/A | BS18: N/A | BT18: N/A | BU18: N/A | BV18: N/A | BW18: N/A | BX18: N/A | BY18: N/A | BZ18: N/A | CA18: N/A | CB18: N/A | CC18: N/A | CD18: N/A | CE18: N/A | CF18: N/A | CG18: N/A | CH18: N/A | CI18: N/A | CJ18: N/A | CK18: N/A | CL18: N/A | CM18: N/A | CN18: N/A | CO18: N/A | CP18: N/A | CQ18: N/A | CR18: N/A | CS18: N/A | CT18: N/A | CU18: N/A | CV18: N/A | CW18: N/A | CX18: N/A | CY18: N/A | CZ18: N/A | DA18: N/A | DB18: N/A
A19: Romania-Promotion | B19: Change Job | C19: Start | D19: New Team | E19: =SUBSTITUTE(B19," ","") & "_" & SUBSTITUTE(IF(C19="N/A","",C19& "_")," ","") & SUBSTITUTE(SUBSTITUTE(D19," ",""),"/","") -> ChangeJob_Start_NewTeam | F19: =E19&2 -> ChangeJob_Start_NewTeam2 | G19: Only needed if changing store. Otherwise N/A | H19: N/A | I19: N/A | J19: N/A | K19: N/A | L19: N/A | M19: N/A | N19: N/A | O19: N/A | P19: N/A | Q19: N/A | R19: N/A | S19: N/A | T19: N/A | U19: N/A | V19: N/A | W19: N/A | X19: N/A | Y19: N/A | Z19: N/A | AA19: N/A | AB19: N/A | AC19: N/A | AD19: N/A | AE19: N/A | AF19: N/A | AG19: N/A | AH19: N/A | AI19: N/A | AJ19: N/A | AK19: N/A | AL19: N/A | AM19: N/A | AN19: N/A | AO19: N/A | AP19: N/A | AQ19: N/A | AR19: N/A | AS19: N/A | AT19: N/A | AU19: N/A | AV19: N/A | AW19: N/A | AX19: N/A | AY19: N/A | AZ19: N/A | BA19: N/A | BB19: N/A | BC19: N/A | BD19: N/A | BE19: N/A | BF19: N/A | BG19: N/A | BH19: N/A | BI19: N/A | BJ19: N/A | BK19: N/A | BL19: N/A | BM19: N/A | BN19: N/A | BO19: N/A | BP19: N/A | BQ19: N/A | BR19: N/A | BS19: N/A | BT19: N/A | BU19: N/A | BV19: N/A | BW19: N/A | BX19: N/A | BY19: N/A | BZ19: N/A | CA19: N/A | CB19: N/A | CC19: N/A | CD19: N/A | CE19: N/A | CF19: N/A | CG19: N/A | CH19: N/A | CI19: N/A | CJ19: N/A | CK19: N/A | CL19: N/A | CM19: N/A | CN19: N/A | CO19: N/A | CP19: N/A | CQ19: N/A | CR19: N/A | CS19: N/A | CT19: N/A | CU19: N/A | CV19: N/A | CW19: N/A | CX19: N/A | CY19: N/A | CZ19: N/A | DA19: N/A | DB19: N/A
A20: Romania-Promotion | B20: Change Job | C20: Start | D20: New Location | E20: =SUBSTITUTE(B20," ","") & "_" & SUBSTITUTE(IF(C20="N/A","",C20& "_")," ","") & SUBSTITUTE(SUBSTITUTE(D20," ",""),"/","") -> ChangeJob_Start_NewLocation | F20: =E20&2 -> ChangeJob_Start_NewLocation2 | G20: Only needed if changing store. Otherwise N/A | H20: N/A | I20: N/A | J20: N/A | K20: N/A | L20: N/A | M20: N/A | N20: N/A | O20: N/A | P20: N/A | Q20: N/A | R20: N/A | S20: N/A | T20: N/A | U20: N/A | V20: N/A | W20: N/A | X20: N/A | Y20: N/A | Z20: N/A | AA20: N/A | AB20: N/A | AC20: N/A | AD20: N/A | AE20: N/A | AF20: N/A | AG20: N/A | AH20: N/A | AI20: N/A | AJ20: N/A | AK20: N/A | AL20: N/A | AM20: N/A | AN20: N/A | AO20: N/A | AP20: N/A | AQ20: N/A | AR20: N/A | AS20: N/A | AT20: N/A | AU20: N/A | AV20: N/A | AW20: N/A | AX20: N/A | AY20: N/A | AZ20: N/A | BA20: N/A | BB20: N/A | BC20: N/A | BD20: N/A | BE20: N/A | BF20: N/A | BG20: N/A | BH20: N/A | BI20: N/A | BJ20: N/A | BK20: N/A | BL20: N/A | BM20: N/A | BN20: N/A | BO20: N/A | BP20: N/A | BQ20: N/A | BR20: N/A | BS20: N/A | BT20: N/A | BU20: N/A | BV20: N/A | BW20: N/A | BX20: N/A | BY20: N/A | BZ20: N/A | CA20: N/A | CB20: N/A | CC20: N/A | CD20: N/A | CE20: N/A | CF20: N/A | CG20: N/A | CH20: N/A | CI20: N/A | CJ20: N/A | CK20: N/A | CL20: N/A | CM20: N/A | CN20: N/A | CO20: N/A | CP20: N/A | CQ20: N/A | CR20: N/A | CS20: N/A | CT20: N/A | CU20: N/A | CV20: N/A | CW20: N/A | CX20: N/A | CY20: N/A | CZ20: N/A | DA20: N/A | DB20: N/A
A21: Romania-Promotion | B21: Change Job | C21: Start | D21: Next Pay Period | E21: =SUBSTITUTE(B21," ","") & "_" & SUBSTITUTE(IF(C21="N/A","",C21& "_")," ","") & SUBSTITUTE(SUBSTITUTE(D21," ",""),"/","") -> ChangeJob_Start_NextPayPeriod | F21: =E21&2 -> ChangeJob_Start_NextPayPeriod2 | H21: N/A | I21: N/A | J21: N/A | K21: N/A | L21: N/A | M21: N/A | N21: N/A | O21: N/A | P21: N/A | Q21: N/A | R21: N/A | S21: N/A | T21: N/A | U21: N/A | V21: N/A | W21: N/A | X21: N/A | Y21: N/A | Z21: N/A | AA21: N/A | AB21: N/A | AC21: N/A | AD21: N/A | AE21: N/A | AF21: N/A | AG21: N/A | AH21: N/A | AI21: N/A | AJ21: N/A | AK21: N/A | AL21: N/A | AM21: N/A | AN21: N/A | AO21: N/A | AP21: N/A | AQ21: N/A | AR21: N/A | AS21: N/A | AT21: N/A | AU21: N/A | AV21: N/A | AW21: N/A | AX21: N/A | AY21: N/A | AZ21: N/A | BA21: N/A | BB21: N/A | BC21: N/A | BD21: N/A | BE21: N/A | BF21: N/A | BG21: N/A | BH21: N/A | BI21: N/A | BJ21: N/A | BK21: N/A | BL21: N/A | BM21: N/A | BN21: N/A | BO21: N/A | BP21: N/A | BQ21: N/A | BR21: N/A | BS21: N/A | BT21: N/A | BU21: N/A | BV21: N/A | BW21: N/A | BX21: N/A | BY21: N/A | BZ21: N/A | CA21: N/A | CB21: N/A | CC21: N/A | CD21: N/A | CE21: N/A | CF21: N/A | CG21: N/A | CH21: N/A | CI21: N/A | CJ21: N/A | CK21: N/A | CL21: N/A | CM21: N/A | CN21: N/A | CO21: N/A | CP21: N/A | CQ21: N/A | CR21: N/A | CS21: N/A | CT21: N/A | CU21: N/A | CV21: N/A | CW21: N/A | CX21: N/A | CY21: N/A | CZ21: N/A | DA21: N/A | DB21: N/A
A22: Romania-Promotion | B22: Change Job | C22: Job Profile | D22: Job Profile | E22: =SUBSTITUTE(B22," ","") & "_" & SUBSTITUTE(IF(C22="N/A","",C22& "_")," ","") & SUBSTITUTE(SUBSTITUTE(D22," ",""),"/","") -> ChangeJob_JobProfile_JobProfile | F22: =E22&2 -> ChangeJob_JobProfile_JobProfile2 | H22: N/A | I22: N/A | J22: N/A | K22: N/A | L22: N/A | M22: N/A | N22: N/A | O22: N/A | P22: N/A | Q22: N/A | R22: N/A | S22: N/A | T22: N/A | U22: N/A | V22: N/A | W22: N/A | X22: N/A | Y22: N/A | Z22: N/A | AA22: N/A | AB22: N/A | AC22: N/A | AD22: N/A | AE22: N/A | AF22: N/A | AG22: N/A | AH22: N/A | AI22: N/A | AJ22: N/A | AK22: N/A | AL22: N/A | AM22: N/A | AN22: N/A | AO22: N/A | AP22: N/A | AQ22: N/A | AR22: N/A | AS22: N/A | AT22: N/A | AU22: N/A | AV22: N/A | AW22: N/A | AX22: N/A | AY22: N/A | AZ22: N/A | BA22: N/A | BB22: N/A | BC22: N/A | BD22: N/A | BE22: N/A | BF22: N/A | BG22: N/A | BH22: N/A | BI22: N/A | BJ22: N/A | BK22: N/A | BL22: N/A | BM22: N/A | BN22: N/A | BO22: N/A | BP22: N/A | BQ22: N/A | BR22: N/A | BS22: N/A | BT22: N/A | BU22: N/A | BV22: N/A | BW22: N/A | BX22: N/A | BY22: N/A | BZ22: N/A | CA22: N/A | CB22: N/A | CC22: N/A | CD22: N/A | CE22: N/A | CF22: N/A | CG22: N/A | CH22: N/A | CI22: N/A | CJ22: N/A | CK22: N/A | CL22: N/A | CM22: N/A | CN22: N/A | CO22: N/A | CP22: N/A | CQ22: N/A | CR22: N/A | CS22: N/A | CT22: N/A | CU22: N/A | CV22: N/A | CW22: N/A | CX22: N/A | CY22: N/A | CZ22: N/A | DA22: N/A | DB22: N/A
A23: Romania-Promotion | B23: Change Job | C23: Job Profile | D23: Job Title | E23: =SUBSTITUTE(B23," ","") & "_" & SUBSTITUTE(IF(C23="N/A","",C23& "_")," ","") & SUBSTITUTE(SUBSTITUTE(D23," ",""),"/","") -> ChangeJob_JobProfile_JobTitle | F23: =E23&2 -> ChangeJob_JobProfile_JobTitle2 | H23: N/A | I23: N/A | J23: N/A | K23: N/A | L23: N/A | M23: N/A | N23: N/A | O23: N/A | P23: N/A | Q23: N/A | R23: N/A | S23: N/A | T23: N/A | U23: N/A | V23: N/A | W23: N/A | X23: N/A | Y23: N/A | Z23: N/A | AA23: N/A | AB23: N/A | AC23: N/A | AD23: N/A | AE23: N/A | AF23: N/A | AG23: N/A | AH23: N/A | AI23: N/A | AJ23: N/A | AK23: N/A | AL23: N/A | AM23: N/A | AN23: N/A | AO23: N/A | AP23: N/A | AQ23: N/A | AR23: N/A | AS23: N/A | AT23: N/A | AU23: N/A | AV23: N/A | AW23: N/A | AX23: N/A | AY23: N/A | AZ23: N/A | BA23: N/A | BB23: N/A | BC23: N/A | BD23: N/A | BE23: N/A | BF23: N/A | BG23: N/A | BH23: N/A | BI23: N/A | BJ23: N/A | BK23: N/A | BL23: N/A | BM23: N/A | BN23: N/A | BO23: N/A | BP23: N/A | BQ23: N/A | BR23: N/A | BS23: N/A | BT23: N/A | BU23: N/A | BV23: N/A | BW23: N/A | BX23: N/A | BY23: N/A | BZ23: N/A | CA23: N/A | CB23: N/A | CC23: N/A | CD23: N/A | CE23: N/A | CF23: N/A | CG23: N/A | CH23: N/A | CI23: N/A | CJ23: N/A | CK23: N/A | CL23: N/A | CM23: N/A | CN23: N/A | CO23: N/A | CP23: N/A | CQ23: N/A | CR23: N/A | CS23: N/A | CT23: N/A | CU23: N/A | CV23: N/A | CW23: N/A | CX23: N/A | CY23: N/A | CZ23: N/A | DA23: N/A | DB23: N/A
A24: Romania-Promotion | B24: Change Job | C24: Location Details | D24: Location | E24: =SUBSTITUTE(B24," ","") & "_" & SUBSTITUTE(IF(C24="N/A","",C24& "_")," ","") & SUBSTITUTE(SUBSTITUTE(D24," ",""),"/","") -> ChangeJob_LocationDetails_Location | F24: =E24&2 -> ChangeJob_LocationDetails_Location2 | H24: 895 | I24: 895 | J24: 895 | K24: 895 | L24: 895 | M24: 895 | N24: 895 | O24: 895 | P24: 895 | Q24: 895 | R24: 895 | S24: 895 | T24: 895 | U24: 895 | V24: 895 | W24: 895 | X24: 895 | Y24: 895 | Z24: 895 | AA24: 895 | AB24: 895 | AC24: 895 | AD24: 895 | AE24: 895 | AF24: 895 | AG24: 895 | AH24: 895 | AI24: 895 | AJ24: 895 | AK24: 895 | AL24: 895 | AM24: 895 | AN24: 895 | AO24: 895 | AP24: 895 | AQ24: 895 | AR24: 895 | AS24: 895 | AT24: 895 | AU24: 895 | AV24: 895 | AW24: 895 | AX24: 895 | AY24: 895 | AZ24: 895 | BA24: 895 | BB24: 895 | BC24: 895 | BD24: 895 | BE24: 895 | BF24: 895 | BG24: 895 | BH24: 895 | BI24: 895 | BJ24: 895 | BK24: 895 | BL24: 895 | BM24: 895 | BN24: 895 | BO24: 895 | BP24: 895 | BQ24: 895 | BR24: 895 | BS24: 895 | BT24: 895 | BU24: 895 | BV24: 895 | BW24: 895 | BX24: 895 | BY24: 895 | BZ24: 895 | CA24: 895 | CB24: 895 | CC24: 895 | CD24: 895 | CE24: 895 | CF24: 895 | CG24: 895 | CH24: 895 | CI24: 895 | CJ24: 895 | CK24: 895 | CL24: 895 | CM24: 895 | CN24: 895 | CO24: 895 | CP24: 895 | CQ24: 895 | CR24: 895 | CS24: 895 | CT24: 895 | CU24: 895 | CV24: 895 | CW24: 895 | CX24: 895 | CY24: 895 | CZ24: 895 | DA24: 895 | DB24: 895
A25: Romania-Promotion | B25: Change Job | C25: Location Details | D25: Scheduled Weekly Hours | E25: =SUBSTITUTE(B25," ","") & "_" & SUBSTITUTE(IF(C25="N/A","",C25& "_")," ","") & SUBSTITUTE(SUBSTITUTE(D25," ",""),"/","") -> ChangeJob_LocationDetails_ScheduledWeeklyHours | F25: =E25&2 -> ChangeJob_LocationDetails_ScheduledWeeklyHours2 | G25: Set to 100 for full time for Spain & 40 For FT Portugal | H25: N/A | I25: N/A | J25: N/A | K25: N/A | L25: N/A | M25: N/A | N25: N/A | O25: N/A | P25: N/A | Q25: N/A | R25: N/A | S25: N/A | T25: N/A | U25: N/A | V25: N/A | W25: N/A | X25: N/A | Y25: N/A | Z25: N/A | AA25: N/A | AB25: N/A | AC25: N/A | AD25: N/A | AE25: N/A | AF25: N/A | AG25: N/A | AH25: N/A | AI25: N/A | AJ25: N/A | AK25: N/A | AL25: N/A | AM25: N/A | AN25: N/A | AO25: N/A | AP25: N/A | AQ25: N/A | AR25: N/A | AS25: N/A | AT25: N/A | AU25: N/A | AV25: N/A | AW25: N/A | AX25: N/A | AY25: N/A | AZ25: N/A | BA25: N/A | BB25: N/A | BC25: N/A | BD25: N/A | BE25: N/A | BF25: N/A | BG25: N/A | BH25: N/A | BI25: N/A | BJ25: N/A | BK25: N/A | BL25: N/A | BM25: N/A | BN25: N/A | BO25: N/A | BP25: N/A | BQ25: N/A | BR25: N/A | BS25: N/A | BT25: N/A | BU25: N/A | BV25: N/A | BW25: N/A | BX25: N/A | BY25: N/A | BZ25: N/A | CA25: N/A | CB25: N/A | CC25: N/A | CD25: N/A | CE25: N/A | CF25: N/A | CG25: N/A | CH25: N/A | CI25: N/A | CJ25: N/A | CK25: N/A | CL25: N/A | CM25: N/A | CN25: N/A | CO25: N/A | CP25: N/A | CQ25: N/A | CR25: N/A | CS25: N/A | CT25: N/A | CU25: N/A | CV25: N/A | CW25: N/A | CX25: N/A | CY25: N/A | CZ25: N/A | DA25: N/A | DB25: N/A
A26: Romania-Promotion | B26: Change Job | C26: Location Details | D26: Work Shift | E26: =SUBSTITUTE(B26," ","") & "_" & SUBSTITUTE(IF(C26="N/A","",C26& "_")," ","") & SUBSTITUTE(SUBSTITUTE(D26," ",""),"/","") -> ChangeJob_LocationDetails_WorkShift | F26: =E26&2 -> ChangeJob_LocationDetails_WorkShift2 | G26: Should be 5 days for full time | H26: N/A | I26: N/A | J26: N/A | K26: N/A | L26: N/A | M26: N/A | N26: N/A | O26: N/A | P26: N/A | Q26: N/A | R26: N/A | S26: N/A | T26: N/A | U26: N/A | V26: N/A | W26: N/A | X26: N/A | Y26: N/A | Z26: N/A | AA26: N/A | AB26: N/A | AC26: N/A | AD26: N/A | AE26: N/A | AF26: N/A | AG26: N/A | AH26: N/A | AI26: N/A | AJ26: N/A | AK26: N/A | AL26: N/A | AM26: N/A | AN26: N/A | AO26: N/A | AP26: N/A | AQ26: N/A | AR26: N/A | AS26: N/A | AT26: N/A | AU26: N/A | AV26: N/A | AW26: N/A | AX26: N/A | AY26: N/A | AZ26: N/A | BA26: N/A | BB26: N/A | BC26: N/A | BD26: N/A | BE26: N/A | BF26: N/A | BG26: N/A | BH26: N/A | BI26: N/A | BJ26: N/A | BK26: N/A | BL26: N/A | BM26: N/A | BN26: N/A | BO26: N/A | BP26: N/A | BQ26: N/A | BR26: N/A | BS26: N/A | BT26: N/A | BU26: N/A | BV26: N/A | BW26: N/A | BX26: N/A | BY26: N/A | BZ26: N/A | CA26: N/A | CB26: N/A | CC26: N/A | CD26: N/A | CE26: N/A | CF26: N/A | CG26: N/A | CH26: N/A | CI26: N/A | CJ26: N/A | CK26: N/A | CL26: N/A | CM26: N/A | CN26: N/A | CO26: N/A | CP26: N/A | CQ26: N/A | CR26: N/A | CS26: N/A | CT26: N/A | CU26: N/A | CV26: N/A | CW26: N/A | CX26: N/A | CY26: N/A | CZ26: N/A | DA26: N/A | DB26: N/A
A27: Romania-Promotion | B27: Change Job | C27: Job Classifications | D27: Additional Job Classifications | E27: =SUBSTITUTE(B27," ","") & "_" & SUBSTITUTE(IF(C27="N/A","",C27& "_")," ","") & SUBSTITUTE(SUBSTITUTE(D27," ",""),"/","") -> ChangeJob_JobClassifications_AdditionalJobClassifications | F27: =E27&2 -> ChangeJob_JobClassifications_AdditionalJobClassifications2 | H27: N/A | I27: N/A | J27: N/A | K27: N/A | L27: N/A | M27: N/A | N27: N/A | O27: N/A | P27: N/A | Q27: N/A | R27: N/A | S27: N/A | T27: N/A | U27: N/A | V27: N/A | W27: N/A | X27: N/A | Y27: N/A | Z27: N/A | AA27: N/A | AB27: N/A | AC27: N/A | AD27: N/A | AE27: N/A | AF27: N/A | AG27: N/A | AH27: N/A | AI27: N/A | AJ27: N/A | AK27: N/A | AL27: N/A | AM27: N/A | AN27: N/A | AO27: N/A | AP27: N/A | AQ27: N/A | AR27: N/A | AS27: N/A | AT27: N/A | AU27: N/A | AV27: N/A | AW27: N/A | AX27: N/A | AY27: N/A | AZ27: N/A | BA27: N/A | BB27: N/A | BC27: N/A | BD27: N/A | BE27: N/A | BF27: N/A | BG27: N/A | BH27: N/A | BI27: N/A | BJ27: N/A | BK27: N/A | BL27: N/A | BM27: N/A | BN27: N/A | BO27: N/A | BP27: N/A | BQ27: N/A | BR27: N/A | BS27: N/A | BT27: N/A | BU27: N/A | BV27: N/A | BW27: N/A | BX27: N/A | BY27: N/A | BZ27: N/A | CA27: N/A | CB27: N/A | CC27: N/A | CD27: N/A | CE27: N/A | CF27: N/A | CG27: N/A | CH27: N/A | CI27: N/A | CJ27: N/A | CK27: N/A | CL27: N/A | CM27: N/A | CN27: N/A | CO27: N/A | CP27: N/A | CQ27: N/A | CR27: N/A | CS27: N/A | CT27: N/A | CU27: N/A | CV27: N/A | CW27: N/A | CX27: N/A | CY27: N/A | CZ27: N/A | DA27: N/A | DB27: N/A
A28: Romania-Promotion, Portugal-Fixed_To_Permanent | B28: Change Job | C28: Job Classifications | D28: Employee Type | E28: =SUBSTITUTE(B28," ","") & "_" & SUBSTITUTE(IF(C28="N/A","",C28& "_")," ","") & SUBSTITUTE(SUBSTITUTE(D28," ",""),"/","") -> ChangeJob_JobClassifications_EmployeeType | F28: =E28&2 -> ChangeJob_JobClassifications_EmployeeType2 | G28: Choice of Permanent/Fixed | H28: N/A | I28: N/A | J28: N/A | K28: N/A | L28: N/A | M28: N/A | N28: N/A | O28: N/A | P28: N/A | Q28: N/A | R28: N/A | S28: N/A | T28: N/A | U28: N/A | V28: N/A | W28: N/A | X28: N/A | Y28: N/A | Z28: N/A | AA28: N/A | AB28: N/A | AC28: N/A | AD28: N/A | AE28: N/A | AF28: N/A | AG28: N/A | AH28: N/A | AI28: N/A | AJ28: N/A | AK28: N/A | AL28: N/A | AM28: N/A | AN28: N/A | AO28: N/A | AP28: N/A | AQ28: N/A | AR28: N/A | AS28: N/A | AT28: N/A | AU28: N/A | AV28: N/A | AW28: N/A | AX28: N/A | AY28: N/A | AZ28: N/A | BA28: N/A | BB28: N/A | BC28: N/A | BD28: N/A | BE28: N/A | BF28: N/A | BG28: N/A | BH28: N/A | BI28: N/A | BJ28: N/A | BK28: N/A | BL28: N/A | BM28: N/A | BN28: N/A | BO28: N/A | BP28: N/A | BQ28: N/A | BR28: N/A | BS28: N/A | BT28: N/A | BU28: N/A | BV28: N/A | BW28: N/A | BX28: N/A | BY28: N/A | BZ28: N/A | CA28: N/A | CB28: N/A | CC28: N/A | CD28: N/A | CE28: N/A | CF28: N/A | CG28: N/A | CH28: N/A | CI28: N/A | CJ28: N/A | CK28: N/A | CL28: N/A | CM28: N/A | CN28: N/A | CO28: N/A | CP28: N/A | CQ28: N/A | CR28: N/A | CS28: N/A | CT28: N/A | CU28: N/A | CV28: N/A | CW28: N/A | CX28: N/A | CY28: N/A | CZ28: N/A | DA28: N/A | DB28: N/A
A29: Romania-Promotion, Portugal-PT_To_FT | B29: Change Job | C29: Job Classifications | D29: Time Type | E29: =SUBSTITUTE(B29," ","") & "_" & SUBSTITUTE(IF(C29="N/A","",C29& "_")," ","") & SUBSTITUTE(SUBSTITUTE(D29," ",""),"/","") -> ChangeJob_JobClassifications_TimeType | F29: =E29&2 -> ChangeJob_JobClassifications_TimeType2 | G29: Choice of Full Time/Part Time | H29: N/A | I29: N/A | J29: N/A | K29: N/A | L29: N/A | M29: N/A | N29: N/A | O29: N/A | P29: N/A | Q29: N/A | R29: N/A | S29: N/A | T29: N/A | U29: N/A | V29: N/A | W29: N/A | X29: N/A | Y29: N/A | Z29: N/A | AA29: N/A | AB29: N/A | AC29: N/A | AD29: N/A | AE29: N/A | AF29: N/A | AG29: N/A | AH29: N/A | AI29: N/A | AJ29: N/A | AK29: N/A | AL29: N/A | AM29: N/A | AN29: N/A | AO29: N/A | AP29: N/A | AQ29: N/A | AR29: N/A | AS29: N/A | AT29: N/A | AU29: N/A | AV29: N/A | AW29: N/A | AX29: N/A | AY29: N/A | AZ29: N/A | BA29: N/A | BB29: N/A | BC29: N/A | BD29: N/A | BE29: N/A | BF29: N/A | BG29: N/A | BH29: N/A | BI29: N/A | BJ29: N/A | BK29: N/A | BL29: N/A | BM29: N/A | BN29: N/A | BO29: N/A | BP29: N/A | BQ29: N/A | BR29: N/A | BS29: N/A | BT29: N/A | BU29: N/A | BV29: N/A | BW29: N/A | BX29: N/A | BY29: N/A | BZ29: N/A | CA29: N/A | CB29: N/A | CC29: N/A | CD29: N/A | CE29: N/A | CF29: N/A | CG29: N/A | CH29: N/A | CI29: N/A | CJ29: N/A | CK29: N/A | CL29: N/A | CM29: N/A | CN29: N/A | CO29: N/A | CP29: N/A | CQ29: N/A | CR29: N/A | CS29: N/A | CT29: N/A | CU29: N/A | CV29: N/A | CW29: N/A | CX29: N/A | CY29: N/A | CZ29: N/A | DA29: N/A | DB29: N/A
A30: Romania-Promotion | B30: Change Job | C30: Job Classifications | D30: Pay Rate Type | E30: =SUBSTITUTE(B30," ","") & "_" & SUBSTITUTE(IF(C30="N/A","",C30& "_")," ","") & SUBSTITUTE(SUBSTITUTE(D30," ",""),"/","") -> ChangeJob_JobClassifications_PayRateType | F30: =E30&2 -> ChangeJob_JobClassifications_PayRateType2 | G30: Choice of Salary/Hourly/ | H30: N/A | I30: N/A | J30: N/A | K30: N/A | L30: N/A | M30: N/A | N30: N/A | O30: N/A | P30: N/A | Q30: N/A | R30: N/A | S30: N/A | T30: N/A | U30: N/A | V30: N/A | W30: N/A | X30: N/A | Y30: N/A | Z30: N/A | AA30: N/A | AB30: N/A | AC30: N/A | AD30: N/A | AE30: N/A | AF30: N/A | AG30: N/A | AH30: N/A | AI30: N/A | AJ30: N/A | AK30: N/A | AL30: N/A | AM30: N/A | AN30: N/A | AO30: N/A | AP30: N/A | AQ30: N/A | AR30: N/A | AS30: N/A | AT30: N/A | AU30: N/A | AV30: N/A | AW30: N/A | AX30: N/A | AY30: N/A | AZ30: N/A | BA30: N/A | BB30: N/A | BC30: N/A | BD30: N/A | BE30: N/A | BF30: N/A | BG30: N/A | BH30: N/A | BI30: N/A | BJ30: N/A | BK30: N/A | BL30: N/A | BM30: N/A | BN30: N/A | BO30: N/A | BP30: N/A | BQ30: N/A | BR30: N/A | BS30: N/A | BT30: N/A | BU30: N/A | BV30: N/A | BW30: N/A | BX30: N/A | BY30: N/A | BZ30: N/A | CA30: N/A | CB30: N/A | CC30: N/A | CD30: N/A | CE30: N/A | CF30: N/A | CG30: N/A | CH30: N/A | CI30: N/A | CJ30: N/A | CK30: N/A | CL30: N/A | CM30: N/A | CN30: N/A | CO30: N/A | CP30: N/A | CQ30: N/A | CR30: N/A | CS30: N/A | CT30: N/A | CU30: N/A | CV30: N/A | CW30: N/A | CX30: N/A | CY30: N/A | CZ30: N/A | DA30: N/A | DB30: N/A
A31: Romania-Promotion | B31: Change Job | C31: Job Classifications | D31: Default Weekly Hours | E31: =SUBSTITUTE(B31," ","") & "_" & SUBSTITUTE(IF(C31="N/A","",C31& "_")," ","") & SUBSTITUTE(SUBSTITUTE(D31," ",""),"/","") -> ChangeJob_JobClassifications_DefaultWeeklyHours | F31: =E31&2 -> ChangeJob_JobClassifications_DefaultWeeklyHours2 | H31: N/A | I31: N/A | J31: N/A | K31: N/A | L31: N/A | M31: N/A | N31: N/A | O31: N/A | P31: N/A | Q31: N/A | R31: N/A | S31: N/A | T31: N/A | U31: N/A | V31: N/A | W31: N/A | X31: N/A | Y31: N/A | Z31: N/A | AA31: N/A | AB31: N/A | AC31: N/A | AD31: N/A | AE31: N/A | AF31: N/A | AG31: N/A | AH31: N/A | AI31: N/A | AJ31: N/A | AK31: N/A | AL31: N/A | AM31: N/A | AN31: N/A | AO31: N/A | AP31: N/A | AQ31: N/A | AR31: N/A | AS31: N/A | AT31: N/A | AU31: N/A | AV31: N/A | AW31: N/A | AX31: N/A | AY31: N/A | AZ31: N/A | BA31: N/A | BB31: N/A | BC31: N/A | BD31: N/A | BE31: N/A | BF31: N/A | BG31: N/A | BH31: N/A | BI31: N/A | BJ31: N/A | BK31: N/A | BL31: N/A | BM31: N/A | BN31: N/A | BO31: N/A | BP31: N/A | BQ31: N/A | BR31: N/A | BS31: N/A | BT31: N/A | BU31: N/A | BV31: N/A | BW31: N/A | BX31: N/A | BY31: N/A | BZ31: N/A | CA31: N/A | CB31: N/A | CC31: N/A | CD31: N/A | CE31: N/A | CF31: N/A | CG31: N/A | CH31: N/A | CI31: N/A | CJ31: N/A | CK31: N/A | CL31: N/A | CM31: N/A | CN31: N/A | CO31: N/A | CP31: N/A | CQ31: N/A | CR31: N/A | CS31: N/A | CT31: N/A | CU31: N/A | CV31: N/A | CW31: N/A | CX31: N/A | CY31: N/A | CZ31: N/A | DA31: N/A | DB31: N/A
A32: Romania-Promotion | B32: Change Job | C32: Job Classifications | D32: End Employment Date | E32: =SUBSTITUTE(B32," ","") & "_" & SUBSTITUTE(IF(C32="N/A","",C32& "_")," ","") & SUBSTITUTE(SUBSTITUTE(D32," ",""),"/","") -> ChangeJob_JobClassifications_EndEmploymentDate | F32: =E32&2 -> ChangeJob_JobClassifications_EndEmploymentDate2 | H32: 46022 | I32: 46022 | J32: 46022 | K32: 46022 | L32: 46022 | M32: 46022 | N32: 46022 | O32: 46022 | P32: 46022 | Q32: 46022 | R32: 46022 | S32: 46022 | T32: 46022 | U32: 46022 | V32: 46022 | W32: 46022 | X32: 46022 | Y32: 46022 | Z32: 46022 | AA32: 46022 | AB32: 46022 | AC32: 46022 | AD32: 46022 | AE32: 46022 | AF32: 46022 | AG32: 46022 | AH32: 46022 | AI32: 46022 | AJ32: 46022 | AK32: 46022 | AL32: 46022 | AM32: 46022 | AN32: 46022 | AO32: 46022 | AP32: 46022 | AQ32: 46022 | AR32: 46022 | AS32: 46022 | AT32: 46022 | AU32: 46022 | AV32: 46022 | AW32: 46022 | AX32: 46022 | AY32: 46022 | AZ32: 46022 | BA32: 46022 | BB32: 46022 | BC32: 46022 | BD32: 46022 | BE32: 46022 | BF32: 46022 | BG32: 46022 | BH32: 46022 | BI32: 46022 | BJ32: 46022 | BK32: 46022 | BL32: 46022 | BM32: 46022 | BN32: 46022 | BO32: 46022 | BP32: 46022 | BQ32: 46022 | BR32: 46022 | BS32: 46022 | BT32: 46022 | BU32: 46022 | BV32: 46022 | BW32: 46022 | BX32: 46022 | BY32: 46022 | BZ32: 46022 | CA32: 46022 | CB32: 46022 | CC32: 46022 | CD32: 46022 | CE32: 46022 | CF32: 46022 | CG32: 46022 | CH32: 46022 | CI32: 46022 | CJ32: 46022 | CK32: 46022 | CL32: 46022 | CM32: 46022 | CN32: 46022 | CO32: 46022 | CP32: 46022 | CQ32: 46022 | CR32: 46022 | CS32: 46022 | CT32: 46022 | CU32: 46022 | CV32: 46022 | CW32: 46022 | CX32: 46022 | CY32: 46022 | CZ32: 46022 | DA32: 46022 | DB32: 46022
A33: Romania-Promotion | B33: Change Job | C33: Job Classifications | D33: Assignment Type | E33: =SUBSTITUTE(B33," ","") & "_" & SUBSTITUTE(IF(C33="N/A","",C33& "_")," ","") & SUBSTITUTE(SUBSTITUTE(D33," ",""),"/","") -> ChangeJob_JobClassifications_AssignmentType | F33: =E33&2 -> ChangeJob_JobClassifications_AssignmentType2 | H33: N/A | I33: N/A | J33: N/A | K33: N/A | L33: N/A | M33: N/A | N33: N/A | O33: N/A | P33: N/A | Q33: N/A | R33: N/A | S33: N/A | T33: N/A | U33: N/A | V33: N/A | W33: N/A | X33: N/A | Y33: N/A | Z33: N/A | AA33: N/A | AB33: N/A | AC33: N/A | AD33: N/A | AE33: N/A | AF33: N/A | AG33: N/A | AH33: N/A | AI33: N/A | AJ33: N/A | AK33: N/A | AL33: N/A | AM33: N/A | AN33: N/A | AO33: N/A | AP33: N/A | AQ33: N/A | AR33: N/A | AS33: N/A | AT33: N/A | AU33: N/A | AV33: N/A | AW33: N/A | AX33: N/A | AY33: N/A | AZ33: N/A | BA33: N/A | BB33: N/A | BC33: N/A | BD33: N/A | BE33: N/A | BF33: N/A | BG33: N/A | BH33: N/A | BI33: N/A | BJ33: N/A | BK33: N/A | BL33: N/A | BM33: N/A | BN33: N/A | BO33: N/A | BP33: N/A | BQ33: N/A | BR33: N/A | BS33: N/A | BT33: N/A | BU33: N/A | BV33: N/A | BW33: N/A | BX33: N/A | BY33: N/A | BZ33: N/A | CA33: N/A | CB33: N/A | CC33: N/A | CD33: N/A | CE33: N/A | CF33: N/A | CG33: N/A | CH33: N/A | CI33: N/A | CJ33: N/A | CK33: N/A | CL33: N/A | CM33: N/A | CN33: N/A | CO33: N/A | CP33: N/A | CQ33: N/A | CR33: N/A | CS33: N/A | CT33: N/A | CU33: N/A | CV33: N/A | CW33: N/A | CX33: N/A | CY33: N/A | CZ33: N/A | DA33: N/A | DB33: N/A
