Workbook
Name AddProbationPeriod_EndDate: Test_Data!$F$40
Name AddProbationPeriod_ProbationEndDate: Test_Data!#REF!
Name AddProbationPeriod_ProbationEndDate2: Automation_Lookups!$BB$2:$BB$4
Name AddProbationPeriod_StartDate: Test_Data!$F$39
Name AssignPayGroup_ProposedPayGroup: Test_Data!#REF!
Name AssignPayGroup_ProposedPayGroup: Automation_Lookups!$AH$2:$AH$20
Name AssignPayGroup_ProposedPayGroup2: Automation_Lookups!$AH$2
Name AssignPayGroup_ProposedPayGroupFinal: Test_Data!#REF!
Name Automation_Ref: Test_Data!$H$12:$K$12
Name AutomationComments: Test_Data!$F$9
Name ChangeJob_AssignCollectiveAgreement_CollectiveAgreement: Test_Data!$F$45
Name ChangeJob_AssignCollectiveAgreement_Level: Test_Data!$F$47
Name ChangeJob_AssignCollectiveAgreement_ProfessionalCategory: Test_Data!$F$46
Name ChangeJob_Company_CostCentre: Test_Data!$F$37
Name ChangeJob_Company_Department: Test_Data!$F$38
Name ChangeJob_ContractType: Test_Data!$F$33
Name ChangeJob_JobClassifications_AdditionalJobClassifications: Test_Data!$F$27
Name ChangeJob_JobClassifications_AssignmentType: Test_Data!$F$35
Name ChangeJob_JobClassifications_DefaultWeeklyHours: Test_Data!$F$31
Name ChangeJob_JobClassifications_EmployeeType: Test_Data!$F$28
Name ChangeJob_JobClassifications_EndEmploymentDate: Test_Data!$F$32
Name ChangeJob_JobClassifications_FirstDayofWork: Test_Data!$F$36
Name ChangeJob_JobClassifications_PayRateType: Test_Data!$F$30
Name ChangeJob_JobClassifications_TimeType: Test_Data!$F$29
Name ChangeJob_JobProfile_JobProfile: Test_Data!$F$22
Name ChangeJob_JobProfile_JobTitle: Test_Data!$F$23
Name ChangeJob_LocationDetails_Location: Test_Data!$F$24
Name ChangeJob_LocationDetails_ScheduledWeeklyHours: Test_Data!$F$25
Name ChangeJob_LocationDetails_WorkShift: Test_Data!$F$26
Name ChangeJob_LocationDetails_WorkShift2: Automation_Lookups!$I$2:$I$6
Name ChangeJob_Start_EffectiveDate: Test_Data!$F$16
Name ChangeJob_Start_NewLocation: Test_Data!$F$20
Name ChangeJob_Start_NewLocation2: Automation_Lookups!$G$2:$G$3
Name ChangeJob_Start_NewManager: Test_Data!$F$18
Name ChangeJob_Start_NewManager2: Automation_Lookups!$E$2:$E$3
Name ChangeJob_Start_NewTeam: Test_Data!$F$19
Name ChangeJob_Start_NewTeam2: Automation_Lookups!$F$2:$F$3
Name ChangeJob_Start_NextPayPeriod: Test_Data!$F$21
Name ChangeJob_Start_NextPayPeriod2: Automation_Lookups!$H$2:$H$3
Name ChangeJob_Start_NextPayPeriod22: Automation_Lookups!$I$2:$I$6
Name ChangeJob_Start_Reason: Test_Data!$F$17
Name ChangeJob_Start_Reason2: Automation_Lookups!$D$2:$D$3
Name ChangeMyEmergencyContacts_City: Test_Data!#REF!
Name ChangeMyEmergencyContacts_EmailAddress: Test_Data!#REF!
Name ChangeMyEmergencyContacts_FamilyName: Test_Data!#REF!
Name ChangeMyEmergencyContacts_GivenName: Test_Data!#REF!
Name ChangeMyEmergencyContacts_PhoneDevice: Test_Data!#REF!
Name ChangeMyEmergencyContacts_PhoneDevice2: Automation_Lookups!$AX$2:$AX$3
Name ChangeMyEmergencyContacts_PhoneNumber: Test_Data!#REF!
Name ChangeMyEmergencyContacts_PostalCode: Test_Data!#REF!
Name ChangeMyEmergencyContacts_Relationship: Test_Data!#REF!
Name ChangeMyEmergencyContacts_Relationship2: Automation_Lookups!$AW$2:$AW$5
Name ChangeMyEmergencyContacts_StreetName: Test_Data!#REF!
Name ChangeMyGovernmentIDs_NationalIDs_AddEditID: Test_Data!#REF!
Name ChangeMyGovernmentIDs_NationalIDs_AddEditID1: Test_Data!#REF!
Name ChangeMyGovernmentIDs_NationalIDs_AddEditID2: Test_Data!#REF!
Name ChangeMyGovernmentIDs_NationalIDs_Country1: Test_Data!#REF!
Name ChangeMyGovernmentIDs_NationalIDs_Country2: Test_Data!#REF!
Name ChangeMyGovernmentIDs_NationalIDs_NationalIDType1: Test_Data!#REF!
Name ChangeMyGovernmentIDs_NationalIDs_NationalIDType12: Automation_Lookups!$BH$2

Sheet Information
A1: Version | F1: Info
A6: Version | B6: 0.3 | F6: Info
F7: Dates | G7: For Czech all dates to be entered in format of DD/MM/YYYY
A8: History | F8: Unhighlighted fields | G8: Only data in unhighlighted fields can be changed.
A9: Date | B9: Version | C9: Details | F9: Red highlighted fields | G9: Indicates fields where unique data is required otherwise automation will throw errors
A10: 44061 | B10: 0.3 | C10: Initial Release | F10: Grey highlighted fields | G10: Indicates fields that cannot be changed
F11: Last Run Status / Last Run Error Message | G11: When automation has run for a particular test, we need to check the status is set to Passed and no error messages are present for each test before the automation run for that particular test is considered valid

Sheet Test_Data
B1: Version_Number | D1: Test_ID | E1: =SUBSTITUTE(D1," ","") -> Test_ID | F1: =E1&2 -> Test_ID2 | G1: Notes | H1: Test_1 | I1: Test_2 | J1: Test_3 | K1: Test_4 | L1: Test_5 | M1: Test_6 | N1: Test_7 | O1: Test_8 | P1: Test_9 | Q1: Test_10 | R1: Test_11 | S1: Test_12 | T1: Test_13 | U1: Test_14
B2: =Information!B6 -> 0.3 | D2: Reporting_ID | H2: 1 | I2: 2 | J2: 3 | K2: 4 | L2: 5 | M2: 6 | N2: 7 | O2: 8 | P2: 9 | Q2: 10 | R2: 11 | S2: 12 | T2: 13 | U2: 14
D3: Process | E3: =SUBSTITUTE(D3," ","") -> Process | F3: =E3&2 -> Process2 | G3: If a manager hire and new role is required then select "New Role and New Hire" otherwise select "New Hire | H3: FullTime_To_PartTime | I3: FullTime_To_PartTime | J3: PartTime_To_FullTime | K3: PartTime_To_FullTime | L3: Permanent | M3: Permanent | N3: Permanent | O3: Permanent | P3: Promotion_To_Manager | Q3: Demotion | R3: Permanent | S3: Permanent | T3: Permanent | U3: Permanent
D4: Execution Flag | E4: =SUBSTITUTE(D4," ","") -> ExecutionFlag | F4: =E4&2 -> ExecutionFlag2 | G4: If set to No will not execute in next automation run | H4: Yes | I4: Yes | J4: Yes | K4: Yes | L4: Yes | M4: Yes | N4: Yes | O4: Yes | P4: Yes | Q4: Yes | R4: Yes | S4: Yes | T4: Yes | U4: Yes
D5: Country | E5: =SUBSTITUTE(D5," ","") -> Country | F5: =E5&2 -> Country2 | H5: Hungary | I5: Hungary | J5: Hungary | K5: Hungary | L5: Hungary | M5: Hungary | N5: Hungary | O5: Hungary | P5: Hungary | Q5: Hungary | R5: Hungary
D6: Last Run Time and Status | E6: =SUBSTITUTE(D6," ","") -> LastRunTimeandStatus | F6: =E6&2 -> LastRunTimeandStatus2 | G6: Once test is executed the Execution Timestamp and Pass/Fail status will be recorded here
A7: Portugal-Fixed_To_Permanent | D7: Last Run Error Message | E7: =SUBSTITUTE(D7," ","") -> LastRunErrorMessage | F7: =E7&2 -> LastRunErrorMessage2 | G7: If Automation throws errors, the details will be placed here
D8: Defect Description | E8: =SUBSTITUTE(D8," ","") -> DefectDescription | F8: =E8&2 -> DefectDescription2 | G8: After error investigation by the automation team, the defect description will be completed here
D9: Automation Comments | E9: =SUBSTITUTE(D9," ","") -> AutomationComments | F9: =E9&2 -> AutomationComments2 | G9: Automation team free text field
D10: QA Comments | E10: =SUBSTITUTE(D10," ","") -> QAComments | F10: =E10&2 -> QAComments2 | G10: QA team free text field | H10: FullTime_To_PartTime | I10: FullTime_To_PartTime | J10: PartTime_To_FullTime | K10: PartTime_To_FullTime | L10: Fix term to permenunt | M10: Permanent to Fixed term | N10: Irregular to Regular | O10: Regular to Irregular | P10: Dept Manager to Store Manager | Q10: Team Managet to Retail Assistant | R10: Extend Fixed term contract | S10: Retail Assisstant in to New dept | T10: Regular Employee to a Irregular (Effective the next pay period). | U10: Fixed Term Employee to a Permanent (Effective the next pay period)
B12: Screen | C12: Subscreen | D12: Field | E12: Automation Ref | F12: Lookups Ref | H12: Test_1 | I12: Test_2 | J12: Test_3 | K12: Test_4 | L12: Test_5 | M12: Test_6 | N12: Test_7 | O12: Test_8 | P12: Test_9 | Q12: Test_10 | R12: Test_13 | S12: Test_14 | T12: Test_27 | U12: Test_28
A13: Romania-Promotion, Portugal-PT_To_FT, Portugal-Fixed_To_Permanent | B13: Login | C13: N/A | D13: Username | E13: =SUBSTITUTE(B13," ","") & "_" & SUBSTITUTE(IF(C13="N/A","",C13& "_")," ","") & SUBSTITUTE(SUBSTITUTE(D13," ",""),"/","") -> Login_Username | F13: =E13&2 -> Login_Username2 | H13: 90001655 | I13: 90001655 | J13: 90001655 | K13: 90001655 | L13: 90001655 | M13: 90001655 | N13: 90001655 | O13: 90001655 | P13: 90001655 | Q13: 90001655 | R13: 90001655 | S13: 90001655 | T13: 90001655 | U13: 90001655
A14: Romania-Promotion, Portugal-PT_To_FT, Portugal-Fixed_To_Permanent | B14: Login | C14: N/A | D14: Password | E14: =SUBSTITUTE(B14," ","") & "_" & SUBSTITUTE(IF(C14="N/A","",C14& "_")," ","") & SUBSTITUTE(SUBSTITUTE(D14," ",""),"/","") -> Login_Password | F14: =E14&2 -> Login_Password2 | H14: 682e0aa7f09c8f62da00e2760c7d42eab76e6a47dd9e23c820d4607d | I14: 682e0aa7f09c8f62da00e2760c7d42eab76e6a47dd9e23c820d4607d | J14: 682e0aa7f09c8f62da00e2760c7d42eab76e6a47dd9e23c820d4607d | K14: 682e0aa7f09c8f62da00e2760c7d42eab76e6a47dd9e23c820d4607d | L14: 682e0aa7f09c8f62da00e2760c7d42eab76e6a47dd9e23c820d4607d | M14: 682e0aa7f09c8f62da00e2760c7d42eab76e6a47dd9e23c820d4607d | N14: 682e0aa7f09c8f62da00e2760c7d42eab76e6a47dd9e23c820d4607d | O14: 682e0aa7f09c8f62da00e2760c7d42eab76e6a47dd9e23c820d4607d | P14: 682e0aa7f09c8f62da00e2760c7d42eab76e6a47dd9e23c820d4607d | Q14: 682e0aa7f09c8f62da00e2760c7d42eab76e6a47dd9e23c820d4607d | R14: 682e0aa7f09c8f62da00e2760c7d42eab76e6a47dd9e23c820d4607d | S14: 682e0aa7f09c8f62da00e2760c7d42eab76e6a47dd9e23c820d4607d | T14: 682e0aa7f09c8f62da00e2760c7d42eab76e6a47dd9e23c820d4607d | U14: 682e0aa7f09c8f62da00e2760c7d42eab76e6a47dd9e23c820d4607d
A15: Romania-Promotion, Portugal-PT_To_FT, Portugal-Fixed_To_Permanent | B15: Proxy | C15: N/A | D15: Employee ID | E15: =SUBSTITUTE(B15," ","") & "_" & SUBSTITUTE(IF(C15="N/A","",C15& "_")," ","") & SUBSTITUTE(SUBSTITUTE(D15," ",""),"/","") -> Proxy_EmployeeID | F15: =E15&2 -> Proxy_EmployeeID2 | H15: 10699195 | I15: 10699177 | J15: 10699178 | K15: 10699165 | L15: 10699179 | M15: 10699126 | N15: 10699127 | O15: 10699162 | P15: 10699119 | Q15: 10699118 | R15: 10699128 | S15: 10699197 | T15: 10699139 | U15: 10699185
A16: Romania-Promotion, Portugal-PT_To_FT, Portugal-Fixed_To_Permanent | B16: Change Job | C16: Start | D16: Effective Date | E16: =SUBSTITUTE(B16," ","") & "_" & SUBSTITUTE(IF(C16="N/A","",C16& "_")," ","") & SUBSTITUTE(SUBSTITUTE(D16," ",""),"/","") -> ChangeJob_Start_EffectiveDate | F16: =E16&2 -> ChangeJob_Start_EffectiveDate2 | H16: 45778 | I16: 45778 | J16: 45778 | K16: 45778 | L16: 45778 | M16: 45778 | N16: 45778 | O16: 45778 | P16: 45778 | Q16: 45778 | R16: 45778 | S16: 45778 | T16: 45839 | U16: 45839
A17: Romania-Promotion, Portugal-PT_To_FT, Portugal-Fixed_To_Permanent | B17: Change Job | C17: Start | D17: Reason | E17: =SUBSTITUTE(B17," ","") & "_" & SUBSTITUTE(IF(C17="N/A","",C17& "_")," ","") & SUBSTITUTE(SUBSTITUTE(D17," ",""),"/","") -> ChangeJob_Start_Reason | F17: =E17&2 -> ChangeJob_Start_Reason2 | G17: Choice of Contractual Change/Promotion | H17: Change of Hours, Employee Type, Time Type, End Employment Date | I17: Change of Hours, Employee Type, Time Type, End Employment Date | J17: Change of Hours, Employee Type, Time Type, End Employment Date | K17: Change of Hours, Employee Type, Time Type, End Employment Date | L17: Change of Hours, Employee Type, Time Type, End Employment Date | M17: Change of Hours, Employee Type, Time Type, End Employment Date | N17: Change of Hours, Employee Type, Time Type, End Employment Date | O17: Change of Hours, Employee Type, Time Type, End Employment Date | P17: Promotion | Q17: Step Back | R17: Change of Hours, Employee Type, Time Type, End Employment Date | S17: Change of Hours, Employee Type, Time Type, End Employment Date | T17: Change of Hours, Employee Type, Time Type, End Employment Date | U17: Change of Hours, Employee Type, Time Type, End Employment Date
A18: Romania-Promotion | B18: Change Job | C18: Start | D18: New Manager | E18: =SUBSTITUTE(B18," ","") & "_" & SUBSTITUTE(IF(C18="N/A","",C18& "_")," ","") & SUBSTITUTE(SUBSTITUTE(D18," ",""),"/","") -> ChangeJob_Start_NewManager | F18: =E18&2 -> ChangeJob_Start_NewManager2 | G18: Only needed if promoted to manager. Otherwise N/A | H18: N/A | I18: N/A | J18: N/A | K18: N/A | L18: N/A | M18: N/A | N18: N/A | O18: N/A | P18: N/A | Q18: N/A | R18: N/A | S18: N/A | T18: N/A | U18: N/A
A19: Romania-Promotion | B19: Change Job | C19: Start | D19: New Team | E19: =SUBSTITUTE(B19," ","") & "_" & SUBSTITUTE(IF(C19="N/A","",C19& "_")," ","") & SUBSTITUTE(SUBSTITUTE(D19," ",""),"/","") -> ChangeJob_Start_NewTeam | F19: =E19&2 -> ChangeJob_Start_NewTeam2 | G19: Only needed if changing store. Otherwise N/A | H19: N/A | I19: N/A | J19: N/A | K19: N/A | L19: N/A | M19: N/A | N19: N/A | O19: N/A | P19: 970 Store Management (Hungary StoreMgr (10698630)) | Q19: 970 Recruitment (Hungary PCManager (10698631)) | R19: N/A | S19: N/A | T19: N/A | U19: N/A
A20: Romania-Promotion | B20: Change Job | C20: Start | D20: New Location | E20: =SUBSTITUTE(B20," ","") & "_" & SUBSTITUTE(IF(C20="N/A","",C20& "_")," ","") & SUBSTITUTE(SUBSTITUTE(D20," ",""),"/","") -> ChangeJob_Start_NewLocation | F20: =E20&2 -> ChangeJob_Start_NewLocation2 | G20: Only needed if changing store. Otherwise N/A | H20: N/A | I20: N/A | J20: N/A | K20: N/A | L20: N/A | M20: N/A | N20: N/A | O20: N/A | P20: 970 | Q20: 970 | R20: N/A | S20: N/A | T20: N/A | U20: N/A
A21: Romania-Promotion | B21: Change Job | C21: Start | D21: Next Pay Period | E21: =SUBSTITUTE(B21," ","") & "_" & SUBSTITUTE(IF(C21="N/A","",C21& "_")," ","") & SUBSTITUTE(SUBSTITUTE(D21," ",""),"/","") -> ChangeJob_Start_NextPayPeriod | F21: =E21&2 -> ChangeJob_Start_NextPayPeriod2 | H21: N/A | I21: N/A | J21: N/A | K21: N/A | L21: N/A | M21: N/A | N21: N/A | O21: N/A | P21: N/A | Q21: N/A | R21: N/A | S21: N/A | T21: N/A | U21: N/A
A22: Romania-Promotion | B22: Change Job | C22: Job Profile | D22: Job Profile | E22: =SUBSTITUTE(B22," ","") & "_" & SUBSTITUTE(IF(C22="N/A","",C22& "_")," ","") & SUBSTITUTE(SUBSTITUTE(D22," ",""),"/","") -> ChangeJob_JobProfile_JobProfile | F22: =E22&2 -> ChangeJob_JobProfile_JobProfile2 | H22: N/A | I22: N/A | J22: N/A | K22: N/A | L22: N/A | M22: N/A | N22: N/A | O22: N/A | P22: Store Manager_NEW | Q22: Retail Assistant_NEW | R22: N/A | S22: N/A | T22: N/A | U22: N/A
A23: Romania-Promotion | B23: Change Job | C23: Job Profile | D23: Job Title | E23: =SUBSTITUTE(B23," ","") & "_" & SUBSTITUTE(IF(C23="N/A","",C23& "_")," ","") & SUBSTITUTE(SUBSTITUTE(D23," ",""),"/","") -> ChangeJob_JobProfile_JobTitle | F23: =E23&2 -> ChangeJob_JobProfile_JobTitle2 | H23: N/A | I23: N/A | J23: N/A | K23: N/A | L23: N/A | M23: N/A | N23: N/A | O23: N/A | P23: Store Manager_NEW | Q23: Retail Assistant_NEW | R23: N/A | S23: N/A | T23: N/A | U23: N/A
A24: Romania-Promotion | B24: Change Job | C24: Location Details | D24: Location | E24: =SUBSTITUTE(B24," ","") & "_" & SUBSTITUTE(IF(C24="N/A","",C24& "_")," ","") & SUBSTITUTE(SUBSTITUTE(D24," ",""),"/","") -> ChangeJob_LocationDetails_Location | F24: =E24&2 -> ChangeJob_LocationDetails_Location2 | H24: N/A | I24: N/A | J24: N/A | K24: N/A | L24: N/A | M24: N/A | N24: N/A | O24: N/A | P24: 970 | Q24: 970 | R24: N/A | S24: N/A | T24: N/A | U24: N/A
A25: Romania-Promotion | B25: Change Job | C25: Location Details | D25: Scheduled Weekly Hours | E25: =SUBSTITUTE(B25," ","") & "_" & SUBSTITUTE(IF(C25="N/A","",C25& "_")," ","") & SUBSTITUTE(SUBSTITUTE(D25," ",""),"/","") -> ChangeJob_LocationDetails_ScheduledWeeklyHours | F25: =E25&2 -> ChangeJob_LocationDetails_ScheduledWeeklyHours2 | G25: Set to 100 for full time for Spain & 40 For FT Portugal | H25: 15 | I25: 30 | J25: 40 | K25: 40 | L25: N/A | M25: N/A | N25: N/A | O25: N/A | P25: N/A | Q25: N/A | R25: N/A | S25: N/A | T25: N/A | U25: N/A
A26: Romania-Promotion | B26: Change Job | C26: Location Details | D26: Work Shift | E26: =SUBSTITUTE(B26," ","") & "_" & SUBSTITUTE(IF(C26="N/A","",C26& "_")," ","") & SUBSTITUTE(SUBSTITUTE(D26," ",""),"/","") -> ChangeJob_LocationDetails_WorkShift | F26: =E26&2 -> ChangeJob_LocationDetails_WorkShift2 | G26: Should be 5 days for full time | H26: 5 | I26: 5 | J26: 5 | K26: 5 | L26: N/A | M26: N/A | N26: N/A | O26: N/A | P26: N/A | Q26: N/A | R26: N/A | S26: N/A | T26: N/A | U26: N/A
A27: Romania-Promotion | B27: Change Job | C27: Job Classifications | D27: Additional Job Classifications | E27: =SUBSTITUTE(B27," ","") & "_" & SUBSTITUTE(IF(C27="N/A","",C27& "_")," ","") & SUBSTITUTE(SUBSTITUTE(D27," ",""),"/","") -> ChangeJob_JobClassifications_AdditionalJobClassifications | F27: =E27&2 -> ChangeJob_JobClassifications_AdditionalJobClassifications2 | H27: N/A | I27: N/A | J27: N/A | K27: N/A | L27: N/A | M27: N/A | N27: REGULAR | O27: IRREGULAR | P27: N/A | Q27: N/A | R27: N/A | S27: N/A | T27: IRREGULER | U27: N/A
A28: Romania-Promotion, Portugal-Fixed_To_Permanent | B28: Change Job | C28: Job Classifications | D28: Employee Type | E28: =SUBSTITUTE(B28," ","") & "_" & SUBSTITUTE(IF(C28="N/A","",C28& "_")," ","") & SUBSTITUTE(SUBSTITUTE(D28," ",""),"/","") -> ChangeJob_JobClassifications_EmployeeType | F28: =E28&2 -> ChangeJob_JobClassifications_EmployeeType2 | G28: Choice of Permanent/Fixed | H28: N/A | I28: N/A | J28: N/A | K28: N/A | L28: Permanent | M28: Fixed term | N28: N/A | O28: N/A | P28: N/A | Q28: N/A | R28: N/A | S28: N/A | T28: N/A | U28: Permanent
A29: Romania-Promotion, Portugal-PT_To_FT | B29: Change Job | C29: Job Classifications | D29: Time Type | E29: =SUBSTITUTE(B29," ","") & "_" & SUBSTITUTE(IF(C29="N/A","",C29& "_")," ","") & SUBSTITUTE(SUBSTITUTE(D29," ",""),"/","") -> ChangeJob_JobClassifications_TimeType | F29: =E29&2 -> ChangeJob_JobClassifications_TimeType2 | G29: Choice of Full Time/Part Time | H29: Part Time | I29: Part Time | J29: Full Time | K29: Full Time | L29: N/A | M29: N/A | N29: N/A | O29: N/A | P29: N/A | Q29: N/A | R29: N/A | S29: N/A | T29: N/A | U29: N/A
A30: Romania-Promotion | B30: Change Job | C30: Job Classifications | D30: Pay Rate Type | E30: =SUBSTITUTE(B30," ","") & "_" & SUBSTITUTE(IF(C30="N/A","",C30& "_")," ","") & SUBSTITUTE(SUBSTITUTE(D30," ",""),"/","") -> ChangeJob_JobClassifications_PayRateType | F30: =E30&2 -> ChangeJob_JobClassifications_PayRateType2 | G30: Choice of Salary/Hourly/ | H30: N/A | I30: N/A | J30: N/A | K30: N/A | L30: N/A | M30: N/A | N30: N/A | O30: N/A | P30: N/A | Q30: N/A | R30: N/A | S30: N/A | T30: N/A | U30: N/A
A31: Romania-Promotion | B31: Change Job | C31: Job Classifications | D31: Default Weekly Hours | E31: =SUBSTITUTE(B31," ","") & "_" & SUBSTITUTE(IF(C31="N/A","",C31& "_")," ","") & SUBSTITUTE(SUBSTITUTE(D31," ",""),"/","") -> ChangeJob_JobClassifications_DefaultWeeklyHours | F31: =E31&2 -> ChangeJob_JobClassifications_DefaultWeeklyHours2 | H31: 40 | I31: 40 | J31: 40 | K31: 40 | L31: N/A | M31: N/A | N31: N/A | O31: N/A | P31: N/A | Q31: N/A | R31: N/A | S31: N/A | T31: N/A | U31: N/A
A32: Romania-Promotion | B32: Change Job | C32: Job Classifications | D32: End Employment Date | E32: =SUBSTITUTE(B32," ","") & "_" & SUBSTITUTE(IF(C32="N/A","",C32& "_")," ","") & SUBSTITUTE(SUBSTITUTE(D32," ",""),"/","") -> ChangeJob_JobClassifications_EndEmploymentDate | F32: =E32&2 -> ChangeJob_JobClassifications_EndEmploymentDate2 | H32: N/A | I32: N/A | J32: N/A | K32: N/A | L32: N/A | M32: N/A | N32: N/A | O32: N/A | P32: N/A | Q32: N/A | R32: 46722 | S32: N/A | T32: N/A | U32: N/A
A33: Change Job | B33: Change Job | C33: N/A | D33: ContractType | E33: =SUBSTITUTE(B33," ","") & "_" & SUBSTITUTE(IF(C33="N/A","",C33& "_")," ","") & SUBSTITUTE(SUBSTITUTE(D33," ",""),"/","") -> ChangeJob_ContractType | F33: =E33&2 -> ChangeJob_ContractType2 | G33: Permanent | H33: N/A | I33: N/A | J33: N/A | K33: N/A | L33: Permanent | M33: Fixed Term | N33: N/A | O33: N/A | P33: N/A | Q33: N/A | R33: Fixed Term | S33: N/A | T33: N/A | U33: N/A
B34: MaintainEmployeeContract | C34: N/A | D34: EndContractDate | E34: =SUBSTITUTE(B34," ","") & "_" & SUBSTITUTE(IF(C34="N/A","",C34& "_")," ","") & SUBSTITUTE(SUBSTITUTE(D34," ",""),"/","") -> MaintainEmployeeContract_EndContractDate | F34: =E34&2 -> MaintainEmployeeContract_EndContractDate2 | G34: Set to N/A when field not present otherwise automation will throw error | H34: N/A | I34: N/A | J34: N/A | K34: N/A | L34: N/A | M34: 46508 | N34: N/A | O34: N/A | P34: N/A | Q34: N/A | R34: 46722 | S34: N/A | T34: N/A | U34: N/A
A35: Romania-Promotion | B35: Change Job | C35: Job Classifications | D35: Assignment Type | E35: =SUBSTITUTE(B35," ","") & "_" & SUBSTITUTE(IF(C35="N/A","",C35& "_")," ","") & SUBSTITUTE(SUBSTITUTE(D35," ",""),"/","") -> ChangeJob_JobClassifications_AssignmentType | F35: =E35&2 -> ChangeJob_JobClassifications_AssignmentType2 | H35: N/A | I35: N/A | J35: N/A | K35: N/A | L35: N/A | M35: N/A | N35: N/A | O35: N/A | P35: N/A | Q35: N/A | R35: N/A | S35: N/A | T35: N/A | U35: N/A
A36: Romania-Promotion | B36: Change Job | C36: Job Classifications | D36: First Day of Work | E36: =SUBSTITUTE(B36," ","") & "_" & SUBSTITUTE(IF(C36="N/A","",C36& "_")," ","") & SUBSTITUTE(SUBSTITUTE(D36," ",""),"/","") -> ChangeJob_JobClassifications_FirstDayofWork | F36: =E36&2 -> ChangeJob_JobClassifications_FirstDayofWork2 | H36: N/A | I36: N/A | J36: N/A | K36: N/A | L36: N/A | M36: N/A | N36: N/A | O36: N/A | P36: N/A | Q36: N/A | R36: N/A | S36: N/A | T36: N/A | U36: N/A
A37: Romania-Promotion | B37: Change Job | C37: Company | D37: Cost Centre | E37: =SUBSTITUTE(B37," ","") & "_" & SUBSTITUTE(IF(C37="N/A","",C37& "_")," ","") & SUBSTITUTE(SUBSTITUTE(D37," ",""),"/","") -> ChangeJob_Company_CostCentre | F37: =E37&2 -> ChangeJob_Company_CostCentre2 | G37: Set to N/A if not promotion | H37: N/A | I37: N/A | J37: N/A | K37: N/A | L37: N/A | M37: N/A | N37: N/A | O37: N/A | P37: 92 Retail Management | Q37: 94 Retail Operatives | R37: N/A | S37: N/A | T37: N/A | U37: N/A
A38: Romania-Promotion | B38: Change Job | C38: Company | D38: Department | E38: =SUBSTITUTE(B38," ","") & "_" & SUBSTITUTE(IF(C38="N/A","",C38& "_")," ","") & SUBSTITUTE(SUBSTITUTE(D38," ",""),"/","") -> ChangeJob_Company_Department | F38: =E38&2 -> ChangeJob_Company_Department2 | G38: Set to N/A if department is the same | H38: N/A | I38: N/A | J38: N/A | K38: N/A | L38: N/A | M38: N/A | N38: N/A | O38: N/A | P38: 251 Management Retail | Q38: 01 Accessories | R38: N/A | S38: 15 Children’s Accessories | T38: N/A | U38: N/A
A39: Romania-Promotion | B39: Add Probation Period | C39: N/A | D39: Start Date | E39: =SUBSTITUTE(B39," ","") & "_" & SUBSTITUTE(IF(C39="N/A","",C39& "_")," ","") & SUBSTITUTE(SUBSTITUTE(D39," ",""),"/","") -> AddProbationPeriod_StartDate | F39: =E39&2 -> AddProbationPeriod_StartDate2 | H39: N/A | I39: N/A | J39: N/A | K39: N/A | L39: N/A | M39: N/A | N39: N/A | O39: N/A | P39: N/A | Q39: N/A | R39: N/A | S39: N/A | T39: N/A | U39: N/A
A40: Romania-Promotion | B40: Add Probation Period | C40: N/A | D40: End Date | E40: =SUBSTITUTE(B40," ","") & "_" & SUBSTITUTE(IF(C40="N/A","",C40& "_")," ","") & SUBSTITUTE(SUBSTITUTE(D40," ",""),"/","") -> AddProbationPeriod_EndDate | F40: =E40&2 -> AddProbationPeriod_EndDate2 | G40: For promotion must have value | H40: N/A | I40: N/A | J40: N/A | K40: N/A | L40: N/A | M40: N/A | N40: N/A | O40: N/A | P40: N/A | Q40: N/A | R40: N/A | S40: N/A | T40: N/A | U40: N/A
B41: Propose Compensation Change | C41: N/A | D41: Salary | E41: =SUBSTITUTE(B41," ","") & "_" & SUBSTITUTE(IF(C41="N/A","",C41& "_")," ","") & SUBSTITUTE(SUBSTITUTE(D41," ",""),"/","") -> ProposeCompensationChange_Salary | F41: =E41&2 -> ProposeCompensationChange_Salary2 | G41: Portugal Supervisor needs amount = €1234 | H41: N/A | I41: N/A | J41: N/A | K41: N/A | L41: N/A | M41: N/A | N41: N/A | O41: N/A | P41: N/A | Q41: N/A | R41: N/A | S41: N/A | T41: N/A | U41: N/A
...

Sheet Mapping Table
G4: Hungary
E5: Job Change Test_ID | F5: Hire Test_ID | G5: Job Change Test_ID | H5: Hire Test_ID
E6: Test_1 | F6: Test_3 | G6: E2E002_HU_JBC_TC01 | H6: E2E001_HU_HIR_TC001
E7: Test_2 | F7: Test_2 | G7: E2E002_HU_JBC_TC02 | H7: E2E001_HU_HIR_TC002
E8: Test_3 | F8: Test_6 | G8: E2E002_HU_JBC_TC03
E9: Test_4 | F9: Test_3 | G9: E2E002_HU_JBC_TC04
E10: Test_5 | F10: Test_8 | G10: E2E002_HU_JBC_TC05
E11: Test_6 | F11: Test_12 | G11: E2E002_HU_JBC_TC06
E12: Test_7 | F12: Test_9 | G12: E2E002_HU_JBC_TC07
E13: Test_8 | F13: N/A | G13: E2E002_HU_JBC_TC08
E14: Test_9 | F14: Test_10 | G14: E2E002_HU_JBC_TC09
E15: Test_10 | F15: Test_4 | G15: E2E002_HU_JBC_TC10
E16: Test_11 | F16: N/A | G16: E2E002_HU_JBC_TC11
G17: E2E002_HU_JBC_TC12
G18: E2E002_HU_JBC_TC13
G19: E2E002_HU_JBC_TC14
G20: E2E002_HU_JBC_TC15
G21: E2E002_HU_JBC_TC16
G22: E2E002_HU_JBC_TC17
G23: E2E002_HU_JBC_TC18
G24: E2E002_HU_JBC_TC19
G25: E2E002_HU_JBC_TC20
G26: E2E002_HU_JBC_TC21
G27: E2E002_HU_JBC_TC22
G28: E2E002_HU_JBC_TC23
... G33: E2E002_HU_JBC_TC28

Sheet Sheet1
A1: 10286580 | B1: 10286658
A2: 10286586 | B2: 10286659
A3: 10286587 | B3: 10286660
A4: 10286588 | B4: 10286661
A5: 10286589

Sheet Defects
B2: Batch 1 - Summary | E2: Batch 2 - Summary | H2: Batch 3 - Summary | K2: All E2E Cycle 1 - Summary
B3: Description | C3: Total | E3: Description | F3: Total | H3: Description | I3: Total | K3: Description | L3: Total No. | M3: %
B4: Passed | C4: 35 | E4: Passed | F4: 141 | H4: Passed | I4: 0 | K4: Passed | L4: =C4+F4+I4 -> 176 | M4: =L4/L8*100 -> 72.131148
B5: Failed | C5: 17 | E5: Failed | F5: 27 | H5: Failed | I5: 24 | K5: Failed | L5: =C5+F5+I5 -> 68 | M5: =L5/L8*100 -> 27.868852
B6: Not Run | C6: 0 | E6: Not Run | F6: 0 | H6: Not Run | I6: 0 | K6: Not Run | L6: =C6+F6+I6 -> 0 | M6: =L6/L8*100 -> 0
B7: Executed | C7: 52 | E7: Executed | F7: 168 | H7: Executed | I7: 24 | K7: Executed | L7: =C7+F7+I7 -> 244 | M7: =L7/L8*100 -> 100
B8: Total | C8: 52 | E8: Total | F8: 168 | H8: Total | I8: 24 | K8: Total | L8: =C8+F8+I8 -> 244 | M8: =M4+M5+M6 -> 100
B10: Batch 1 - Defects | E10: Batch 2 - Defects | H10: Batch 3 - Defects | K10: All E2E Cycle 1 - Defects
B11: Failed Tests Description | C11: Total | E11: Failed Tests Description | F11: Total | H11: Failed Tests Description | I11: Total | K11: Failed Tests Description | L11: Total No. | M11: %
B12: P&C Salary Assistant/Supervisor Salary Configuration missing | C12: 12 | E12: Grade Profile not populated causing salary to remain blank | F12: 24 | H12: Data issue - Rerun scheduled | I12: 24 | K12: Personal Information Change Approval Email missing after 2nd and final proxy into HR Manager | L12: 44 | M12: =L12/L17*100 -> 35.2
B13: Automation issue with Maiden Name - Gary to discuss with Shane/Andre | C13: 5 | E13: GC - Under Investigation | F13: 3 | H13: Total | I13: 24 | K13: Open button not available to assign paygroup for payroll. Approval required by David Bradley... | L13: 20 | M13: =L13/L17*100 -> 16
B14: Total | C14: =C12+C13 -> 17 | E14: Total | F14: 27 | K14: Grade Profile not populated causing salary to remain blank | L14: 34 | M14: =L14/L17*100 -> 27.2
K15: Data issue - Rerun scheduled | L15: 24 | M15: =L15/L17*100 -> 19.2
K16: GC - Under Investigation | L16: 3 | M16: =L16/L17*100 -> 2.4
K17: Total | L17: =SUM(L12:L16) -> 125 | M17: =SUM(M12:M16) -> 100

Sheet Automation_Lookups
A1: Process2 | B1: ExecutionFlag2 | C1: Country2 | D1: ChangeJob_Start_Reason2 | E1: ChangeJob_Start_NewManager2 | F1: ChangeJob_Start_NewTeam2 | G1: ChangeJob_Start_NewLocation2 | H1: ChangeJob_Start_NextPayPeriod2 | I1: ChangeJob_LocationDetails_WorkShift2 | Q1: SupervisoryOrganisation_SupervisoryOrganisation2 | R1: LegalNameInformation_Country2 | S1: ContactInformation_Phone_CountryPhoneCode2 | T1: ContactInformation_Phone_PhoneDevice2 | U1: ContactInformation_Phone_Type2 | V1: ContactInformation_Address_Type2 | W1: ContactInformation_Email_Type2 | X1: JobDetails_HireDate2 | Y1: JobDetails_Reason2 | Z1: JobDetails_Position2 | AA1: JobDetails_EmployeeType2 | AB1: JobDetails_JobProfile2 | AC1: JobDetails_TimeType2 | AD1: JobDetails_Location2 | AE1: JobDetails_AdditionalInformation_WorkShift2 | AF1: JobDetails_AdditionalInformation_EndEmploymentDate2 | AG1: ChangeOrganizationAssignments_DepartmentSection2 | AH1: AssignPayGroup_ProposedPayGroup2 | AI1: Proxy_ProxyNumber2 | AJ1: Proxy_OnBehalfOf2 | AK1: MaintainEmployeeContract_Reason2 | AL1: MaintainEmployeeContract_Status2 | AM1: MaintainEmployeeContract_ContractType2 | AN1: MaintainEmployeeContract_ContractEndDate2 | AO1: ProposeCompensationHire_GradeProfile2 | AP1: ProposeCompensationHire_Step2 | AQ1: EditPassportsandVisas_Country2 | AR1: EditPassportsandVisas_PassportIDType2 | AS1: EditPassportsandVisas_IdentificationNo2 | AT1: EditPassportsandVisas_IssuedDate2 | AU1: EditPassportsandVisas_ExpirationDate2 | AV1: ChangeMyPersonalInformation_MaritalStatus2 | AW1: ChangeMyEmergencyContacts_Relationship2 | AX1: ChangeMyEmergencyContacts_PhoneDevice2 | AY1: ChangeMyGovernmentIDs_NationalIDs_NationalIDType2 | AZ1: PaymentElectionOption_AccountType2 | BA1: SkillsAndExperience_AddEducation_School2 | BB1: AddProbationPeriod_ProbationEndDate2 | BC1: EditAdditionalData_PayrollTaxDeduction | BD1: HealthCareProvider_MealVoucher2 | BE1: School1 | BF1: School2 | BG1: ContactInformation_Address_Province2 | BH1: ChangeMyGovernmentIDs_NationalIDs_NationalIDType12 | BI1: ChangeMyGovernmentIDs_NationalIDs_NationalIDType22 | BJ1: EditAdditionalData_EstadolIRPF2 | BK1: EditAdditionalData_MinusvaliaRH2
A2: Promotion_To_Manager | B2: Yes | C2: Slovakia | D2: Promotion | H2: TRUE | I2: 1 Day | Q2: 362 Recruitment (Carolina De La Barrera Crespo (375)) | R2: Czechia | S2: Czechia (+420) | T2: Mobile | U2: Home | V2: Home | W2: Home | X2: =IF(MONTH(TODAY())<10,"0"&MONTH(TODAY())&"/",MONTH(TODAY())&"/") & IF(DAY(TODAY())<10,"0"&DAY(TODAY())&"/",DAY(TODAY())&"/") & YEAR(TODAY()) -> 05/21/2025 | Y2: New Hire | Z2: Assistant Manager-2 | AA2: Fixed Term | AB2: DPP/DPC | AC2: Full time | AD2: 362 Algeciras | AE2: 1 Day | AF2: =IF(MONTH(TODAY())<10,"0"&MONTH(TODAY())&"/",MONTH(TODAY())&"/") & IF(DAY(TODAY())<10,"0"&DAY(TODAY())&"/",DAY(TODAY())&"/") & YEAR(TODAY()) -> 05/21/2025 | AG2: Accessories | AH2: Please select a Spanish Pay Group | AI2: 10223439 | AJ2: Iwona Chrostowska (10223439) | AK2: for the purposes of performing any work of casual or seasonal nature | AL2: 1st Fixed Term Contract | AM2: Employment Agreement | AN2: =IF(MONTH(TODAY())<10,"0"&MONTH(TODAY())&"/",MONTH(TODAY())&"/") & IF(DAY(TODAY())<10,"0"&DAY(TODAY())&"/",DAY(TODAY())&"/") & YEAR(TODAY()) -> 05/21/2025 | AO2: Defaulted | AP2: Defaulted | AV2: Single | AW2: Father | AX2: Mobile/Cell | AY2: Social Security Number (NSS) | AZ2: Savings | BA2: N/A | BB2: =IF(MONTH(TODAY()+100)<10,"0"&MONTH(TODAY()+100)&"/",MONTH(TODAY()+100)&"/") & IF(DAY(TODAY()+100)<10,"0"&DAY(TODAY()+100)&"/",DAY(TODAY()+100)&"/") & YEAR(TODAY()+100) -> 08/29/2025 | BC2: Yes | BD2: Yes | BE2: Střední bez maturity či výučního listu | BF2: stredni bez maturity ci vyucniho listu | BG2: Madrid | BH2: Social Security Number (NSS) | BI2: ID Card (DNI) Number | BJ2: Soltero/a, viudo/a, divorciado/a o separado/a legalmente con hijos solteros menores de 18 años o incapacitados judicialmente que conviven exclusivamente con Vd., sin convivir también con el otro progenitor Soltero/a, viudo/a, divorciado/a o separado/a legalmente con hijos solteros menores de 18 años o incapacitados judicialmente que conviven exclusivamente con Vd., sin convivir también con el otro progenitor | BK2: Del 33% hasta el 65%
A3: PartTime_To_FullTime | B3: No | C3: Slovenia | D3: Change of Hours, Employee Type, Time Type, End Employment Date | H3: FALSE | I3: 2 Days | Q3: 895 Store Management (Male Teststmanager (10224969)) | R3: Czechia | S3: Czechia (+420) | T3: Landline | U3: Work | V3: Work | W3: Work | X3: =IF(MONTH(TODAY()-10)<10,"0"&MONTH(TODAY()-10)&"/",MONTH(TODAY()-10))&"/" & IF(DAY(TODAY()-10)<10,"0"&DAY(TODAY()-10)&"/",DAY(TODAY()-10)&"/") & YEAR(TODAY()-10) -> 05//11/2025 | Z3: Assistant Manager-3 | AA3: Intern | AB3: Retail Assistant | AC3: Part time | AE3: 2 Days | AF3: =IF(MONTH(TODAY()+100)<10,"0"&MONTH(TODAY()+100)&"/",MONTH(TODAY()+100)&"/") & IF(DAY(TODAY()+100)<10,"0"&DAY(TODAY()+100)&"/",DAY(TODAY()+100)&"/") & YEAR(TODAY()+100) -> 08/29/2025 | AH3: ES Monthly - 15 payments | AI3: 10225553 | AJ3: Kocour Mikeš (10225553) | AK3: for the purposes of performing work during the term of office | AL3: 2nd Fixed Term Contract | AM3: Agreement to perform work | AN3: =IF(MONTH(TODAY()+100)<10,"0"&MONTH(TODAY()+100)&"/",MONTH(TODAY()+100)&"/") & IF(DAY(TODAY()+100)<10,"0"&DAY(TODAY()+100)&"/",DAY(TODAY()+100)&"/") & YEAR(TODAY()+100) -> 08/29/2025 | AV3: Married | AW3: Mother | AX3: Telephone - Landline | AY3: ID Card (DNI) Number | AZ3: Checking | BA3: Vseobecne stredni s maturitou | BB3: =IF(MONTH(TODAY()+1000)<10,"0"&MONTH(TODAY()+1000)&"/",MONTH(TODAY()+1000)&"/") & IF(DAY(TODAY()+1000)<10,"0"&DAY(TODAY()+1000)&"/",DAY(TODAY()+1000)&"/") & YEAR(TODAY()+1000) -> 02/15/2028 | BC3: No | BD3: No | BE3: Střední odborné vzdělání s výučním listem | BF3: stredni odborne vzdelani s vyucnim listem
A4: FullTime_To_PartTime | C4: USA | D4: Step Back | I4: 3 Days | R4: Poland | S4: Poland (+48) | X4: =IF(MONTH(TODAY()+10)<10,"0"&MONTH(TODAY()+10)&"/",MONTH(TODAY()+10)&"/") & IF(DAY(TODAY()+10)<10,"0"&DAY(TODAY()+10)&"/",DAY(TODAY()+10)&"/") & YEAR(TODAY()+10) -> 05/31/2025 | Z4: Test Store Manager-2 | AA4: Permanent | AB4: Department Manager | AE4: 3 Days | AF4: =IF(MONTH(TODAY()+1000)<10,"0"&MONTH(TODAY()+1000)&"/",MONTH(TODAY()+1000)&"/") & IF(DAY(TODAY()+1000)<10,"0"&DAY(TODAY()+1000)&"/",DAY(TODAY()+1000)&"/") & YEAR(TODAY()+1000) -> 02/15/2028 | AK4: for the purposes of substituting an employee during his/her excused absence at work | AL4: 3rd Fixed Term Contract | AM4: Agreement to complete a job | AN4: =IF(MONTH(TODAY()+1000)<10,"0"&MONTH(TODAY()+1000)&"/",MONTH(TODAY()+1000)&"/") & IF(DAY(TODAY()+1000)<10,"0"&DAY(TODAY()+1000)&"/",DAY(TODAY()+1000)&"/") & YEAR(TODAY()+1000) -> 02/15/2028 | AV4: Not Disclosed | AW4: Spouse | BB4: N/A | BE4: Všeobecné střední s maturitou | BF4: vseobecne stredni s maturitou
A5: Demotion | C5: UK | I5: 4 Days | R5: Poland | S5: Poland (+48) | Z5: N/A | AA5: Students | AB5: Senior Department Manager | AE5: 4 Days | AF5: N/A | AK5: No reason necessary | AL5: Active | AN5: N/A | AW5: Partner | BE5: Vysokoškolské Bc. | BF5: Vysokoskolske Bc
A6: Promotion | C6: Czechia | I6: 5 Days | AB6: Supervisor | AE6: 5 Days | AL6: Inactive | BE6: Vysokoškolské MUDr., JUDr., Mgr., MgA., Ing. | BF6: vysokoskolske MUDR., JUDr., Mgr., MgA., Ing.
A7: Permanent | C7: Italy | AB7: P&C Supervisor | BE7: Vysokoškolské PhDr, PhD, JUDr, MUDr | BF7: vysokoskolske PhDr, PhD, JUDr, MUDr
C8: Portugal | AB8: P&C Assistant | BE8: vyšší odborné DiS | BF8: vyssi odborne DiS
C9: France | AB9: Trainee Manager | BE9: Základní | BF9: Zakladni
C10: Poland | AB10: Assistant Manager
C11: Romania | AB11: P&C Manager
C12: Ireland | AB12: Store Manager
C13: Belgium | AB13: Visual Merchandiser Manager
C14: Netherlands | AB14: Visual Merchandising Supervisor
C15: Spain | AB15: Visual Merchandising Assistant
C16: Hungary
Y21: Rehire | AI21: 8701839 | AJ21: Lisanne Kluinhaar (8701839) | AK21: Defined contract end date (Determined) | BD21: Netherlands Retail Assistant
Q22: 701 Recruitment (Lisanne Kluinhaar (8701839)) | R22: Netherlands | S22: Netherlands (+31) | Y22: Seasonal | AK22: Undefined contract end date (Undetermined) | AM22: Part-time( PT ) | BD22: Netherlands Retail Assistant Cash Office | BE22: Retail Assistant (18)
AK23: Intern | AM23: Full-time( FT. ) | BE23: Retail Assistant (19)
Q24: Retail - Central & Eastern Europe (Stephen Regan (9910010) (Inherited) | R24: Poland | S24: Poland (+48) | BE24: Retail Assistant (20)
Q25: Retail Poland Area: Central Poland (Stephen Regan (9910010) (Inherited)) | R25: Poland | S25: Poland (+48) | BE25: Retail Assistant (21)
BE26: Retail Assistant (22)
BE27: Retail Assistant (23+)
BE28: Retail Assistant (Under 18)

Sheet RC. No
A1: D.O.B | B1: 35139 | C1: 33054 | D1: 31390 | F1: r col b | G1: r col c | H1: r col d
B2: 9603150007 | C2: 9006300006 | D2: 8512090004 | F2: =B2/11 -> 873013637 | G2: =C2/11 -> 818754546 | H2: =D2/11 -> 773826364
B3: =B2+11 -> 9603150018 | C3: =C2+11 -> 9006300017 | D3: =D2+11 -> 8512090015 | F3: =B3/11 -> 873013638 | G3: =C3/11 -> 818754547 | H3: =D3/11 -> 773826365
B4: =B3+11 -> 9603150029 | C4: =C3+11 -> 9006300028 | D4: =D3+11 -> 8512090026 | F4: =B4/11 -> 873013639 | G4: =C4/11 -> 818754548 | H4: =D4/11 -> 773826366
B5: =B4+11 -> 9603150040 | C5: =C4+11 -> 9006300039 | D5: =D4+11 -> 8512090037 | F5: =B5/11 -> 873013640 | G5: =C5/11 -> 818754549 | H5: =D5/11 -> 773826367
B6: =B5+11 -> 9603150051 | C6: =C5+11 -> 9006300050 | D6: =D5+11 -> 8512090048 | F6: =B6/11 -> 873013641 | G6: =C6/11 -> 818754550 | H6: =D6/11 -> 773826368
B7: =B6+11 -> 9603150062 | C7: =C6+11 -> 9006300061 | D7: =D6+11 -> 8512090059 | F7: =B7/11 -> 873013642 | G7: =C7/11 -> 818754551 | H7: =D7/11 -> 773826369
B8: =B7+11 -> 9603150073 | C8: =C7+11 -> 9006300072 | D8: =D7+11 -> 8512090070 | F8: =B8/11 -> 873013643 | G8: =C8/11 -> 818754552 | H8: =D8/11 -> 773826370
B9: =B8+11 -> 9603150084 | C9: =C8+11 -> 9006300083 | D9: =D8+11 -> 8512090081 | F9: =B9/11 -> 873013644 | G9: =C9/11 -> 818754553 | H9: =D9/11 -> 773826371
B10: =B9+11 -> 9603150095 | C10: =C9+11 -> 9006300094 | D10: =D9+11 -> 8512090092 | F10: =B10/11 -> 873013645 | G10: =C10/11 -> 818754554 | H10: =D10/11 -> 773826372
B11: =B10+11 -> 9603150106 | C11: =C10+11 -> 9006300105 | D11: =D10+11 -> 8512090103 | F11: =B11/11 -> 873013646 | G11: =C11/11 -> 818754555 | H11: =D11/11 -> 773826373
B12: =B11+11 -> 9603150117 | C12: =C11+11 -> 9006300116 | D12: =D11+11 -> 8512090114 | F12: =B12/11 -> 873013647 | G12: =C12/11 -> 818754556 | H12: =D12/11 -> 773826374
B13: =B12+11 -> 9603150128 | C13: =C12+11 -> 9006300127 | D13: =D12+11 -> 8512090125 | F13: =B13/11 -> 873013648 | G13: =C13/11 -> 818754557 | H13: =D13/11 -> 773826375
B14: =B13+11 -> 9603150139 | C14: =C13+11 -> 9006300138 | D14: =D13+11 -> 8512090136 | F14: =B14/11 -> 873013649 | G14: =C14/11 -> 818754558 | H14: =D14/11 -> 773826376
... B28: =B27+11 -> 9603150293 | C28: =C27+11 -> 9006300292 | D28: =D27+11 -> 8512090290 | F28: =B28/11 -> 873013663 | G28: =C28/11 -> 818754572 | H28: =D28/11 -> 773826390
B29: =B28+11 -> 9603150304
B30: =B29+11 -> 9603150315
B31: =B30+11 -> 9603150326
B32: =B31+11 -> 9603150337
B33: =B32+11 -> 9603150348
B34: =B33+11 -> 9603150359
B35: =B34+11 -> 9603150370
B36: =B35+11 -> 9603150381
B37: =B36+11 -> 9603150392
B38: =B37+11 -> 9603150403
B39: =B38+11 -> 9603150414
B40: =B39+11 -> 9603150425
... B75: =B74+11 -> 9603150810
B76: =B75+11 -> 9603150821 | X76: New RC Numbers
B77: =B76+11 -> 9603150832 | X77: 9202101337
B78: =B77+11 -> 9603150843 | X78: =SUM(X77)+11 -> 9202101348
B79: =B78+11 -> 9603150854 | X79: =SUM(X78)+11 -> 9202101359
B80: =B79+11 -> 9603150865 | X80: =SUM(X79)+11 -> 9202101370
B81: =B80+11 -> 9603150876 | X81: =SUM(X80)+11 -> 9202101381
B82: =B81+11 -> 9603150887 | X82: =SUM(X81)+11 -> 9202101392
B83: =B82+11 -> 9603150898 | X83: =SUM(X82)+11 -> 9202101403
B84: =B83+11 -> 9603150909 | X84: =SUM(X83)+11 -> 9202101414
B85: =B84+11 -> 9603150920 | X85: =SUM(X84)+11 -> 9202101425
B86: =B85+11 -> 9603150931 | D86: 9603170269 | X86: =SUM(X85)+11 -> 9202101436
D87: =D86+11 -> 9603170280 | F87: 9603170280 | H87: 9603170280 | I87: 9603170291 | J87: 9603170302 | K87: 9603170313 | L87: 9603170324 | M87: 9603170335 | N87: 9603170346 | O87: 9603170357 | P87: 9603170368 | Q87: 9603170379 | R87: 9603170390 | S87: 9603170401 | T87: 9603170412 | X87: =SUM(X86)+11 -> 9202101447
...

Sheet Code_11122019_1000
B1: Variable Row | C1: Variable Row Combined | D1: Variable Value | E1: Variable Value Combined | F1: Row Number Declaration --------------------------------- intRowProcess = comExcelWorksheet.Range("Process").Row | G1: Value Declaration ------------------------ strProcess = comExcelWorksheet.Cells(intRowProcess, intColTestColumn).Value | H1: Getters
A2: =Test_Data!E3 -> Process | B2: ="intRow" & A2 & ", " -> intRowProcess, | C2: =B2 -> intRowProcess, | D2: ="str" & A2 & ", " -> strProcess, | E2: =D2 -> strProcess, | F2: ="intRow" & A2 & " = comExcelWorksheet.Range(""" & A2 & """).Row" -> intRowProcess = comExcelWorksheet.Range("Process").Row | G2: ="str" & A2 & " = comExcelWorksheet.Cells(intRow" & A2 & ", intColTestColumn).Value" -> strProcess = comExcelWorksheet.Cells(intRowProcess, intColTestColumn).Value | H2: ="Public Property Get get" & A2 & "() : get" & A2 & " = str" & A2 & " : End Property" -> Public Property Get getProcess() : getProcess = strProcess : End Property
A3: =Test_Data!E4 -> ExecutionFlag | B3: ="intRow" & A3 & ", " -> intRowExecutionFlag, | C3: =B3 -> intRowExecutionFlag, | D3: ="str" & A3 & ", " -> strExecutionFlag, | E3: =E2 & " " & D3 -> strProcess, strExecutionFlag, | F3: ="intRow" & A3 & " = comExcelWorksheet.Range(""" & A3 & """).Row" -> intRowExecutionFlag = comExcelWorksheet.Range("ExecutionFlag").Row | G3: ="str" & A3 & " = comExcelWorksheet.Cells(intRow" & A3 & ", intColTestColumn).Value" -> strExecutionFlag = comExcelWorksheet.Cells(intRowExecutionFlag, intColTestColumn).Value | H3: ="Public Property Get get" & A3 & "() : get" & A3 & " = str" & A3 & " : End Property" -> Public Property Get getExecutionFlag() : getExecutionFlag = strExecutionFlag : End Property
A4: =Test_Data!E5 -> Country | B4: ="intRow" & A4 & ", " -> intRowCountry, | C4: =B4 -> intRowCountry, | D4: ="str" & A4 & ", " -> strCountry, | E4: =E3 & " " & D4 -> strProcess, strExecutionFlag, strCountry, | F4: ="intRow" & A4 & " = comExcelWorksheet.Range(""" & A4 & """).Row" -> intRowCountry = comExcelWorksheet.Range("Country").Row | G4: ="str" & A4 & " = comExcelWorksheet.Cells(intRow" & A4 & ", intColTestColumn).Value" -> strCountry = comExcelWorksheet.Cells(intRowCountry, intColTestColumn).Value | H4: ="Public Property Get get" & A4 & "() : get" & A4 & " = str" & A4 & " : End Property" -> Public Property Get getCountry() : getCountry = strCountry : End Property
A5: =Test_Data!E6 -> LastRunTimeandStatus | B5: ="intRow" & A5 & ", " -> intRowLastRunTimeandStatus, | C5: =B5 -> intRowLastRunTimeandStatus, | D5: ="str" & A5 & ", " -> strLastRunTimeandStatus, | E5: =E4 & " " & D5 -> strProcess, strExecutionFlag, strCountry, strLastRunTimeandStatus, | F5: ="intRow" & A5 & " = comExcelWorksheet.Range(""" & A5 & """).Row" -> intRowLastRunTimeandStatus = comExcelWorksheet.Range("LastRunTimeandStatus").Row | G5: ="str" & A5 & " = comExcelWorksheet.Cells(intRow" & A5 & ", intColTestColumn).Value" -> strLastRunTimeandStatus = comExcelWorksheet.Cells(intRowLastRunTimeandStatus, intColTestColumn).Value | H5: ="Public Property Get get" & A5 & "() : get" & A5 & " = str" & A5 & " : End Property" -> Public Property Get getLastRunTimeandStatus() : getLastRunTimeandStatus = strLastRunTimeandStatus : End Property
A6: =Test_Data!E7 -> LastRunErrorMessage | B6: ="intRow" & A6 & ", " -> intRowLastRunErrorMessage, | C6: =B6 -> intRowLastRunErrorMessage, | D6: ="str" & A6 & ", " -> strLastRunErrorMessage, | E6: =E5 & " " & D6 -> strProcess, strExecutionFlag, strCountry, strLastRunTimeandStatus, strLastRunErrorMessage, | F6: ="intRow" & A6 & " = comExcelWorksheet.Range(""" & A6 & """).Row" -> intRowLastRunErrorMessage = comExcelWorksheet.Range("LastRunErrorMessage").Row | G6: ="str" & A6 & " = comExcelWorksheet.Cells(intRow" & A6 & ", intColTestColumn).Value" -> strLastRunErrorMessage = comExcelWorksheet.Cells(intRowLastRunErrorMessage, intColTestColumn).Value | H6: ="Public Property Get get" & A6 & "() : get" & A6 & " = str" & A6 & " : End Property" -> Public Property Get getLastRunErrorMessage() : getLastRunErrorMessage = strLastRunErrorMessage : End Property
A7: =Test_Data!E13 -> Login_Username | B7: ="intRow" & A7 & ", " -> intRowLogin_Username, | C7: =B7 -> intRowLogin_Username, | D7: ="str" & A7 & ", " -> strLogin_Username, | E7: =E6 & " " & D7 -> strProcess, strExecutionFlag, strCountry, strLastRunTimeandStatus, strLastRunErrorMessage, strLogin_Username, | F7: ="intRow" & A7 & " = comExcelWorksheet.Range(""" & A7 & """).Row" -> intRowLogin_Username = comExcelWorksheet.Range("Login_Username").Row | G7: ="str" & A7 & " = comExcelWorksheet.Cells(intRow" & A7 & ", intColTestColumn).Value" -> strLogin_Username = comExcelWorksheet.Cells(intRowLogin_Username, intColTestColumn).Value | H7: ="Public Property Get get" & A7 & "() : get" & A7 & " = str" & A7 & " : End Property" -> Public Property Get getLogin_Username() : getLogin_Username = strLogin_Username : End Property
A8: =Test_Data!E14 -> Login_Password | B8: ="intRow" & A8 & ", " -> intRowLogin_Password, | C8: =B8 -> intRowLogin_Password, | D8: ="str" & A8 & ", " -> strLogin_Password, | E8: =E7 & " " & D8 -> strProcess, strExecutionFlag, strCountry, strLastRunTimeandStatus, strLastRunErrorMessage, strLogin_Username, strLogin_Password, | F8: ="intRow" & A8 & " = comExcelWorksheet.Range(""" & A8 & """).Row" -> intRowLogin_Password = comExcelWorksheet.Range("Login_Password").Row | G8: ="str" & A8 & " = comExcelWorksheet.Cells(intRow" & A8 & ", intColTestColumn).Value" -> strLogin_Password = comExcelWorksheet.Cells(intRowLogin_Password, intColTestColumn).Value | H8: ="Public Property Get get" & A8 & "() : get" & A8 & " = str" & A8 & " : End Property" -> Public Property Get getLogin_Password() : getLogin_Password = strLogin_Password : End Property
A9: =Test_Data!#REF! -> #REF! | B9: ="intRow" & A9 & ", " -> #REF! | C9: =B9 -> #REF! | D9: ="str" & A9 & ", " -> #REF! | E9: =E8 & " " & D9 -> #REF! | F9: ="intRow" & A9 & " = comExcelWorksheet.Range(""" & A9 & """).Row" -> #REF! | G9: ="str" & A9 & " = comExcelWorksheet.Cells(intRow" & A9 & ", intColTestColumn).Value" -> #REF! | H9: ="Public Property Get get" & A9 & "() : get" & A9 & " = str" & A9 & " : End Property" -> #REF!
A10: =Test_Data!#REF! -> #REF! | B10: ="intRow" & A10 & ", " -> #REF! | C10: =B10 -> #REF! | D10: ="str" & A10 & ", " -> #REF! | E10: =E9 & " " & D10 -> #REF! | F10: ="intRow" & A10 & " = comExcelWorksheet.Range(""" & A10 & """).Row" -> #REF! | G10: ="str" & A10 & " = comExcelWorksheet.Cells(intRow" & A10 & ", intColTestColumn).Value" -> #REF! | H10: ="Public Property Get get" & A10 & "() : get" & A10 & " = str" & A10 & " : End Property" -> #REF!
A11: =Test_Data!E15 -> Proxy_EmployeeID | B11: ="intRow" & A11 & ", " -> intRowProxy_EmployeeID, | C11: =B11 -> intRowProxy_EmployeeID, | D11: ="str" & A11 & ", " -> strProxy_EmployeeID, | E11: =E10 & " " & D11 -> #REF! | F11: ="intRow" & A11 & " = comExcelWorksheet.Range(""" & A11 & """).Row" -> intRowProxy_EmployeeID = comExcelWorksheet.Range("Proxy_EmployeeID").Row | G11: ="str" & A11 & " = comExcelWorksheet.Cells(intRow" & A11 & ", intColTestColumn).Value" -> strProxy_EmployeeID = comExcelWorksheet.Cells(intRowProxy_EmployeeID, intColTestColumn).Value | H11: ="Public Property Get get" & A11 & "() : get" & A11 & " = str" & A11 & " : End Property" -> Public Property Get getProxy_EmployeeID() : getProxy_EmployeeID = strProxy_EmployeeID : End Property
A12: =Test_Data!#REF! -> #REF! | B12: ="intRow" & A12 & ", " -> #REF! | C12: =B12 -> #REF! | D12: ="str" & A12 & ", " -> #REF! | E12: =E11 & " " & D12 -> #REF! | F12: ="intRow" & A12 & " = comExcelWorksheet.Range(""" & A12 & """).Row" -> #REF! | G12: ="str" & A12 & " = comExcelWorksheet.Cells(intRow" & A12 & ", intColTestColumn).Value" -> #REF! | H12: ="Public Property Get get" & A12 & "() : get" & A12 & " = str" & A12 & " : End Property" -> #REF!
A13: =Test_Data!E16 -> ChangeJob_Start_EffectiveDate | B13: ="intRow" & A13 & ", " -> intRowChangeJob_Start_EffectiveDate, | C13: =B13 -> intRowChangeJob_Start_EffectiveDate, | D13: ="str" & A13 & ", " -> strChangeJob_Start_EffectiveDate, | E13: =E12 & " " & D13 -> #REF! | F13: ="intRow" & A13 & " = comExcelWorksheet.Range(""" & A13 & """).Row" -> intRowChangeJob_Start_EffectiveDate = comExcelWorksheet.Range("ChangeJob_Start_EffectiveDate").Row | G13: ="str" & A13 & " = comExcelWorksheet.Cells(intRow" & A13 & ", intColTestColumn).Value" -> strChangeJob_Start_EffectiveDate = comExcelWorksheet.Cells(intRowChangeJob_Start_EffectiveDate, intColTestColumn).Value | H13: ="Public Property Get get" & A13 & "() : get" & A13 & " = str" & A13 & " : End Property" -> Public Property Get getChangeJob_Start_EffectiveDate() : getChangeJob_Start_EffectiveDate = strChangeJob_Start_EffectiveDate : End Property
A14: =Test_Data!E17 -> ChangeJob_Start_Reason | B14: ="intRow" & A14 & ", " -> intRowChangeJob_Start_Reason, | C14: =B14 -> intRowChangeJob_Start_Reason, | D14: ="str" & A14 & ", " -> strChangeJob_Start_Reason, | E14: =E13 & " " & D14 -> #REF! | F14: ="intRow" & A14 & " = comExcelWorksheet.Range(""" & A14 & """).Row" -> intRowChangeJob_Start_Reason = comExcelWorksheet.Range("ChangeJob_Start_Reason").Row | G14: ="str" & A14 & " = comExcelWorksheet.Cells(intRow" & A14 & ", intColTestColumn).Value" -> strChangeJob_Start_Reason = comExcelWorksheet.Cells(intRowChangeJob_Start_Reason, intColTestColumn).Value | H14: ="Public Property Get get" & A14 & "() : get" & A14 & " = str" & A14 & " : End Property" -> Public Property Get getChangeJob_Start_Reason() : getChangeJob_Start_Reason = strChangeJob_Start_Reason : End Property
A15: =Test_Data!E18 -> ChangeJob_Start_NewManager | B15: ="intRow" & A15 & ", " -> intRowChangeJob_Start_NewManager, | C15: =B15 -> intRowChangeJob_Start_NewManager, | D15: ="str" & A15 & ", " -> strChangeJob_Start_NewManager, | E15: =E14 & " " & D15 -> #REF! | F15: ="intRow" & A15 & " = comExcelWorksheet.Range(""" & A15 & """).Row" -> intRowChangeJob_Start_NewManager = comExcelWorksheet.Range("ChangeJob_Start_NewManager").Row | G15: ="str" & A15 & " = comExcelWorksheet.Cells(intRow" & A15 & ", intColTestColumn).Value" -> strChangeJob_Start_NewManager = comExcelWorksheet.Cells(intRowChangeJob_Start_NewManager, intColTestColumn).Value | H15: ="Public Property Get get" & A15 & "() : get" & A15 & " = str" & A15 & " : End Property" -> Public Property Get getChangeJob_Start_NewManager() : getChangeJob_Start_NewManager = strChangeJob_Start_NewManager : End Property
A16: =Test_Data!E19 -> ChangeJob_Start_NewTeam | B16: ="intRow" & A16 & ", " -> intRowChangeJob_Start_NewTeam, | C16: =B16 -> intRowChangeJob_Start_NewTeam, | D16: ="str" & A16 & ", " -> strChangeJob_Start_NewTeam, | E16: =E15 & " " & D16 -> #REF! | F16: ="intRow" & A16 & " = comExcelWorksheet.Range(""" & A16 & """).Row" -> intRowChangeJob_Start_NewTeam = comExcelWorksheet.Range("ChangeJob_Start_NewTeam").Row | G16: ="str" & A16 & " = comExcelWorksheet.Cells(intRow" & A16 & ", intColTestColumn).Value" -> strChangeJob_Start_NewTeam = comExcelWorksheet.Cells(intRowChangeJob_Start_NewTeam, intColTestColumn).Value | H16: ="Public Property Get get" & A16 & "() : get" & A16 & " = str" & A16 & " : End Property" -> Public Property Get getChangeJob_Start_NewTeam() : getChangeJob_Start_NewTeam = strChangeJob_Start_NewTeam : End Property
A17: =Test_Data!E20 -> ChangeJob_Start_NewLocation | B17: ="intRow" & A17 & ", " -> intRowChangeJob_Start_NewLocation, | C17: =B17 -> intRowChangeJob_Start_NewLocation, | D17: ="str" & A17 & ", " -> strChangeJob_Start_NewLocation, | E17: =E16 & " " & D17 -> #REF! | F17: ="intRow" & A17 & " = comExcelWorksheet.Range(""" & A17 & """).Row" -> intRowChangeJob_Start_NewLocation = comExcelWorksheet.Range("ChangeJob_Start_NewLocation").Row | G17: ="str" & A17 & " = comExcelWorksheet.Cells(intRow" & A17 & ", intColTestColumn).Value" -> strChangeJob_Start_NewLocation = comExcelWorksheet.Cells(intRowChangeJob_Start_NewLocation, intColTestColumn).Value | H17: ="Public Property Get get" & A17 & "() : get" & A17 & " = str" & A17 & " : End Property" -> Public Property Get getChangeJob_Start_NewLocation() : getChangeJob_Start_NewLocation = strChangeJob_Start_NewLocation : End Property
A18: =Test_Data!E21 -> ChangeJob_Start_NextPayPeriod | B18: ="intRow" & A18 & ", " -> intRowChangeJob_Start_NextPayPeriod, | C18: =B18 -> intRowChangeJob_Start_NextPayPeriod, | D18: ="str" & A18 & ", " -> strChangeJob_Start_NextPayPeriod, | E18: =E17 & " " & D18 -> #REF! | F18: ="intRow" & A18 & " = comExcelWorksheet.Range(""" & A18 & """).Row" -> intRowChangeJob_Start_NextPayPeriod = comExcelWorksheet.Range("ChangeJob_Start_NextPayPeriod").Row | G18: ="str" & A18 & " = comExcelWorksheet.Cells(intRow" & A18 & ", intColTestColumn).Value" -> strChangeJob_Start_NextPayPeriod = comExcelWorksheet.Cells(intRowChangeJob_Start_NextPayPeriod, intColTestColumn).Value | H18: ="Public Property Get get" & A18 & "() : get" & A18 & " = str" & A18 & " : End Property" -> Public Property Get getChangeJob_Start_NextPayPeriod() : getChangeJob_Start_NextPayPeriod = strChangeJob_Start_NextPayPeriod : End Property
A19: =Test_Data!E22 -> ChangeJob_JobProfile_JobProfile | B19: ="intRow" & A19 & ", " -> intRowChangeJob_JobProfile_JobProfile, | C19: =B19 -> intRowChangeJob_JobProfile_JobProfile, | D19: ="str" & A19 & ", " -> strChangeJob_JobProfile_JobProfile, | E19: =E18 & " " & D19 -> #REF! | F19: ="intRow" & A19 & " = comExcelWorksheet.Range(""" & A19 & """).Row" -> intRowChangeJob_JobProfile_JobProfile = comExcelWorksheet.Range("ChangeJob_JobProfile_JobProfile").Row | G19: ="str" & A19 & " = comExcelWorksheet.Cells(intRow" & A19 & ", intColTestColumn).Value" -> strChangeJob_JobProfile_JobProfile = comExcelWorksheet.Cells(intRowChangeJob_JobProfile_JobProfile, intColTestColumn).Value | H19: ="Public Property Get get" & A19 & "() : get" & A19 & " = str" & A19 & " : End Property" -> Public Property Get getChangeJob_JobProfile_JobProfile() : getChangeJob_JobProfile_JobProfile = strChangeJob_JobProfile_JobProfile : End Property
A20: =Test_Data!E23 -> ChangeJob_JobProfile_JobTitle | B20: ="intRow" & A20 & ", " -> intRowChangeJob_JobProfile_JobTitle, | C20: =B20 -> intRowChangeJob_JobProfile_JobTitle, | D20: ="str" & A20 & ", " -> strChangeJob_JobProfile_JobTitle, | E20: =E19 & " " & D20 -> #REF! | F20: ="intRow" & A20 & " = comExcelWorksheet.Range(""" & A20 & """).Row" -> intRowChangeJob_JobProfile_JobTitle = comExcelWorksheet.Range("ChangeJob_JobProfile_JobTitle").Row | G20: ="str" & A20 & " = comExcelWorksheet.Cells(intRow" & A20 & ", intColTestColumn).Value" -> strChangeJob_JobProfile_JobTitle = comExcelWorksheet.Cells(intRowChangeJob_JobProfile_JobTitle, intColTestColumn).Value | H20: ="Public Property Get get" & A20 & "() : get" & A20 & " = str" & A20 & " : End Property" -> Public Property Get getChangeJob_JobProfile_JobTitle() : getChangeJob_JobProfile_JobTitle = strChangeJob_JobProfile_JobTitle : End Property
A21: =Test_Data!E24 -> ChangeJob_LocationDetails_Location | B21: ="intRow" & A21 & ", " -> intRowChangeJob_LocationDetails_Location, | C21: =B21 -> intRowChangeJob_LocationDetails_Location, | D21: ="str" & A21 & ", " -> strChangeJob_LocationDetails_Location, | E21: =E20 & " " & D21 -> #REF! | F21: ="intRow" & A21 & " = comExcelWorksheet.Range(""" & A21 & """).Row" -> intRowChangeJob_LocationDetails_Location = comExcelWorksheet.Range("ChangeJob_LocationDetails_Location").Row | G21: ="str" & A21 & " = comExcelWorksheet.Cells(intRow" & A21 & ", intColTestColumn).Value" -> strChangeJob_LocationDetails_Location = comExcelWorksheet.Cells(intRowChangeJob_LocationDetails_Location, intColTestColumn).Value | H21: ="Public Property Get get" & A21 & "() : get" & A21 & " = str" & A21 & " : End Property" -> Public Property Get getChangeJob_LocationDetails_Location() : getChangeJob_LocationDetails_Location = strChangeJob_LocationDetails_Location : End Property
A22: =Test_Data!E25 -> ChangeJob_LocationDetails_ScheduledWeeklyHours | B22: ="intRow" & A22 & ", " -> intRowChangeJob_LocationDetails_ScheduledWeeklyHours, | C22: =B22 -> intRowChangeJob_LocationDetails_ScheduledWeeklyHours, | D22: ="str" & A22 & ", " -> strChangeJob_LocationDetails_ScheduledWeeklyHours, | E22: =E21 & " " & D22 -> #REF! | F22: ="intRow" & A22 & " = comExcelWorksheet.Range(""" & A22 & """).Row" -> intRowChangeJob_LocationDetails_ScheduledWeeklyHours = comExcelWorksheet.Range("ChangeJob_LocationDetails_ScheduledWeeklyHours").Row | G22: ="str" & A22 & " = comExcelWorksheet.Cells(intRow" & A22 & ", intColTestColumn).Value" -> strChangeJob_LocationDetails_ScheduledWeeklyHours = comExcelWorksheet.Cells(intRowChangeJob_LocationDetails_ScheduledWeeklyHours, intColTestColumn).Value | H22: ="Public Property Get get" & A22 & "() : get" & A22 & " = str" & A22 & " : End Property" -> Public Property Get getChangeJob_LocationDetails_ScheduledWeeklyHours() : getChangeJob_LocationDetails_ScheduledWeeklyHours = strChangeJob_LocationDetails_ScheduledWeeklyHours : End Property
A23: =Test_Data!E26 -> ChangeJob_LocationDetails_WorkShift | B23: ="intRow" & A23 & ", " -> intRowChangeJob_LocationDetails_WorkShift, | C23: =B23 -> intRowChangeJob_LocationDetails_WorkShift, | D23: ="str" & A23 & ", " -> strChangeJob_LocationDetails_WorkShift, | E23: =E22 & " " & D23 -> #REF! | F23: ="intRow" & A23 & " = comExcelWorksheet.Range(""" & A23 & """).Row" -> intRowChangeJob_LocationDetails_WorkShift = comExcelWorksheet.Range("ChangeJob_LocationDetails_WorkShift").Row | G23: ="str" & A23 & " = comExcelWorksheet.Cells(intRow" & A23 & ", intColTestColumn).Value" -> strChangeJob_LocationDetails_WorkShift = comExcelWorksheet.Cells(intRowChangeJob_LocationDetails_WorkShift, intColTestColumn).Value | H23: ="Public Property Get get" & A23 & "() : get" & A23 & " = str" & A23 & " : End Property" -> Public Property Get getChangeJob_LocationDetails_WorkShift() : getChangeJob_LocationDetails_WorkShift = strChangeJob_LocationDetails_WorkShift : End Property
A24: =Test_Data!E27 -> ChangeJob_JobClassifications_AdditionalJobClassifications | B24: ="intRow" & A24 & ", " -> intRowChangeJob_JobClassifications_AdditionalJobClassifications, | C24: =B24 -> intRowChangeJob_JobClassifications_AdditionalJobClassifications, | D24: ="str" & A24 & ", " -> strChangeJob_JobClassifications_AdditionalJobClassifications, | E24: =E23 & " " & D24 -> #REF! | F24: ="intRow" & A24 & " = comExcelWorksheet.Range(""" & A24 & """).Row" -> intRowChangeJob_JobClassifications_AdditionalJobClassifications = comExcelWorksheet.Range("ChangeJob_JobClassifications_AdditionalJobClassifications").Row | G24: ="str" & A24 & " = comExcelWorksheet.Cells(intRow" & A24 & ", intColTestColumn).Value" -> strChangeJob_JobClassifications_AdditionalJobClassifications = comExcelWorksheet.Cells(intRowChangeJob_JobClassifications_AdditionalJobClassifications, intColTestColumn).Value | H24: ="Public Property Get get" & A24 & "() : get" & A24 & " = str" & A24 & " : End Property" -> Public Property Get getChangeJob_JobClassifications_AdditionalJobClassifications() : getChangeJob_JobClassifications_AdditionalJobClassifications = strChangeJob_JobClassifications_AdditionalJobClassifications : End Property
... A29: =Test_Data!E32 -> ChangeJob_JobClassifications_EndEmploymentDate | B29: ="intRow" & A29 & ", " -> intRowChangeJob_JobClassifications_EndEmploymentDate, | C29: =B29 -> intRowChangeJob_JobClassifications_EndEmploymentDate, | D29: ="str" & A29 & ", " -> strChangeJob_JobClassifications_EndEmploymentDate, | E29: =E28 & " " & D29 -> #REF! | F29: ="intRow" & A29 & " = comExcelWorksheet.Range(""" & A29 & """).Row" -> intRowChangeJob_JobClassifications_EndEmploymentDate = comExcelWorksheet.Range("ChangeJob_JobClassifications_EndEmploymentDate").Row | G29: ="str" & A29 & " = comExcelWorksheet.Cells(intRow" & A29 & ", intColTestColumn).Value" -> strChangeJob_JobClassifications_EndEmploymentDate = comExcelWorksheet.Cells(intRowChangeJob_JobClassifications_EndEmploymentDate, intColTestColumn).Value | H29: ="Public Property Get get" & A29 & "() : get" & A29 & " = str" & A29 & " : End Property" -> Public Property Get getChangeJob_JobClassifications_EndEmploymentDate() : getChangeJob_JobClassifications_EndEmploymentDate = strChangeJob_JobClassifications_EndEmploymentDate : End Property
