Workbook
Name AddDependent_AddEditID: Test_Data!#REF!
Name AddDependent_DateOfBirth: Test_Data!#REF!
Name AddDependent_EffectiveDate: Test_Data!#REF!
Name AddDependent_Gender: Test_Data!#REF!
Name AddDependent_GivenName: Test_Data!#REF!
Name AddDependent_LastName: Test_Data!#REF!
Name AddDependent_LivesWithWorker: Test_Data!#REF!
Name AddDependent_LivingWithWorkerEffectiveDate: Test_Data!#REF!
Name AddDependent_NationalIDCountry: Test_Data!#REF!
Name AddDependent_NationalIDType: Test_Data!#REF!
Name AddDependent_Relationship: Test_Data!#REF!
Name AddProbationPeriod_ProbationEndDate: Test_Data!$E$53
Name AddProbationPeriod_ProbationEndDate2: Test_Data!$F$53
Name AddProbationPeriod_ProbationEndDate2: Automation_Lookups!$AO$2:$AO$4
Name AssignPayGroup_ProposedPayGroup: Test_Data!$E$50
Name AssignPayGroup_ProposedPayGroup: Automation_Lookups!$T$2:$T$20
Name AssignPayGroup_ProposedPayGroup2: Test_Data!$F$50
Name AssignPayGroup_ProposedPayGroup2: Automation_Lookups!$T$2
Name Automation_Ref: Test_Data!$G$14:$J$14
Name AutomationComments: Test_Data!$E$11
Name ChangeMyEmergencyContacts_City: Test_Data!#REF!
Name ChangeMyEmergencyContacts_EmailAddress: Test_Data!#REF!
Name ChangeMyEmergencyContacts_FamilyName: Test_Data!#REF!
Name ChangeMyEmergencyContacts_GivenName: Test_Data!#REF!
Name ChangeMyEmergencyContacts_PhoneDevice: Test_Data!#REF!
Name ChangeMyEmergencyContacts_PhoneDevice2: Automation_Lookups!$AJ$2:$AJ$3
Name ChangeMyEmergencyContacts_PhoneNumber: Test_Data!#REF!
Name ChangeMyEmergencyContacts_PostalCode: Test_Data!#REF!
Name ChangeMyEmergencyContacts_Relationship: Test_Data!#REF!
Name ChangeMyEmergencyContacts_Relationship2: Automation_Lookups!$AI$2:$AI$5
Name ChangeMyEmergencyContacts_StreetName: Test_Data!#REF!
Name ChangeMyGovernmentIDs_NationalIDs_AddEditID: Test_Data!$E$68
Name ChangeMyGovernmentIDs_NationalIDs_AddEditID1: Test_Data!$E$65
Name ChangeMyGovernmentIDs_NationalIDs_AddEditID12: Test_Data!$F$65
Name ChangeMyGovernmentIDs_NationalIDs_AddEditID2: Test_Data!$E$68
Name ChangeMyGovernmentIDs_NationalIDs_AddEditID22: Automation_Lookups!$AL$2:$AL$4
Name ChangeMyGovernmentIDs_NationalIDs_AddEditID22: Test_Data!$F$68
Name ChangeMyGovernmentIDs_NationalIDs_AddEditID3: Test_Data!#REF!
Name ChangeMyGovernmentIDs_NationalIDs_Country1: Test_Data!$E$63
Name ChangeMyGovernmentIDs_NationalIDs_Country12: Test_Data!$F$63
Name ChangeMyGovernmentIDs_NationalIDs_Country2: Test_Data!$E$66
Name ChangeMyGovernmentIDs_NationalIDs_Country22: Test_Data!$F$66
Name ChangeMyGovernmentIDs_NationalIDs_Country3: Test_Data!#REF!
Name ChangeMyGovernmentIDs_NationalIDs_NationalIDType1: Test_Data!$E$64
Name ChangeMyGovernmentIDs_NationalIDs_NationalIDType12: Test_Data!$F$64
Name ChangeMyGovernmentIDs_NationalIDs_NationalIDType12: Automation_Lookups!$AK$2:$AK$5
Name ChangeMyGovernmentIDs_NationalIDs_NationalIDType2: Test_Data!$E$67
Name ChangeMyGovernmentIDs_NationalIDs_NationalIDType2: Automation_Lookups!$AL$2:$AL$4
Name ChangeMyGovernmentIDs_NationalIDs_NationalIDType22: Test_Data!$F$67
Name ChangeMyGovernmentIDs_NationalIDs_NationalIDType22: Automation_Lookups!$AL$2:$AL$4
Name ChangeMyGovernmentIDs_NationalIDs_NationalIDType3: Test_Data!#REF!
Name ChangeMyPersonalInformation_CitizenshipStatus: Test_Data!$E$62
Name ChangeMyPersonalInformation_CityOfBirth: Test_Data!$E$59
Name ChangeMyPersonalInformation_CityOfBirth2: Test_Data!$F$59
Name ChangeMyPersonalInformation_CountryTerritoryOfBirth: Test_Data!$E$57
Name ChangeMyPersonalInformation_CountryTerritoryOfBirth2: Test_Data!$F$57
Name ChangeMyPersonalInformation_DateOfBirth: Test_Data!$E$56
Name ChangeMyPersonalInformation_DateOfBirth2: Test_Data!$F$56
Name ChangeMyPersonalInformation_Gender: Test_Data!$E$55
Name ChangeMyPersonalInformation_Gender2: Test_Data!$F$55

Sheet Information
A1: Version | F1: Info
A6: Version | B6: 0.3 | F6: Info
F7: Dates | G7: For Czech all dates to be entered in format of DD/MM/YYYY
A8: History | F8: Unhighlighted fields | G8: Only data in unhighlighted fields can be changed.
A9: Date | B9: Version | C9: Details | F9: Red highlighted fields | G9: Indicates fields where unique data is required otherwise automation will throw errors
A10: 44061 | B10: 0.3 | C10: Initial Release | F10: Grey highlighted fields | G10: Indicates fields that cannot be changed
F11: Last Run Status / Last Run Error Message | G11: When automation has run for a particular test, we need to check the status is set to Passed and no error messages are present for each test before the automation run for that particular test is considered valid

Sheet Defects
B2: Batch 1 - Summary | E2: Batch 2 - Summary | H2: Batch 3 - Summary | K2: All E2E Cycle 1 - Summary
B3: Description | C3: Total | E3: Description | F3: Total | H3: Description | I3: Total | K3: Description | L3: Total No. | M3: %
B4: Passed | C4: 35 | E4: Passed | F4: 141 | H4: Passed | I4: 0 | K4: Passed | L4: =C4+F4+I4 -> 176 | M4: =L4/L8*100 -> 72.131148
B5: Failed | C5: 17 | E5: Failed | F5: 27 | H5: Failed | I5: 24 | K5: Failed | L5: =C5+F5+I5 -> 68 | M5: =L5/L8*100 -> 27.868852
B6: Not Run | C6: 0 | E6: Not Run | F6: 0 | H6: Not Run | I6: 0 | K6: Not Run | L6: =C6+F6+I6 -> 0 | M6: =L6/L8*100 -> 0
B7: Executed | C7: 52 | E7: Executed | F7: 168 | H7: Executed | I7: 24 | K7: Executed | L7: =C7+F7+I7 -> 244 | M7: =L7/L8*100 -> 100
B8: Total | C8: 52 | E8: Total | F8: 168 | H8: Total | I8: 24 | K8: Total | L8: =C8+F8+I8 -> 244 | M8: =M4+M5+M6 -> 100
B10: Batch 1 - Defects | E10: Batch 2 - Defects | H10: Batch 3 - Defects | K10: All E2E Cycle 1 - Defects
B11: Failed Tests Description | C11: Total | E11: Failed Tests Description | F11: Total | H11: Failed Tests Description | I11: Total | K11: Failed Tests Description | L11: Total No. | M11: %
B12: P&C Salary Assistant/Supervisor Salary Configuration missing | C12: 12 | E12: Grade Profile not populated causing salary to remain blank | F12: 24 | H12: Data issue - Rerun scheduled | I12: 24 | K12: Personal Information Change Approval Email missing after 2nd and final proxy into HR Manager | L12: 44 | M12: =L12/L17*100 -> 35.2
B13: Automation issue with Maiden Name - Gary to discuss with Shane/Andre | C13: 5 | E13: GC - Under Investigation | F13: 3 | H13: Total | I13: 24 | K13: Open button not available to assign paygroup for payroll. Approval required by David Bradley... | L13: 20 | M13: =L13/L17*100 -> 16
B14: Total | C14: =C12+C13 -> 17 | E14: Total | F14: 27 | K14: Grade Profile not populated causing salary to remain blank | L14: 34 | M14: =L14/L17*100 -> 27.2
K15: Data issue - Rerun scheduled | L15: 24 | M15: =L15/L17*100 -> 19.2
K16: GC - Under Investigation | L16: 3 | M16: =L16/L17*100 -> 2.4
K17: Total | L17: =SUM(L12:L16) -> 125 | M17: =SUM(M12:M16) -> 100

Sheet Automation_Lookups
A1: Process2 | B1: ExecutionFlag2 | C1: SupervisoryOrganisation_SupervisoryOrganisation2 | D1: LegalNameInformation_Country2 | E1: ContactInformation_Phone_CountryPhoneCode2 | F1: ContactInformation_Phone_PhoneDevice2 | G1: ContactInformation_Phone_Type2 | H1: ContactInformation_Address_Type2 | I1: ContactInformation_Email_Type2 | J1: JobDetails_HireDate2 | K1: JobDetails_Reason2 | L1: JobDetails_Position2 | M1: JobDetails_EmployeeType2 | N1: JobDetails_JobProfile2 | O1: JobDetails_TimeType2 | P1: JobDetails_Location2 | Q1: JobDetails_AdditionalInformation_WorkShift2 | R1: JobDetails_AdditionalInformation_EndEmploymentDate2 | S1: ChangeOrganizationAssignments_DepartmentSection2 | T1: AssignPayGroup_ProposedPayGroup2 | U1: Proxy_ProxyNumber2 | V1: Proxy_OnBehalfOf2 | W1: MaintainEmployeeContract_Reason2 | X1: MaintainEmployeeContract_Status2 | Y1: MaintainEmployeeContract_ContractType2 | Z1: MaintainEmployeeContract_ContractEndDate2 | AA1: ProposeCompensationHire_GradeProfile2 | AB1: ProposeCompensationHire_Step2 | AC1: EditPassportsandVisas_Country2 | AD1: EditPassportsandVisas_PassportIDType2 | AE1: EditPassportsandVisas_IdentificationNo2 | AF1: EditPassportsandVisas_IssuedDate2 | AG1: EditPassportsandVisas_ExpirationDate2 | AH1: ChangeMyPersonalInformation_MaritalStatus2 | AI1: ChangeMyEmergencyContacts_Relationship2 | AJ1: ChangeMyEmergencyContacts_PhoneDevice2 | AK1: ChangeMyGovernmentIDs_NationalIDs_NationalIDType12 | AL1: ChangeMyGovernmentIDs_NationalIDs_AddEditID22 | AM1: PaymentElectionOption_AccountType2 | AN1: SkillsAndExperience_AddEducation_School2 | AO1: AddProbationPeriod_ProbationEndDate2 | AP1: EditAdditionalData_PayrollTaxDeduction | AQ1: HealthCareProvider_MealVoucher2 | AR1: School1 | AS1: School2 | AT1: ContactInformation_Address_Province2 | AU1: ChangeMyGovernmentIDs_NationalIDs_NationalIDType12 | AV1: ChangeMyGovernmentIDs_NationalIDs_NationalIDType22 | AW1: EditAdditionalData_EstadolIRPF2 | AX1: EditAdditionalData_MinusvaliaRH2
A2: New Hire | B2: Yes | C2: 362 Recruitment (Carolina De La Barrera Crespo (375)) | D2: Czechia | E2: Czechia (+420) | F2: Mobile | G2: Home | H2: Home | I2: Home | J2: =IF(MONTH(TODAY())<10,"0"&MONTH(TODAY())&"/",MONTH(TODAY())&"/") & IF(DAY(TODAY())<10,"0"&DAY(TODAY())&"/",DAY(TODAY())&"/") & YEAR(TODAY()) -> 10/15/2024 | K2: New Hire | L2: Assistant Manager-2 | M2: Fixed Term | N2: DPP/DPC | O2: Full time | P2: 362 Algeciras | Q2: 1 Day | R2: =IF(MONTH(TODAY())<10,"0"&MONTH(TODAY())&"/",MONTH(TODAY())&"/") & IF(DAY(TODAY())<10,"0"&DAY(TODAY())&"/",DAY(TODAY())&"/") & YEAR(TODAY()) -> 10/15/2024 | S2: Accessories | T2: Please select a Spanish Pay Group | U2: 10223439 | V2: Iwona Chrostowska (10223439) | W2: for the purposes of performing any work of casual or seasonal nature | X2: 1st Fixed Term Contract | Y2: Employment Agreement | Z2: =IF(MONTH(TODAY())<10,"0"&MONTH(TODAY())&"/",MONTH(TODAY())&"/") & IF(DAY(TODAY())<10,"0"&DAY(TODAY())&"/",DAY(TODAY())&"/") & YEAR(TODAY()) -> 10/15/2024 | AA2: Defaulted | AB2: Defaulted | AH2: Single | AI2: Father | AJ2: Mobile/Cell | AK2: Social Security Number (NSS) | AL2: Social Security Number (NSS) | AM2: Savings | AN2: N/A | AO2: =IF(MONTH(TODAY()+100)<10,"0"&MONTH(TODAY()+100)&"/",MONTH(TODAY()+100)&"/") & IF(DAY(TODAY()+100)<10,"0"&DAY(TODAY()+100)&"/",DAY(TODAY()+100)&"/") & YEAR(TODAY()+100) -> 01/23/2025 | AP2: Yes | AQ2: Yes | AR2: Střední bez maturity či výučního listu | AS2: stredni bez maturity ci vyucniho listu | AT2: Madrid | AU2: Social Security Number (NSS) | AV2: ID Card (DNI) Number | AW2: Soltero/a, viudo/a, divorciado/a o separado/a legalmente con hijos solteros menores de 18 años o incapacitados judicialmente que conviven exclusivamente con Vd., sin convivir también con el otro progenitor Soltero/a, viudo/a, divorciado/a o separado/a legalmente con hijos solteros menores de 18 años o incapacitados judicialmente que conviven exclusivamente con Vd., sin convivir también con el otro progenitor | AX2: Del 33% hasta el 65%
A3: New Role & New Hire | B3: No | C3: 895 Store Management (Male Teststmanager (10224969)) | D3: Czechia | E3: Czechia (+420) | F3: Landline | G3: Work | H3: Work | I3: Work | J3: =IF(MONTH(TODAY()-10)<10,"0"&MONTH(TODAY()-10)&"/",MONTH(TODAY()-10))&"/" & IF(DAY(TODAY()-10)<10,"0"&DAY(TODAY()-10)&"/",DAY(TODAY()-10)&"/") & YEAR(TODAY()-10) -> 10/05/2024 | L3: Assistant Manager-3 | M3: Intern | N3: Retail Assistant | O3: Part time | Q3: 2 Days | R3: =IF(MONTH(TODAY()+100)<10,"0"&MONTH(TODAY()+100)&"/",MONTH(TODAY()+100)&"/") & IF(DAY(TODAY()+100)<10,"0"&DAY(TODAY()+100)&"/",DAY(TODAY()+100)&"/") & YEAR(TODAY()+100) -> 01/23/2025 | T3: ES Monthly - 15 payments | U3: 10225553 | V3: Kocour Mikeš (10225553) | W3: for the purposes of performing work during the term of office | X3: 2nd Fixed Term Contract | Y3: Agreement to perform work | Z3: =IF(MONTH(TODAY()+100)<10,"0"&MONTH(TODAY()+100)&"/",MONTH(TODAY()+100)&"/") & IF(DAY(TODAY()+100)<10,"0"&DAY(TODAY()+100)&"/",DAY(TODAY()+100)&"/") & YEAR(TODAY()+100) -> 01/23/2025 | AH3: Married | AI3: Mother | AJ3: Telephone - Landline | AK3: ID Card (DNI) Number | AL3: ID Card (DNI) Number | AM3: Checking | AN3: Vseobecne stredni s maturitou | AO3: =IF(MONTH(TODAY()+1000)<10,"0"&MONTH(TODAY()+1000)&"/",MONTH(TODAY()+1000)&"/") & IF(DAY(TODAY()+1000)<10,"0"&DAY(TODAY()+1000)&"/",DAY(TODAY()+1000)&"/") & YEAR(TODAY()+1000) -> 07/12/2027 | AP3: No | AQ3: No | AR3: Střední odborné vzdělání s výučním listem | AS3: stredni odborne vzdelani s vyucnim listem
D4: Poland | E4: Poland (+48) | J4: =IF(MONTH(TODAY()+10)<10,"0"&MONTH(TODAY()+10)&"/",MONTH(TODAY()+10)&"/") & IF(DAY(TODAY()+10)<10,"0"&DAY(TODAY()+10)&"/",DAY(TODAY()+10)&"/") & YEAR(TODAY()+10) -> 10/25/2024 | L4: Test Store Manager-2 | M4: Permanent | N4: Department Manager | Q4: 3 Days | R4: =IF(MONTH(TODAY()+1000)<10,"0"&MONTH(TODAY()+1000)&"/",MONTH(TODAY()+1000)&"/") & IF(DAY(TODAY()+1000)<10,"0"&DAY(TODAY()+1000)&"/",DAY(TODAY()+1000)&"/") & YEAR(TODAY()+1000) -> 07/12/2027 | W4: for the purposes of substituting an employee during his/her excused absence at work | X4: 3rd Fixed Term Contract | Y4: Agreement to complete a job | Z4: =IF(MONTH(TODAY()+1000)<10,"0"&MONTH(TODAY()+1000)&"/",MONTH(TODAY()+1000)&"/") & IF(DAY(TODAY()+1000)<10,"0"&DAY(TODAY()+1000)&"/",DAY(TODAY()+1000)&"/") & YEAR(TODAY()+1000) -> 07/12/2027 | AH4: Not Disclosed | AI4: Spouse | AK4: Alien Identification Number (NIE) | AL4: Alien Identification Number (NIE) | AO4: N/A | AR4: Všeobecné střední s maturitou | AS4: vseobecne stredni s maturitou
D5: Poland | E5: Poland (+48) | L5: N/A | M5: Students | N5: Senior Department Manager | Q5: 4 Days | R5: N/A | W5: No reason necessary | X5: Active | Z5: N/A | AI5: Partner | AK5: Tax Identification Number (NIF) | AR5: Vysokoškolské Bc. | AS5: Vysokoskolske Bc
N6: Supervisor | Q6: 5 Days | X6: Inactive | AR6: Vysokoškolské MUDr., JUDr., Mgr., MgA., Ing. | AS6: vysokoskolske MUDR., JUDr., Mgr., MgA., Ing.
N7: P&C Supervisor | AR7: Vysokoškolské PhDr, PhD, JUDr, MUDr | AS7: vysokoskolske PhDr, PhD, JUDr, MUDr
N8: P&C Assistant | AR8: vyšší odborné DiS | AS8: vyssi odborne DiS
N9: Trainee Manager | AR9: Základní | AS9: Zakladni
N10: Assistant Manager
N11: P&C Manager
N12: Store Manager
N13: Visual Merchandiser Manager
N14: Visual Merchandising Supervisor
N15: Visual Merchandising Assistant
K21: Rehire | U21: 8701839 | V21: Lisanne Kluinhaar (8701839) | W21: Defined contract end date (Determined) | AQ21: Netherlands Retail Assistant
C22: 701 Recruitment (Lisanne Kluinhaar (8701839)) | D22: Netherlands | E22: Netherlands (+31) | K22: Seasonal | W22: Undefined contract end date (Undetermined) | Y22: Part-time( PT ) | AQ22: Netherlands Retail Assistant Cash Office | AR22: Retail Assistant (18)
W23: Intern | Y23: Full-time( FT. ) | AR23: Retail Assistant (19)
C24: Retail - Central & Eastern Europe (Stephen Regan (9910010) (Inherited) | D24: Poland | E24: Poland (+48) | AR24: Retail Assistant (20)
C25: Retail Poland Area: Central Poland (Stephen Regan (9910010) (Inherited)) | D25: Poland | E25: Poland (+48) | AR25: Retail Assistant (21)
AR26: Retail Assistant (22)
AR27: Retail Assistant (23+)
AR28: Retail Assistant (Under 18)

Sheet RC. No
A1: D.O.B | B1: 35139 | C1: 33054 | D1: 31390 | F1: r col b | G1: r col c | H1: r col d
B2: 9603150007 | C2: 9006300006 | D2: 8512090004 | F2: =B2/11 -> 873013637 | G2: =C2/11 -> 818754546 | H2: =D2/11 -> 773826364
B3: =B2+11 -> 9603150018 | C3: =C2+11 -> 9006300017 | D3: =D2+11 -> 8512090015 | F3: =B3/11 -> 873013638 | G3: =C3/11 -> 818754547 | H3: =D3/11 -> 773826365
B4: =B3+11 -> 9603150029 | C4: =C3+11 -> 9006300028 | D4: =D3+11 -> 8512090026 | F4: =B4/11 -> 873013639 | G4: =C4/11 -> 818754548 | H4: =D4/11 -> 773826366
B5: =B4+11 -> 9603150040 | C5: =C4+11 -> 9006300039 | D5: =D4+11 -> 8512090037 | F5: =B5/11 -> 873013640 | G5: =C5/11 -> 818754549 | H5: =D5/11 -> 773826367
B6: =B5+11 -> 9603150051 | C6: =C5+11 -> 9006300050 | D6: =D5+11 -> 8512090048 | F6: =B6/11 -> 873013641 | G6: =C6/11 -> 818754550 | H6: =D6/11 -> 773826368
B7: =B6+11 -> 9603150062 | C7: =C6+11 -> 9006300061 | D7: =D6+11 -> 8512090059 | F7: =B7/11 -> 873013642 | G7: =C7/11 -> 818754551 | H7: =D7/11 -> 773826369
B8: =B7+11 -> 9603150073 | C8: =C7+11 -> 9006300072 | D8: =D7+11 -> 8512090070 | F8: =B8/11 -> 873013643 | G8: =C8/11 -> 818754552 | H8: =D8/11 -> 773826370
B9: =B8+11 -> 9603150084 | C9: =C8+11 -> 9006300083 | D9: =D8+11 -> 8512090081 | F9: =B9/11 -> 873013644 | G9: =C9/11 -> 818754553 | H9: =D9/11 -> 773826371
B10: =B9+11 -> 9603150095 | C10: =C9+11 -> 9006300094 | D10: =D9+11 -> 8512090092 | F10: =B10/11 -> 873013645 | G10: =C10/11 -> 818754554 | H10: =D10/11 -> 773826372
B11: =B10+11 -> 9603150106 | C11: =C10+11 -> 9006300105 | D11: =D10+11 -> 8512090103 | F11: =B11/11 -> 873013646 | G11: =C11/11 -> 818754555 | H11: =D11/11 -> 773826373
B12: =B11+11 -> 9603150117 | C12: =C11+11 -> 9006300116 | D12: =D11+11 -> 8512090114 | F12: =B12/11 -> 873013647 | G12: =C12/11 -> 818754556 | H12: =D12/11 -> 773826374
B13: =B12+11 -> 9603150128 | C13: =C12+11 -> 9006300127 | D13: =D12+11 -> 8512090125 | F13: =B13/11 -> 873013648 | G13: =C13/11 -> 818754557 | H13: =D13/11 -> 773826375
B14: =B13+11 -> 9603150139 | C14: =C13+11 -> 9006300138 | D14: =D13+11 -> 8512090136 | F14: =B14/11 -> 873013649 | G14: =C14/11 -> 818754558 | H14: =D14/11 -> 773826376
... B28: =B27+11 -> 9603150293 | C28: =C27+11 -> 9006300292 | D28: =D27+11 -> 8512090290 | F28: =B28/11 -> 873013663 | G28: =C28/11 -> 818754572 | H28: =D28/11 -> 773826390
B29: =B28+11 -> 9603150304
B30: =B29+11 -> 9603150315
B31: =B30+11 -> 9603150326
B32: =B31+11 -> 9603150337
B33: =B32+11 -> 9603150348
B34: =B33+11 -> 9603150359
B35: =B34+11 -> 9603150370
B36: =B35+11 -> 9603150381
B37: =B36+11 -> 9603150392
B38: =B37+11 -> 9603150403
B39: =B38+11 -> 9603150414
B40: =B39+11 -> 9603150425
... B75: =B74+11 -> 9603150810
B76: =B75+11 -> 9603150821 | X76: New RC Numbers
B77: =B76+11 -> 9603150832 | X77: 9202101337
B78: =B77+11 -> 9603150843 | X78: =SUM(X77)+11 -> 9202101348
B79: =B78+11 -> 9603150854 | X79: =SUM(X78)+11 -> 9202101359
B80: =B79+11 -> 9603150865 | X80: =SUM(X79)+11 -> 9202101370
B81: =B80+11 -> 9603150876 | X81: =SUM(X80)+11 -> 9202101381
B82: =B81+11 -> 9603150887 | X82: =SUM(X81)+11 -> 9202101392
B83: =B82+11 -> 9603150898 | X83: =SUM(X82)+11 -> 9202101403
B84: =B83+11 -> 9603150909 | X84: =SUM(X83)+11 -> 9202101414
B85: =B84+11 -> 9603150920 | X85: =SUM(X84)+11 -> 9202101425
B86: =B85+11 -> 9603150931 | D86: 9603170269 | X86: =SUM(X85)+11 -> 9202101436
D87: =D86+11 -> 9603170280 | F87: 9603170280 | H87: 9603170280 | I87: 9603170291 | J87: 9603170302 | K87: 9603170313 | L87: 9603170324 | M87: 9603170335 | N87: 9603170346 | O87: 9603170357 | P87: 9603170368 | Q87: 9603170379 | R87: 9603170390 | S87: 9603170401 | T87: 9603170412 | X87: =SUM(X86)+11 -> 9202101447
...

Sheet Code_11122019_1000
B1: Variable Row | C1: Variable Row Combined | D1: Variable Value | E1: Variable Value Combined | F1: Row Number Declaration --------------------------------- intRowProcess = comExcelWorksheet.Range("Process").Row | G1: Value Declaration ------------------------ strProcess = comExcelWorksheet.Cells(intRowProcess, intColTestColumn).Value | H1: Getters
A2: =Test_Data!D3 -> Process | B2: ="intRow" & A2 & ", " -> intRowProcess, | C2: =B2 -> intRowProcess, | D2: ="str" & A2 & ", " -> strProcess, | E2: =D2 -> strProcess, | F2: ="intRow" & A2 & " = comExcelWorksheet.Range(""" & A2 & """).Row" -> intRowProcess = comExcelWorksheet.Range("Process").Row | G2: ="str" & A2 & " = comExcelWorksheet.Cells(intRow" & A2 & ", intColTestColumn).Value" -> strProcess = comExcelWorksheet.Cells(intRowProcess, intColTestColumn).Value | H2: ="Public Property Get get" & A2 & "() : get" & A2 & " = str" & A2 & " : End Property" -> Public Property Get getProcess() : getProcess = strProcess : End Property
A3: =Test_Data!D4 -> ExecutionFlag | B3: ="intRow" & A3 & ", " -> intRowExecutionFlag, | C3: =C2 &B3 -> intRowProcess, intRowExecutionFlag, | D3: ="str" & A3 & ", " -> strExecutionFlag, | E3: =E2 &D3 -> strProcess, strExecutionFlag, | F3: ="intRow" & A3 & " = comExcelWorksheet.Range(""" & A3 & """).Row" -> intRowExecutionFlag = comExcelWorksheet.Range("ExecutionFlag").Row | G3: ="str" & A3 & " = comExcelWorksheet.Cells(intRow" & A3 & ", intColTestColumn).Value" -> strExecutionFlag = comExcelWorksheet.Cells(intRowExecutionFlag, intColTestColumn).Value | H3: ="Public Property Get get" & A3 & "() : get" & A3 & " = str" & A3 & " : End Property" -> Public Property Get getExecutionFlag() : getExecutionFlag = strExecutionFlag : End Property
A4: =Test_Data!D7 -> LastRunTimeandStatus | B4: ="intRow" & A4 & ", " -> intRowLastRunTimeandStatus, | C4: =C3 &B4 -> intRowProcess, intRowExecutionFlag, intRowLastRunTimeandStatus, | D4: ="str" & A4 & ", " -> strLastRunTimeandStatus, | E4: =E3 &D4 -> strProcess, strExecutionFlag, strLastRunTimeandStatus, | F4: ="intRow" & A4 & " = comExcelWorksheet.Range(""" & A4 & """).Row" -> intRowLastRunTimeandStatus = comExcelWorksheet.Range("LastRunTimeandStatus").Row | G4: ="str" & A4 & " = comExcelWorksheet.Cells(intRow" & A4 & ", intColTestColumn).Value" -> strLastRunTimeandStatus = comExcelWorksheet.Cells(intRowLastRunTimeandStatus, intColTestColumn).Value | H4: ="Public Property Get get" & A4 & "() : get" & A4 & " = str" & A4 & " : End Property" -> Public Property Get getLastRunTimeandStatus() : getLastRunTimeandStatus = strLastRunTimeandStatus : End Property
A5: =Test_Data!D8 -> LastRunEmployeeNo | B5: ="intRow" & A5 & ", " -> intRowLastRunEmployeeNo, | C5: =C4 &B5 -> intRowProcess, intRowExecutionFlag, intRowLastRunTimeandStatus, intRowLastRunEmployeeNo, | D5: ="str" & A5 & ", " -> strLastRunEmployeeNo, | E5: =E4 &D5 -> strProcess, strExecutionFlag, strLastRunTimeandStatus, strLastRunEmployeeNo, | F5: ="intRow" & A5 & " = comExcelWorksheet.Range(""" & A5 & """).Row" -> intRowLastRunEmployeeNo = comExcelWorksheet.Range("LastRunEmployeeNo").Row | G5: ="str" & A5 & " = comExcelWorksheet.Cells(intRow" & A5 & ", intColTestColumn).Value" -> strLastRunEmployeeNo = comExcelWorksheet.Cells(intRowLastRunEmployeeNo, intColTestColumn).Value | H5: ="Public Property Get get" & A5 & "() : get" & A5 & " = str" & A5 & " : End Property" -> Public Property Get getLastRunEmployeeNo() : getLastRunEmployeeNo = strLastRunEmployeeNo : End Property
A6: =Test_Data!D9 -> LastRunErrorMessage | B6: ="intRow" & A6 & ", " -> intRowLastRunErrorMessage, | C6: =C5 &B6 -> intRowProcess, intRowExecutionFlag, intRowLastRunTimeandStatus, intRowLastRunEmployeeNo, intRowLastRunErrorMessage, | D6: ="str" & A6 & ", " -> strLastRunErrorMessage, | E6: =E5 &D6 -> strProcess, strExecutionFlag, strLastRunTimeandStatus, strLastRunEmployeeNo, strLastRunErrorMessage, | F6: ="intRow" & A6 & " = comExcelWorksheet.Range(""" & A6 & """).Row" -> intRowLastRunErrorMessage = comExcelWorksheet.Range("LastRunErrorMessage").Row | G6: ="str" & A6 & " = comExcelWorksheet.Cells(intRow" & A6 & ", intColTestColumn).Value" -> strLastRunErrorMessage = comExcelWorksheet.Cells(intRowLastRunErrorMessage, intColTestColumn).Value | H6: ="Public Property Get get" & A6 & "() : get" & A6 & " = str" & A6 & " : End Property" -> Public Property Get getLastRunErrorMessage() : getLastRunErrorMessage = strLastRunErrorMessage : End Property
A7: =Test_Data!D10 -> DefectDescription | B7: ="intRow" & A7 & ", " -> intRowDefectDescription, | C7: =C6 &B7 -> intRowProcess, intRowExecutionFlag, intRowLastRunTimeandStatus, intRowLastRunEmployeeNo, intRowLastRunErrorMessage, intRowDefectDescription, | D7: ="str" & A7 & ", " -> strDefectDescription, | E7: =E6 &D7 -> strProcess, strExecutionFlag, strLastRunTimeandStatus, strLastRunEmployeeNo, strLastRunErrorMessage, strDefectDescription, | F7: ="intRow" & A7 & " = comExcelWorksheet.Range(""" & A7 & """).Row" -> intRowDefectDescription = comExcelWorksheet.Range("DefectDescription").Row | G7: ="str" & A7 & " = comExcelWorksheet.Cells(intRow" & A7 & ", intColTestColumn).Value" -> strDefectDescription = comExcelWorksheet.Cells(intRowDefectDescription, intColTestColumn).Value | H7: ="Public Property Get get" & A7 & "() : get" & A7 & " = str" & A7 & " : End Property" -> Public Property Get getDefectDescription() : getDefectDescription = strDefectDescription : End Property
A8: =Test_Data!D11 -> AutomationComments | B8: ="intRow" & A8 & ", " -> intRowAutomationComments, | C8: =C7 &B8 -> intRowProcess, intRowExecutionFlag, intRowLastRunTimeandStatus, intRowLastRunEmployeeNo, intRowLastRunErrorMessage, intRowDefectDescription, intRowAutomationComments, | D8: ="str" & A8 & ", " -> strAutomationComments, | E8: =E7 &D8 -> strProcess, strExecutionFlag, strLastRunTimeandStatus, strLastRunEmployeeNo, strLastRunErrorMessage, strDefectDescription, strAutomationComments, | F8: ="intRow" & A8 & " = comExcelWorksheet.Range(""" & A8 & """).Row" -> intRowAutomationComments = comExcelWorksheet.Range("AutomationComments").Row | G8: ="str" & A8 & " = comExcelWorksheet.Cells(intRow" & A8 & ", intColTestColumn).Value" -> strAutomationComments = comExcelWorksheet.Cells(intRowAutomationComments, intColTestColumn).Value | H8: ="Public Property Get get" & A8 & "() : get" & A8 & " = str" & A8 & " : End Property" -> Public Property Get getAutomationComments() : getAutomationComments = strAutomationComments : End Property
A9: =Test_Data!D12 -> QAComments | B9: ="intRow" & A9 & ", " -> intRowQAComments, | C9: =C8 &B9 -> intRowProcess, intRowExecutionFlag, intRowLastRunTimeandStatus, intRowLastRunEmployeeNo, intRowLastRunErrorMessage, intRowDefectDescription, intRowAutomationComments, intRowQAComments, | D9: ="str" & A9 & ", " -> strQAComments, | E9: =E8 &D9 -> strProcess, strExecutionFlag, strLastRunTimeandStatus, strLastRunEmployeeNo, strLastRunErrorMessage, strDefectDescription, strAutomationComments, strQAComments, | F9: ="intRow" & A9 & " = comExcelWorksheet.Range(""" & A9 & """).Row" -> intRowQAComments = comExcelWorksheet.Range("QAComments").Row | G9: ="str" & A9 & " = comExcelWorksheet.Cells(intRow" & A9 & ", intColTestColumn).Value" -> strQAComments = comExcelWorksheet.Cells(intRowQAComments, intColTestColumn).Value | H9: ="Public Property Get get" & A9 & "() : get" & A9 & " = str" & A9 & " : End Property" -> Public Property Get getQAComments() : getQAComments = strQAComments : End Property
A10: =Test_Data!D13 -> 0 | B10: ="intRow" & A10 & ", " -> intRow0, | C10: =C9 &B10 -> intRowProcess, intRowExecutionFlag, intRowLastRunTimeandStatus, intRowLastRunEmployeeNo, intRowLastRunErrorMessage, intRowDefectDescription, intRowAutomationComments, intRowQAComments, intRow0, | D10: ="str" & A10 & ", " -> str0, | E10: =E9 &D10 -> strProcess, strExecutionFlag, strLastRunTimeandStatus, strLastRunEmployeeNo, strLastRunErrorMessage, strDefectDescription, strAutomationComments, strQAComments, str0, | F10: ="intRow" & A10 & " = comExcelWorksheet.Range(""" & A10 & """).Row" -> intRow0 = comExcelWorksheet.Range("0").Row | G10: ="str" & A10 & " = comExcelWorksheet.Cells(intRow" & A10 & ", intColTestColumn).Value" -> str0 = comExcelWorksheet.Cells(intRow0, intColTestColumn).Value | H10: ="Public Property Get get" & A10 & "() : get" & A10 & " = str" & A10 & " : End Property" -> Public Property Get get0() : get0 = str0 : End Property
A11: =Test_Data!D14 -> Automation Ref | B11: ="intRow" & A11 & ", " -> intRowAutomation Ref, | C11: =C10 &B11 -> intRowProcess, intRowExecutionFlag, intRowLastRunTimeandStatus, intRowLastRunEmployeeNo, intRowLastRunErrorMessage, intRowDefectDescription, intRowAutomationComments, intRowQAComments, intRow0, intRowAutomation Ref, | D11: ="str" & A11 & ", " -> strAutomation Ref, | E11: =E10 &D11 -> strProcess, strExecutionFlag, strLastRunTimeandStatus, strLastRunEmployeeNo, strLastRunErrorMessage, strDefectDescription, strAutomationComments, strQAComments, str0, strAutomation Ref, | F11: ="intRow" & A11 & " = comExcelWorksheet.Range(""" & A11 & """).Row" -> intRowAutomation Ref = comExcelWorksheet.Range("Automation Ref").Row | G11: ="str" & A11 & " = comExcelWorksheet.Cells(intRow" & A11 & ", intColTestColumn).Value" -> strAutomation Ref = comExcelWorksheet.Cells(intRowAutomation Ref, intColTestColumn).Value | H11: ="Public Property Get get" & A11 & "() : get" & A11 & " = str" & A11 & " : End Property" -> Public Property Get getAutomation Ref() : getAutomation Ref = strAutomation Ref : End Property
A12: =Test_Data!D15 -> Login_Username | B12: ="intRow" & A12 & ", " -> intRowLogin_Username, | C12: =C11 &B12 -> intRowProcess, intRowExecutionFlag, intRowLastRunTimeandStatus, intRowLastRunEmployeeNo, intRowLastRunErrorMessage, intRowDefectDescription, intRowAutomationComments, intRowQAComments, intRow0, intRowAutomation Ref, intRowLogin_Username, | D12: ="str" & A12 & ", " -> strLogin_Username, | E12: =E11 &D12 -> strProcess, strExecutionFlag, strLastRunTimeandStatus, strLastRunEmployeeNo, strLastRunErrorMessage, strDefectDescription, strAutomationComments, strQAComments, str0, strAutomation Ref, strLogin_Username, | F12: ="intRow" & A12 & " = comExcelWorksheet.Range(""" & A12 & """).Row" -> intRowLogin_Username = comExcelWorksheet.Range("Login_Username").Row | G12: ="str" & A12 & " = comExcelWorksheet.Cells(intRow" & A12 & ", intColTestColumn).Value" -> strLogin_Username = comExcelWorksheet.Cells(intRowLogin_Username, intColTestColumn).Value | H12: ="Public Property Get get" & A12 & "() : get" & A12 & " = str" & A12 & " : End Property" -> Public Property Get getLogin_Username() : getLogin_Username = strLogin_Username : End Property
A13: =Test_Data!D16 -> Login_Password | B13: ="intRow" & A13 & ", " -> intRowLogin_Password, | C13: =C12 &B13 -> intRowProcess, intRowExecutionFlag, intRowLastRunTimeandStatus, intRowLastRunEmployeeNo, intRowLastRunErrorMessage, intRowDefectDescription, intRowAutomationComments, intRowQAComments, intRow0, intRowAutomation Ref, intRowLogin_Username, intRowLogin_Password, | D13: ="str" & A13 & ", " -> strLogin_Password, | E13: =E12 &D13 -> strProcess, strExecutionFlag, strLastRunTimeandStatus, strLastRunEmployeeNo, strLastRunErrorMessage, strDefectDescription, strAutomationComments, strQAComments, str0, strAutomation Ref, strLogin_Username, strLogin_Password, | F13: ="intRow" & A13 & " = comExcelWorksheet.Range(""" & A13 & """).Row" -> intRowLogin_Password = comExcelWorksheet.Range("Login_Password").Row | G13: ="str" & A13 & " = comExcelWorksheet.Cells(intRow" & A13 & ", intColTestColumn).Value" -> strLogin_Password = comExcelWorksheet.Cells(intRowLogin_Password, intColTestColumn).Value | H13: ="Public Property Get get" & A13 & "() : get" & A13 & " = str" & A13 & " : End Property" -> Public Property Get getLogin_Password() : getLogin_Password = strLogin_Password : End Property
A14: =Test_Data!D17 -> SupervisoryOrganisation_SupervisoryOrganisation | B14: ="intRow" & A14 & ", " -> intRowSupervisoryOrganisation_SupervisoryOrganisation, | C14: =C13 &B14 -> intRowProcess, intRowExecutionFlag, intRowLastRunTimeandStatus, intRowLastRunEmployeeNo, intRowLastRunErrorMessage, intRowDefectDescription, intRowAutomationComments, intRowQAComments, intRow0, intRowAutomation Ref, intRowLogin_Username, intRowLogin_Password, intRowSupervisoryOrganisation_SupervisoryOrganisation, | D14: ="str" & A14 & ", " -> strSupervisoryOrganisation_SupervisoryOrganisation, | E14: =E13 &D14 -> strProcess, strExecutionFlag, strLastRunTimeandStatus, strLastRunEmployeeNo, strLastRunErrorMessage, strDefectDescription, strAutomationComments, strQAComments, str0, strAutomation Ref, strLogin_Username, strLogin_Password, strSupervisoryOrganisation_SupervisoryOrganisation, | F14: ="intRow" & A14 & " = comExcelWorksheet.Range(""" & A14 & """).Row" -> intRowSupervisoryOrganisation_SupervisoryOrganisation = comExcelWorksheet.Range("SupervisoryOrganisation_SupervisoryOrganisation").Row | G14: ="str" & A14 & " = comExcelWorksheet.Cells(intRow" & A14 & ", intColTestColumn).Value" -> strSupervisoryOrganisation_SupervisoryOrganisation = comExcelWorksheet.Cells(intRowSupervisoryOrganisation_SupervisoryOrganisation, intColTestColumn).Value | H14: ="Public Property Get get" & A14 & "() : get" & A14 & " = str" & A14 & " : End Property" -> Public Property Get getSupervisoryOrganisation_SupervisoryOrganisation() : getSupervisoryOrganisation_SupervisoryOrganisation = strSupervisoryOrganisation_SupervisoryOrganisation : End Property
A15: =Test_Data!#REF! -> #REF! | B15: ="intRow" & A15 & ", " -> #REF! | C15: =C14 &B15 -> #REF! | D15: ="str" & A15 & ", " -> #REF! | E15: =E14 &D15 -> #REF! | F15: ="intRow" & A15 & " = comExcelWorksheet.Range(""" & A15 & """).Row" -> #REF! | G15: ="str" & A15 & " = comExcelWorksheet.Cells(intRow" & A15 & ", intColTestColumn).Value" -> #REF! | H15: ="Public Property Get get" & A15 & "() : get" & A15 & " = str" & A15 & " : End Property" -> #REF!
A16: =Test_Data!D18 -> LegalNameInformation_GivenName | B16: ="intRow" & A16 & ", " -> intRowLegalNameInformation_GivenName, | C16: =C15 &B16 -> #REF! | D16: ="str" & A16 & ", " -> strLegalNameInformation_GivenName, | E16: =E15 &D16 -> #REF! | F16: ="intRow" & A16 & " = comExcelWorksheet.Range(""" & A16 & """).Row" -> intRowLegalNameInformation_GivenName = comExcelWorksheet.Range("LegalNameInformation_GivenName").Row | G16: ="str" & A16 & " = comExcelWorksheet.Cells(intRow" & A16 & ", intColTestColumn).Value" -> strLegalNameInformation_GivenName = comExcelWorksheet.Cells(intRowLegalNameInformation_GivenName, intColTestColumn).Value | H16: ="Public Property Get get" & A16 & "() : get" & A16 & " = str" & A16 & " : End Property" -> Public Property Get getLegalNameInformation_GivenName() : getLegalNameInformation_GivenName = strLegalNameInformation_GivenName : End Property
A17: =Test_Data!#REF! -> #REF! | B17: ="intRow" & A17 & ", " -> #REF! | C17: =C16 &B17 -> #REF! | D17: ="str" & A17 & ", " -> #REF! | E17: =E16 &D17 -> #REF! | F17: ="intRow" & A17 & " = comExcelWorksheet.Range(""" & A17 & """).Row" -> #REF! | G17: ="str" & A17 & " = comExcelWorksheet.Cells(intRow" & A17 & ", intColTestColumn).Value" -> #REF! | H17: ="Public Property Get get" & A17 & "() : get" & A17 & " = str" & A17 & " : End Property" -> #REF!
A18: =Test_Data!D19 -> LegalNameInformation_FirstLastName | B18: ="intRow" & A18 & ", " -> intRowLegalNameInformation_FirstLastName, | C18: =C17 &B18 -> #REF! | D18: ="str" & A18 & ", " -> strLegalNameInformation_FirstLastName, | E18: =E17 &D18 -> #REF! | F18: ="intRow" & A18 & " = comExcelWorksheet.Range(""" & A18 & """).Row" -> intRowLegalNameInformation_FirstLastName = comExcelWorksheet.Range("LegalNameInformation_FirstLastName").Row | G18: ="str" & A18 & " = comExcelWorksheet.Cells(intRow" & A18 & ", intColTestColumn).Value" -> strLegalNameInformation_FirstLastName = comExcelWorksheet.Cells(intRowLegalNameInformation_FirstLastName, intColTestColumn).Value | H18: ="Public Property Get get" & A18 & "() : get" & A18 & " = str" & A18 & " : End Property" -> Public Property Get getLegalNameInformation_FirstLastName() : getLegalNameInformation_FirstLastName = strLegalNameInformation_FirstLastName : End Property
A19: =Test_Data!#REF! -> #REF! | B19: ="intRow" & A19 & ", " -> #REF! | C19: =C18 &B19 -> #REF! | D19: ="str" & A19 & ", " -> #REF! | E19: =E18 &D19 -> #REF! | F19: ="intRow" & A19 & " = comExcelWorksheet.Range(""" & A19 & """).Row" -> #REF! | G19: ="str" & A19 & " = comExcelWorksheet.Cells(intRow" & A19 & ", intColTestColumn).Value" -> #REF! | H19: ="Public Property Get get" & A19 & "() : get" & A19 & " = str" & A19 & " : End Property" -> #REF!
A20: =Test_Data!D22 -> ContactInformation_Phone_PhoneNumber | B20: ="intRow" & A20 & ", " -> intRowContactInformation_Phone_PhoneNumber, | C20: =C19 &B20 -> #REF! | D20: ="str" & A20 & ", " -> strContactInformation_Phone_PhoneNumber, | E20: =E19 &D20 -> #REF! | F20: ="intRow" & A20 & " = comExcelWorksheet.Range(""" & A20 & """).Row" -> intRowContactInformation_Phone_PhoneNumber = comExcelWorksheet.Range("ContactInformation_Phone_PhoneNumber").Row | G20: ="str" & A20 & " = comExcelWorksheet.Cells(intRow" & A20 & ", intColTestColumn).Value" -> strContactInformation_Phone_PhoneNumber = comExcelWorksheet.Cells(intRowContactInformation_Phone_PhoneNumber, intColTestColumn).Value | H20: ="Public Property Get get" & A20 & "() : get" & A20 & " = str" & A20 & " : End Property" -> Public Property Get getContactInformation_Phone_PhoneNumber() : getContactInformation_Phone_PhoneNumber = strContactInformation_Phone_PhoneNumber : End Property
A21: =Test_Data!D23 -> ContactInformation_Phone_PhoneDevice | B21: ="intRow" & A21 & ", " -> intRowContactInformation_Phone_PhoneDevice, | C21: =C20 &B21 -> #REF! | D21: ="str" & A21 & ", " -> strContactInformation_Phone_PhoneDevice, | E21: =E20 &D21 -> #REF! | F21: ="intRow" & A21 & " = comExcelWorksheet.Range(""" & A21 & """).Row" -> intRowContactInformation_Phone_PhoneDevice = comExcelWorksheet.Range("ContactInformation_Phone_PhoneDevice").Row | G21: ="str" & A21 & " = comExcelWorksheet.Cells(intRow" & A21 & ", intColTestColumn).Value" -> strContactInformation_Phone_PhoneDevice = comExcelWorksheet.Cells(intRowContactInformation_Phone_PhoneDevice, intColTestColumn).Value | H21: ="Public Property Get get" & A21 & "() : get" & A21 & " = str" & A21 & " : End Property" -> Public Property Get getContactInformation_Phone_PhoneDevice() : getContactInformation_Phone_PhoneDevice = strContactInformation_Phone_PhoneDevice : End Property
A22: =Test_Data!D24 -> ContactInformation_Phone_Type | B22: ="intRow" & A22 & ", " -> intRowContactInformation_Phone_Type, | C22: =C21 &B22 -> #REF! | D22: ="str" & A22 & ", " -> strContactInformation_Phone_Type, | E22: =E21 &D22 -> #REF! | F22: ="intRow" & A22 & " = comExcelWorksheet.Range(""" & A22 & """).Row" -> intRowContactInformation_Phone_Type = comExcelWorksheet.Range("ContactInformation_Phone_Type").Row | G22: ="str" & A22 & " = comExcelWorksheet.Cells(intRow" & A22 & ", intColTestColumn).Value" -> strContactInformation_Phone_Type = comExcelWorksheet.Cells(intRowContactInformation_Phone_Type, intColTestColumn).Value | H22: ="Public Property Get get" & A22 & "() : get" & A22 & " = str" & A22 & " : End Property" -> Public Property Get getContactInformation_Phone_Type() : getContactInformation_Phone_Type = strContactInformation_Phone_Type : End Property
A23: =Test_Data!D25 -> ContactInformation_Address_EffectiveDate | B23: ="intRow" & A23 & ", " -> intRowContactInformation_Address_EffectiveDate, | C23: =C22 &B23 -> #REF! | D23: ="str" & A23 & ", " -> strContactInformation_Address_EffectiveDate, | E23: =E22 &D23 -> #REF! | F23: ="intRow" & A23 & " = comExcelWorksheet.Range(""" & A23 & """).Row" -> intRowContactInformation_Address_EffectiveDate = comExcelWorksheet.Range("ContactInformation_Address_EffectiveDate").Row | G23: ="str" & A23 & " = comExcelWorksheet.Cells(intRow" & A23 & ", intColTestColumn).Value" -> strContactInformation_Address_EffectiveDate = comExcelWorksheet.Cells(intRowContactInformation_Address_EffectiveDate, intColTestColumn).Value | H23: ="Public Property Get get" & A23 & "() : get" & A23 & " = str" & A23 & " : End Property" -> Public Property Get getContactInformation_Address_EffectiveDate() : getContactInformation_Address_EffectiveDate = strContactInformation_Address_EffectiveDate : End Property
A24: =Test_Data!D26 -> ContactInformation_Address_Country | B24: ="intRow" & A24 & ", " -> intRowContactInformation_Address_Country, | C24: =C23 &B24 -> #REF! | D24: ="str" & A24 & ", " -> strContactInformation_Address_Country, | E24: =E23 &D24 -> #REF! | F24: ="intRow" & A24 & " = comExcelWorksheet.Range(""" & A24 & """).Row" -> intRowContactInformation_Address_Country = comExcelWorksheet.Range("ContactInformation_Address_Country").Row | G24: ="str" & A24 & " = comExcelWorksheet.Cells(intRow" & A24 & ", intColTestColumn).Value" -> strContactInformation_Address_Country = comExcelWorksheet.Cells(intRowContactInformation_Address_Country, intColTestColumn).Value | H24: ="Public Property Get get" & A24 & "() : get" & A24 & " = str" & A24 & " : End Property" -> Public Property Get getContactInformation_Address_Country() : getContactInformation_Address_Country = strContactInformation_Address_Country : End Property
A25: =Test_Data!D27 -> ContactInformation_Address_NameOfStreet | B25: ="intRow" & A25 & ", " -> intRowContactInformation_Address_NameOfStreet, | C25: =C24 &B25 -> #REF! | D25: ="str" & A25 & ", " -> strContactInformation_Address_NameOfStreet, | E25: =E24 &D25 -> #REF! | F25: ="intRow" & A25 & " = comExcelWorksheet.Range(""" & A25 & """).Row" -> intRowContactInformation_Address_NameOfStreet = comExcelWorksheet.Range("ContactInformation_Address_NameOfStreet").Row | G25: ="str" & A25 & " = comExcelWorksheet.Cells(intRow" & A25 & ", intColTestColumn).Value" -> strContactInformation_Address_NameOfStreet = comExcelWorksheet.Cells(intRowContactInformation_Address_NameOfStreet, intColTestColumn).Value | H25: ="Public Property Get get" & A25 & "() : get" & A25 & " = str" & A25 & " : End Property" -> Public Property Get getContactInformation_Address_NameOfStreet() : getContactInformation_Address_NameOfStreet = strContactInformation_Address_NameOfStreet : End Property
A26: =Test_Data!#REF! -> #REF! | B26: ="intRow" & A26 & ", " -> #REF! | C26: =C25 &B26 -> #REF! | D26: ="str" & A26 & ", " -> #REF! | E26: =E25 &D26 -> #REF! | F26: ="intRow" & A26 & " = comExcelWorksheet.Range(""" & A26 & """).Row" -> #REF! | G26: ="str" & A26 & " = comExcelWorksheet.Cells(intRow" & A26 & ", intColTestColumn).Value" -> #REF! | H26: ="Public Property Get get" & A26 & "() : get" & A26 & " = str" & A26 & " : End Property" -> #REF!
A27: =Test_Data!D30 -> ContactInformation_Address_City | B27: ="intRow" & A27 & ", " -> intRowContactInformation_Address_City, | C27: =C26 &B27 -> #REF! | D27: ="str" & A27 & ", " -> strContactInformation_Address_City, | E27: =E26 &D27 -> #REF! | F27: ="intRow" & A27 & " = comExcelWorksheet.Range(""" & A27 & """).Row" -> intRowContactInformation_Address_City = comExcelWorksheet.Range("ContactInformation_Address_City").Row | G27: ="str" & A27 & " = comExcelWorksheet.Cells(intRow" & A27 & ", intColTestColumn).Value" -> strContactInformation_Address_City = comExcelWorksheet.Cells(intRowContactInformation_Address_City, intColTestColumn).Value | H27: ="Public Property Get get" & A27 & "() : get" & A27 & " = str" & A27 & " : End Property" -> Public Property Get getContactInformation_Address_City() : getContactInformation_Address_City = strContactInformation_Address_City : End Property
A28: =Test_Data!D29 -> ContactInformation_Address_PostalCode | B28: ="intRow" & A28 & ", " -> intRowContactInformation_Address_PostalCode, | C28: =C27 &B28 -> #REF! | D28: ="str" & A28 & ", " -> strContactInformation_Address_PostalCode, | E28: =E27 &D28 -> #REF! | F28: ="intRow" & A28 & " = comExcelWorksheet.Range(""" & A28 & """).Row" -> intRowContactInformation_Address_PostalCode = comExcelWorksheet.Range("ContactInformation_Address_PostalCode").Row | G28: ="str" & A28 & " = comExcelWorksheet.Cells(intRow" & A28 & ", intColTestColumn).Value" -> strContactInformation_Address_PostalCode = comExcelWorksheet.Cells(intRowContactInformation_Address_PostalCode, intColTestColumn).Value | H28: ="Public Property Get get" & A28 & "() : get" & A28 & " = str" & A28 & " : End Property" -> Public Property Get getContactInformation_Address_PostalCode() : getContactInformation_Address_PostalCode = strContactInformation_Address_PostalCode : End Property
A29: =Test_Data!D32 -> ContactInformation_Address_Type | B29: ="intRow" & A29 & ", " -> intRowContactInformation_Address_Type, | C29: =C28 &B29 -> #REF! | D29: ="str" & A29 & ", " -> strContactInformation_Address_Type, | E29: =E28 &D29 -> #REF! | F29: ="intRow" & A29 & " = comExcelWorksheet.Range(""" & A29 & """).Row" -> intRowContactInformation_Address_Type = comExcelWorksheet.Range("ContactInformation_Address_Type").Row | G29: ="str" & A29 & " = comExcelWorksheet.Cells(intRow" & A29 & ", intColTestColumn).Value" -> strContactInformation_Address_Type = comExcelWorksheet.Cells(intRowContactInformation_Address_Type, intColTestColumn).Value | H29: ="Public Property Get get" & A29 & "() : get" & A29 & " = str" & A29 & " : End Property" -> Public Property Get getContactInformation_Address_Type() : getContactInformation_Address_Type = strContactInformation_Address_Type : End Property
A30: =Test_Data!D33 -> ContactInformation_Address_UseFor | B30: ="intRow" & A30 & ", " -> intRowContactInformation_Address_UseFor, | C30: =C29 &B30 -> #REF! | D30: ="str" & A30 & ", " -> strContactInformation_Address_UseFor, | E30: =E29 &D30 -> #REF! | F30: ="intRow" & A30 & " = comExcelWorksheet.Range(""" & A30 & """).Row" -> intRowContactInformation_Address_UseFor = comExcelWorksheet.Range("ContactInformation_Address_UseFor").Row | G30: ="str" & A30 & " = comExcelWorksheet.Cells(intRow" & A30 & ", intColTestColumn).Value" -> strContactInformation_Address_UseFor = comExcelWorksheet.Cells(intRowContactInformation_Address_UseFor, intColTestColumn).Value | H30: ="Public Property Get get" & A30 & "() : get" & A30 & " = str" & A30 & " : End Property" -> Public Property Get getContactInformation_Address_UseFor() : getContactInformation_Address_UseFor = strContactInformation_Address_UseFor : End Property
A31: =Test_Data!D34 -> ContactInformation_Email_EmailAddress | B31: ="intRow" & A31 & ", " -> intRowContactInformation_Email_EmailAddress, | C31: =C30 &B31 -> #REF! | D31: ="str" & A31 & ", " -> strContactInformation_Email_EmailAddress, | E31: =E30 &D31 -> #REF! | F31: ="intRow" & A31 & " = comExcelWorksheet.Range(""" & A31 & """).Row" -> intRowContactInformation_Email_EmailAddress = comExcelWorksheet.Range("ContactInformation_Email_EmailAddress").Row | G31: ="str" & A31 & " = comExcelWorksheet.Cells(intRow" & A31 & ", intColTestColumn).Value" -> strContactInformation_Email_EmailAddress = comExcelWorksheet.Cells(intRowContactInformation_Email_EmailAddress, intColTestColumn).Value | H31: ="Public Property Get get" & A31 & "() : get" & A31 & " = str" & A31 & " : End Property" -> Public Property Get getContactInformation_Email_EmailAddress() : getContactInformation_Email_EmailAddress = strContactInformation_Email_EmailAddress : End Property
A32: =Test_Data!D35 -> ContactInformation_Email_Type | B32: ="intRow" & A32 & ", " -> intRowContactInformation_Email_Type, | C32: =C31 &B32 -> #REF! | D32: ="str" & A32 & ", " -> strContactInformation_Email_Type, | E32: =E31 &D32 -> #REF! | F32: ="intRow" & A32 & " = comExcelWorksheet.Range(""" & A32 & """).Row" -> intRowContactInformation_Email_Type = comExcelWorksheet.Range("ContactInformation_Email_Type").Row | G32: ="str" & A32 & " = comExcelWorksheet.Cells(intRow" & A32 & ", intColTestColumn).Value" -> strContactInformation_Email_Type = comExcelWorksheet.Cells(intRowContactInformation_Email_Type, intColTestColumn).Value | H32: ="Public Property Get get" & A32 & "() : get" & A32 & " = str" & A32 & " : End Property" -> Public Property Get getContactInformation_Email_Type() : getContactInformation_Email_Type = strContactInformation_Email_Type : End Property
A33: =Test_Data!D36 -> JobDetails_HireDate | B33: ="intRow" & A33 & ", " -> intRowJobDetails_HireDate, | C33: =C32 &B33 -> #REF! | D33: ="str" & A33 & ", " -> strJobDetails_HireDate, | E33: =E32 &D33 -> #REF! | F33: ="intRow" & A33 & " = comExcelWorksheet.Range(""" & A33 & """).Row" -> intRowJobDetails_HireDate = comExcelWorksheet.Range("JobDetails_HireDate").Row | G33: ="str" & A33 & " = comExcelWorksheet.Cells(intRow" & A33 & ", intColTestColumn).Value" -> strJobDetails_HireDate = comExcelWorksheet.Cells(intRowJobDetails_HireDate, intColTestColumn).Value | H33: ="Public Property Get get" & A33 & "() : get" & A33 & " = str" & A33 & " : End Property" -> Public Property Get getJobDetails_HireDate() : getJobDetails_HireDate = strJobDetails_HireDate : End Property
A34: =Test_Data!D37 -> JobDetails_Reason | B34: ="intRow" & A34 & ", " -> intRowJobDetails_Reason, | C34: =C33 &B34 -> #REF! | D34: ="str" & A34 & ", " -> strJobDetails_Reason, | E34: =E33 &D34 -> #REF! | F34: ="intRow" & A34 & " = comExcelWorksheet.Range(""" & A34 & """).Row" -> intRowJobDetails_Reason = comExcelWorksheet.Range("JobDetails_Reason").Row | G34: ="str" & A34 & " = comExcelWorksheet.Cells(intRow" & A34 & ", intColTestColumn).Value" -> strJobDetails_Reason = comExcelWorksheet.Cells(intRowJobDetails_Reason, intColTestColumn).Value | H34: ="Public Property Get get" & A34 & "() : get" & A34 & " = str" & A34 & " : End Property" -> Public Property Get getJobDetails_Reason() : getJobDetails_Reason = strJobDetails_Reason : End Property
A35: =Test_Data!D38 -> JobDetails_Position | B35: ="intRow" & A35 & ", " -> intRowJobDetails_Position, | C35: =C34 &B35 -> #REF! | D35: ="str" & A35 & ", " -> strJobDetails_Position, | E35: =E34 &D35 -> #REF! | F35: ="intRow" & A35 & " = comExcelWorksheet.Range(""" & A35 & """).Row" -> intRowJobDetails_Position = comExcelWorksheet.Range("JobDetails_Position").Row | G35: ="str" & A35 & " = comExcelWorksheet.Cells(intRow" & A35 & ", intColTestColumn).Value" -> strJobDetails_Position = comExcelWorksheet.Cells(intRowJobDetails_Position, intColTestColumn).Value | H35: ="Public Property Get get" & A35 & "() : get" & A35 & " = str" & A35 & " : End Property" -> Public Property Get getJobDetails_Position() : getJobDetails_Position = strJobDetails_Position : End Property
A36: =Test_Data!D39 -> JobDetails_EmployeeType | B36: ="intRow" & A36 & ", " -> intRowJobDetails_EmployeeType, | C36: =C35 &B36 -> #REF! | D36: ="str" & A36 & ", " -> strJobDetails_EmployeeType, | E36: =E35 &D36 -> #REF! | F36: ="intRow" & A36 & " = comExcelWorksheet.Range(""" & A36 & """).Row" -> intRowJobDetails_EmployeeType = comExcelWorksheet.Range("JobDetails_EmployeeType").Row | G36: ="str" & A36 & " = comExcelWorksheet.Cells(intRow" & A36 & ", intColTestColumn).Value" -> strJobDetails_EmployeeType = comExcelWorksheet.Cells(intRowJobDetails_EmployeeType, intColTestColumn).Value | H36: ="Public Property Get get" & A36 & "() : get" & A36 & " = str" & A36 & " : End Property" -> Public Property Get getJobDetails_EmployeeType() : getJobDetails_EmployeeType = strJobDetails_EmployeeType : End Property
A37: =Test_Data!D40 -> JobDetails_JobProfile | B37: ="intRow" & A37 & ", " -> intRowJobDetails_JobProfile, | C37: =C36 &B37 -> #REF! | D37: ="str" & A37 & ", " -> strJobDetails_JobProfile, | E37: =E36 &D37 -> #REF! | F37: ="intRow" & A37 & " = comExcelWorksheet.Range(""" & A37 & """).Row" -> intRowJobDetails_JobProfile = comExcelWorksheet.Range("JobDetails_JobProfile").Row | G37: ="str" & A37 & " = comExcelWorksheet.Cells(intRow" & A37 & ", intColTestColumn).Value" -> strJobDetails_JobProfile = comExcelWorksheet.Cells(intRowJobDetails_JobProfile, intColTestColumn).Value | H37: ="Public Property Get get" & A37 & "() : get" & A37 & " = str" & A37 & " : End Property" -> Public Property Get getJobDetails_JobProfile() : getJobDetails_JobProfile = strJobDetails_JobProfile : End Property
A38: =Test_Data!D41 -> JobDetails_TimeType | B38: ="intRow" & A38 & ", " -> intRowJobDetails_TimeType, | C38: =C37 &B38 -> #REF! | D38: ="str" & A38 & ", " -> strJobDetails_TimeType, | E38: =E37 &D38 -> #REF! | F38: ="intRow" & A38 & " = comExcelWorksheet.Range(""" & A38 & """).Row" -> intRowJobDetails_TimeType = comExcelWorksheet.Range("JobDetails_TimeType").Row | G38: ="str" & A38 & " = comExcelWorksheet.Cells(intRow" & A38 & ", intColTestColumn).Value" -> strJobDetails_TimeType = comExcelWorksheet.Cells(intRowJobDetails_TimeType, intColTestColumn).Value | H38: ="Public Property Get get" & A38 & "() : get" & A38 & " = str" & A38 & " : End Property" -> Public Property Get getJobDetails_TimeType() : getJobDetails_TimeType = strJobDetails_TimeType : End Property
A39: =Test_Data!D42 -> JobDetails_Location | B39: ="intRow" & A39 & ", " -> intRowJobDetails_Location, | C39: =C38 &B39 -> #REF! | D39: ="str" & A39 & ", " -> strJobDetails_Location, | E39: =E38 &D39 -> #REF! | F39: ="intRow" & A39 & " = comExcelWorksheet.Range(""" & A39 & """).Row" -> intRowJobDetails_Location = comExcelWorksheet.Range("JobDetails_Location").Row | G39: ="str" & A39 & " = comExcelWorksheet.Cells(intRow" & A39 & ", intColTestColumn).Value" -> strJobDetails_Location = comExcelWorksheet.Cells(intRowJobDetails_Location, intColTestColumn).Value | H39: ="Public Property Get get" & A39 & "() : get" & A39 & " = str" & A39 & " : End Property" -> Public Property Get getJobDetails_Location() : getJobDetails_Location = strJobDetails_Location : End Property
A40: =Test_Data!D43 -> JobDetails_AdditionalInformation_ScheduledWeeklyHours | B40: ="intRow" & A40 & ", " -> intRowJobDetails_AdditionalInformation_ScheduledWeeklyHours, | C40: =C39 &B40 -> #REF! | D40: ="str" & A40 & ", " -> strJobDetails_AdditionalInformation_ScheduledWeeklyHours, | E40: =E39 &D40 -> #REF! | F40: ="intRow" & A40 & " = comExcelWorksheet.Range(""" & A40 & """).Row" -> intRowJobDetails_AdditionalInformation_ScheduledWeeklyHours = comExcelWorksheet.Range("JobDetails_AdditionalInformation_ScheduledWeeklyHours").Row | G40: ="str" & A40 & " = comExcelWorksheet.Cells(intRow" & A40 & ", intColTestColumn).Value" -> strJobDetails_AdditionalInformation_ScheduledWeeklyHours = comExcelWorksheet.Cells(intRowJobDetails_AdditionalInformation_ScheduledWeeklyHours, intColTestColumn).Value | H40: ="Public Property Get get" & A40 & "() : get" & A40 & " = str" & A40 & " : End Property" -> Public Property Get getJobDetails_AdditionalInformation_ScheduledWeeklyHours() : getJobDetails_AdditionalInformation_ScheduledWeeklyHours = strJobDetails_AdditionalInformation_ScheduledWeeklyHours : End Property
...

Sheet Names
B3: Etoecyeone | C3: 1 | D3: one | F3: 1 | G3: one | J3: =G3&H3 -> one | K3: one
B4: Etoecyeone | C4: 2 | D4: two | F4: 2 | G4: two | J4: =G4&H4 -> two | K4: two
B5: Etoecyeone | C5: 3 | D5: three | F5: 3 | G5: three | J5: =G5&H5 -> three | K5: three
B6: Etoecyeone | C6: 4 | D6: four | F6: 4 | G6: four | J6: =G6&H6 -> four | K6: four
B7: Etoecyeone | C7: 5 | D7: five | F7: 5 | G7: five | J7: =G7&H7 -> five | K7: five
B8: Etoecyeone | C8: 6 | D8: six | F8: 6 | G8: six | J8: =G8&H8 -> six | K8: six
B9: Etoecyeone | C9: 7 | D9: seven | F9: 7 | G9: seven | J9: =G9&H9 -> seven | K9: seven
B10: Etoecyeone | C10: 8 | D10: eight | F10: 8 | G10: eight | J10: =G10&H10 -> eight | K10: eight
B11: Etoecyeone | C11: 9 | D11: nine | F11: 9 | G11: nine | J11: =G11&H11 -> nine | K11: nine
B12: Etoecyeone | C12: 10 | D12: ten | F12: 10 | G12: ten | J12: =G12&H12 -> ten | K12: ten
B13: Etoecyeone | C13: 11 | D13: eleven | F13: 11 | G13: eleven | J13: =G13&H13 -> eleven | K13: eleven
B14: Etoecyeone | C14: 12 | D14: twelve | F14: 12 | G14: twelve | J14: =G14&H14 -> twelve | K14: twelve
B15: Etoecyeone | C15: 13 | D15: thirteen | F15: 13 | G15: thirteen | J15: =G15&H15 -> thirteen | K15: thirteen
... B22: Etoecyeone | C22: 20 | D22: twenty | F22: 20 | G22: twenty | J22: =G22&H22 -> twenty | K22: twenty
B23: Etoecyeone | C23: 30 | D23: thirty | F23: 21 | G23: twenty | H23: one | J23: =G23&H23 -> twentyone | K23: twentyone
B24: Etoecyeone | C24: 40 | D24: forty | F24: 22 | G24: twenty | H24: two | J24: =G24&H24 -> twentytwo | K24: twentytwo
B25: Etoecyeone | C25: 50 | D25: fifty | F25: 23 | G25: twenty | H25: three | J25: =G25&H25 -> twentythree | K25: twentythree
B26: Etoecyeone | C26: 60 | D26: sixty | F26: 24 | G26: twenty | H26: four | J26: =G26&H26 -> twentyfour | K26: twentyfour
B27: Etoecyeone | C27: 70 | D27: seventy | F27: 25 | G27: twenty | H27: five | J27: =G27&H27 -> twentyfive | K27: twentyfive
B28: Etoecyeone | C28: 80 | D28: eighty | F28: 26 | G28: twenty | H28: six | J28: =G28&H28 -> twentysix | K28: twentysix
B29: Etoecyeone | C29: 90 | D29: ninety | F29: 27 | G29: twenty | H29: seven | J29: =G29&H29 -> twentyseven | K29: twentyseven
B30: Etoecyeone | C30: 100 | D30: one hundred | F30: 28 | G30: twenty | H30: eight | J30: =G30&H30 -> twentyeight | K30: twentyeight
B31: Etoecyeone | C31: 1000 | D31: one thousand | F31: 29 | G31: twenty | H31: nine | J31: =G31&H31 -> twentynine | K31: twentynine
B32: Etoecyeone | F32: 30 | G32: thirty | J32: =G32&H32 -> thirty | K32: thirty
B33: Etoecyeone | F33: 31 | G33: thirty | H33: one | J33: =G33&H33 -> thirtyone | K33: thirtyone
B34: Etoecyeone | F34: 32 | G34: thirty | H34: two | J34: =G34&H34 -> thirtytwo | K34: thirtytwo
B35: Etoecyeone | F35: 33 | G35: thirty | H35: three | J35: =G35&H35 -> thirtythree | K35: thirtythree
B36: Etoecyeone | F36: 34 | G36: thirty | H36: four | J36: =G36&H36 -> thirtyfour | K36: thirtyfour
B37: Etoecyeone | F37: 35 | G37: thirty | H37: five | J37: =G37&H37 -> thirtyfive | K37: thirtyfive
B38: Etoecyeone | F38: 36 | G38: thirty | H38: six | J38: =G38&H38 -> thirtysix | K38: thirtysix
B39: Etoecyeone | F39: 37 | G39: thirty | H39: seven | J39: =G39&H39 -> thirtyseven | K39: thirtyseven
B40: Etoecyeone | F40: 38 | G40: thirty | H40: eight | J40: =G40&H40 -> thirtyeight | K40: thirtyeight
B41: Etoecyeone | F41: 39 | G41: thirty | H41: nine | J41: =G41&H41 -> thirtynine | K41: thirtynine
B42: Etoecyeone | F42: 40 | G42: forty | J42: =G42&H42 -> forty | K42: forty
B43: Etoecyeone | F43: 41 | G43: forty | H43: one | J43: =G43&H43 -> fortyone | K43: fortyone
B44: Etoecyeone | F44: 42 | G44: forty | H44: two | J44: =G44&H44 -> fortytwo | K44: fortytwo
B45: Etoecyeone | F45: 43 | G45: forty | H45: three | J45: =G45&H45 -> fortythree | K45: fortythree
B46: Etoecyeone | F46: 44 | G46: forty | H46: four | J46: =G46&H46 -> fortyfour | K46: fortyfour
B47: Etoecyeone | F47: 45 | G47: forty | H47: five | J47: =G47&H47 -> fortyfive | K47: fortyfive
B48: Etoecyeone | F48: 46 | G48: forty | H48: six | J48: =G48&H48 -> fortysix | K48: fortysix
...

Sheet Test_Data
A1: Version_Number | C1: Test_ID | D1: Test_ID | E1: Test_ID2 | F1: Notes | G1: Test_1 | H1: Test_2 | I1: Test_3 | J1: Test_4 | K1: Test_5 | L1: Test_6 | M1: Test_7 | N1: Test_8 | O1: Test_9 | P1: Test_10 | Q1: Test_11 | R1: Test_12 | S1: Test_13 | T1: Test_14 | U1: Test_15
A2: 0.3 | C2: Reporting_ID | G2: 1 | H2: 2 | I2: 3 | J2: 4 | K2: 5 | L2: 6 | M2: 7 | N2: 8 | O2: 9 | P2: 10 | Q2: 11 | R2: 12 | S2: 13 | T2: 14 | U2: 15
C3: Process | D3: Process | E3: Process2 | F3: If a manager hire and new role is required then select "New Role and New Hire" otherwise select "New Hire | G3: New Hire | H3: New Hire | I3: New Role & New Hire | J3: New Hire | K3: New Role & New Hire | L3: New Role & New Hire | M3: New Role & New Hire | N3: New Role & New Hire | O3: New Role & New Hire | P3: New Role & New Hire | Q3: New Hire | R3: New Hire | S3: New Hire | T3: New Hire | U3: New Hire
C4: Execution Flag | D4: ExecutionFlag | E4: ExecutionFlag2 | F4: If set to No will not execute in next automation run | G4: No | H4: No | I4: No | J4: Yes | K4: No | L4: No | M4: No | N4: No | O4: Yes | P4: Yes | Q4: Yes | R4: Yes | S4: Yes | T4: Yes | U4: Yes
C5: Data Validation Complete | D5: DataValidationComplete | E5: DataValidationComplete2 | G5: TRUE | H5: TRUE | I5: TRUE | J5: TRUE | K5: TRUE | L5: TRUE | M5: TRUE | N5: TRUE | O5: TRUE | P5: TRUE | Q5: TRUE | R5: TRUE | S5: TRUE | T5: TRUE | U5: TRUE
C6: Hire Name Complete | D6: HireNameComplete | E6: HireNameComplete2 | G6: TRUE | H6: TRUE | I6: TRUE | J6: TRUE | K6: TRUE | L6: TRUE | M6: TRUE | N6: TRUE | O6: TRUE | P6: TRUE | Q6: TRUE | R6: TRUE | S6: TRUE | T6: TRUE | U6: TRUE
C7: Last Run Time and Status | D7: LastRunTimeandStatus | E7: LastRunTimeandStatus2 | F7: Once test is executed the Execution Timestamp and Pass/Fail status will be recorded here | G7: 15/10/2024 04:40:23 Passed | H7: 15/10/2024 04:56:30 Passed | I7: 15/10/2024 05:14:54 Passed | J7: 15/10/2024 05:24:15 Failed | K7: 15/10/2024 05:42:37 Passed | L7: 15/10/2024 06:01:04 Passed | M7: 15/10/2024 06:19:26 Passed | N7: 15/10/2024 06:38:00 Passed | O7: 15/10/2024 06:40:12 Failed | P7: 15/10/2024 06:40:59 Failed | Q7: 15/10/2024 06:42:48 Failed
C8: Last Run Employee No | D8: LastRunEmployeeNo | E8: LastRunEmployeeNo2 | F8: The newly created employee number will be recorded here | G8: 10651050 | H8: 10651051 | I8: 10651052 | K8: 10651053 | L8: 10651054 | M8: 10651055 | N8: 10651056
