Workbook
Name AddAdditonalName_Country: Test_Data!#REF!
Name AddAdditonalName_FamilyName: Test_Data!#REF!
Name AddAdditonalName_GivenName: Test_Data!#REF!
Name AddAdditonalName_NameType: Test_Data!#REF!
Name AddProbationPeriod_ProbationEndDate: Test_Data!#REF!
Name AddProbationPeriod_ProbationEndDate2: Test_Data!#REF!
Name AddProbationPeriod_ProbationEndDate2: Automation_Lookups!$AO$2:$AO$4
Name AddProbationPeriod_ProbationReviewDate: Test_Data!#REF!
Name AssignPayGroup_ProposedPayGroup: Test_Data!$E$70
Name AssignPayGroup_ProposedPayGroup: Automation_Lookups!$T$2:$T$20
Name AssignPayGroup_ProposedPayGroup2: Test_Data!$F$70
Name AssignPayGroup_ProposedPayGroup2: Automation_Lookups!$T$2
Name AssignPayGroup_ProposedPayGroupFinal: Test_Data!$E$70
Name AssignPayGroup_ProposedPayGroupInitial: Test_Data!$E$69
Name Automation_Ref: Test_Data!$E$14:$F$14
Name AutomationComments: Test_Data!$E$11:$F$11
Name ChangeMyEmergencyContacts_Address_City: Test_Data!#REF!
Name ChangeMyEmergencyContacts_Address_HouseNumber: Test_Data!#REF!
Name ChangeMyEmergencyContacts_Address_PostalCode: Test_Data!#REF!
Name ChangeMyEmergencyContacts_Address_Province: Test_Data!#REF!
Name ChangeMyEmergencyContacts_Address_StreetName: Test_Data!#REF!
Name ChangeMyEmergencyContacts_Address_Type: Test_Data!#REF!
Name ChangeMyEmergencyContacts_City: Test_Data!#REF!
Name ChangeMyEmergencyContacts_Email_Address: Test_Data!#REF!
Name ChangeMyEmergencyContacts_Email_Type: Test_Data!#REF!
Name ChangeMyEmergencyContacts_EmailAddress: Test_Data!#REF!
Name ChangeMyEmergencyContacts_FamilyName: Test_Data!#REF!
Name ChangeMyEmergencyContacts_GivenName: Test_Data!#REF!
Name ChangeMyEmergencyContacts_LegalName_FamilyName: Test_Data!#REF!
Name ChangeMyEmergencyContacts_LegalName_GivenName: Test_Data!#REF!
Name ChangeMyEmergencyContacts_LegalName_Prefix: Test_Data!#REF!
Name ChangeMyEmergencyContacts_PhoneDevice: Test_Data!#REF!
Name ChangeMyEmergencyContacts_PhoneDevice2: Automation_Lookups!$AJ$2:$AJ$3
Name ChangeMyEmergencyContacts_PhoneNumber: Test_Data!#REF!
Name ChangeMyEmergencyContacts_PostalCode: Test_Data!#REF!
Name ChangeMyEmergencyContacts_PreferredLanguage: Test_Data!#REF!
Name ChangeMyEmergencyContacts_Relationship: Test_Data!#REF!
Name ChangeMyEmergencyContacts_Relationship2: Automation_Lookups!$AI$2:$AI$5
Name ChangeMyEmergencyContacts_StreetName: Test_Data!#REF!
Name ChangeMyGovernmentIDs_NationalIDs_AddEditID: Test_Data!#REF!
Name ChangeMyGovernmentIDs_NationalIDs_AddEditID1: Test_Data!$E$57
Name ChangeMyGovernmentIDs_NationalIDs_AddEditID12: Test_Data!$F$57
Name ChangeMyGovernmentIDs_NationalIDs_AddEditID2: Test_Data!#REF!
Name ChangeMyGovernmentIDs_NationalIDs_AddEditID22: Automation_Lookups!$AL$2:$AL$4
Name ChangeMyGovernmentIDs_NationalIDs_AddEditID22: Test_Data!#REF!
Name ChangeMyGovernmentIDs_NationalIDs_AddEditID3: Test_Data!#REF!
Name ChangeMyGovernmentIDs_NationalIDs_Country1: Test_Data!$E$55
Name ChangeMyGovernmentIDs_NationalIDs_Country12: Test_Data!$F$55
Name ChangeMyGovernmentIDs_NationalIDs_Country2: Test_Data!#REF!
Name ChangeMyGovernmentIDs_NationalIDs_Country22: Test_Data!#REF!
Name ChangeMyGovernmentIDs_NationalIDs_Country3: Test_Data!#REF!
Name ChangeMyGovernmentIDs_NationalIDs_ExpirationDate1: Test_Data!#REF!
Name ChangeMyGovernmentIDs_NationalIDs_ExpirationDate2: Test_Data!#REF!
Name ChangeMyGovernmentIDs_NationalIDs_IssuedBy2: Test_Data!#REF!
Name ChangeMyGovernmentIDs_NationalIDs_IssuedDate1: Test_Data!#REF!
Name ChangeMyGovernmentIDs_NationalIDs_IssuedDate2: Test_Data!#REF!
Name ChangeMyGovernmentIDs_NationalIDs_NationalIDType1: Test_Data!$E$56
Name ChangeMyGovernmentIDs_NationalIDs_NationalIDType12: Test_Data!$F$56
Name ChangeMyGovernmentIDs_NationalIDs_NationalIDType12: Automation_Lookups!$AK$2:$AK$5
Name ChangeMyGovernmentIDs_NationalIDs_NationalIDType2: Test_Data!#REF!

Sheet Information
A1: Version | F1: Info
A6: Version | B6: 0.3 | F6: Info
F7: Dates | G7: For Czech all dates to be entered in format of DD/MM/YYYY
A8: History | F8: Unhighlighted fields | G8: Only data in unhighlighted fields can be changed.
A9: Date | B9: Version | C9: Details | F9: Red highlighted fields | G9: Indicates fields where unique data is required otherwise automation will throw errors
A10: 44061 | B10: 0.3 | C10: Initial Release | F10: Grey highlighted fields | G10: Indicates fields that cannot be changed
F11: Last Run Status / Last Run Error Message | G11: When automation has run for a particular test, we need to check the status is set to Passed and no error messages are present for each test before the automation run for that particular test is considered valid

Sheet Defects
B2: Batch 1 - Summary | E2: Batch 2 - Summary | H2: Batch 3 - Summary | K2: All E2E Cycle 1 - Summary
B3: Description | C3: Total | E3: Description | F3: Total | H3: Description | I3: Total | K3: Description | L3: Total No. | M3: %
B4: Passed | C4: 35 | E4: Passed | F4: 141 | H4: Passed | I4: 0 | K4: Passed | L4: =C4+F4+I4 -> 176 | M4: =L4/L8*100 -> 72.131148
B5: Failed | C5: 17 | E5: Failed | F5: 27 | H5: Failed | I5: 24 | K5: Failed | L5: =C5+F5+I5 -> 68 | M5: =L5/L8*100 -> 27.868852
B6: Not Run | C6: 0 | E6: Not Run | F6: 0 | H6: Not Run | I6: 0 | K6: Not Run | L6: =C6+F6+I6 -> 0 | M6: =L6/L8*100 -> 0
B7: Executed | C7: 52 | E7: Executed | F7: 168 | H7: Executed | I7: 24 | K7: Executed | L7: =C7+F7+I7 -> 244 | M7: =L7/L8*100 -> 100
B8: Total | C8: 52 | E8: Total | F8: 168 | H8: Total | I8: 24 | K8: Total | L8: =C8+F8+I8 -> 244 | M8: =M4+M5+M6 -> 100
B10: Batch 1 - Defects | E10: Batch 2 - Defects | H10: Batch 3 - Defects | K10: All E2E Cycle 1 - Defects
B11: Failed Tests Description | C11: Total | E11: Failed Tests Description | F11: Total | H11: Failed Tests Description | I11: Total | K11: Failed Tests Description | L11: Total No. | M11: %
B12: P&C Salary Assistant/Supervisor Salary Configuration missing | C12: 12 | E12: Grade Profile not populated causing salary to remain blank | F12: 24 | H12: Data issue - Rerun scheduled | I12: 24 | K12: Personal Information Change Approval Email missing after 2nd and final proxy into HR Manager | L12: 44 | M12: =L12/L17*100 -> 35.2
B13: Automation issue with Maiden Name - Gary to discuss with Shane/Andre | C13: 5 | E13: GC - Under Investigation | F13: 3 | H13: Total | I13: 24 | K13: Open button not available to assign paygroup for payroll. Approval required by David Bradley... | L13: 20 | M13: =L13/L17*100 -> 16
B14: Total | C14: =C12+C13 -> 17 | E14: Total | F14: 27 | K14: Grade Profile not populated causing salary to remain blank | L14: 34 | M14: =L14/L17*100 -> 27.2
K15: Data issue - Rerun scheduled | L15: 24 | M15: =L15/L17*100 -> 19.2
K16: GC - Under Investigation | L16: 3 | M16: =L16/L17*100 -> 2.4
K17: Total | L17: =SUM(L12:L16) -> 125 | M17: =SUM(M12:M16) -> 100

Sheet Automation_Lookups
A1: Process2 | B1: ExecutionFlag2 | C1: SupervisoryOrganisation_SupervisoryOrganisation2 | D1: LegalNameInformation_Country2 | E1: ContactInformation_Phone_CountryPhoneCode2 | F1: ContactInformation_Phone_PhoneDevice2 | G1: ContactInformation_Phone_Type2 | H1: ContactInformation_Address_Type2 | I1: ContactInformation_Email_Type2 | J1: JobDetails_HireDate2 | K1: JobDetails_Reason2 | L1: JobDetails_Position2 | M1: JobDetails_EmployeeType2 | N1: JobDetails_JobProfile2 | O1: JobDetails_TimeType2 | P1: JobDetails_Location2 | Q1: JobDetails_AdditionalInformation_WorkShift2 | R1: JobDetails_AdditionalInformation_EndEmploymentDate2 | S1: ChangeOrganizationAssignments_DepartmentSection2 | T1: AssignPayGroup_ProposedPayGroup2 | U1: Proxy_ProxyNumber2 | V1: Proxy_OnBehalfOf2 | W1: MaintainEmployeeContract_Reason2 | X1: MaintainEmployeeContract_Status2 | Y1: MaintainEmployeeContract_ContractType2 | Z1: MaintainEmployeeContract_ContractEndDate2 | AA1: ProposeCompensationHire_GradeProfile2 | AB1: ProposeCompensationHire_Step2 | AC1: EditPassportsandVisas_Country2 | AD1: EditPassportsandVisas_PassportIDType2 | AE1: EditPassportsandVisas_IdentificationNo2 | AF1: EditPassportsandVisas_IssuedDate2 | AG1: EditPassportsandVisas_ExpirationDate2 | AH1: ChangeMyPersonalInformation_MaritalStatus2 | AI1: ChangeMyEmergencyContacts_Relationship2 | AJ1: ChangeMyEmergencyContacts_PhoneDevice2 | AK1: ChangeMyGovernmentIDs_NationalIDs_NationalIDType12 | AL1: ChangeMyGovernmentIDs_NationalIDs_AddEditID22 | AM1: PaymentElectionOption_AccountType2 | AN1: SkillsAndExperience_AddEducation_School2 | AO1: AddProbationPeriod_ProbationEndDate2 | AP1: EditAdditionalData_PayrollTaxDeduction | AQ1: HealthCareProvider_MealVoucher2 | AR1: School1 | AS1: School2 | AT1: ContactInformation_Address_Province2 | AU1: ChangeMyGovernmentIDs_NationalIDs_NationalIDType12 | AV1: ChangeMyGovernmentIDs_NationalIDs_NationalIDType22 | AW1: EditAdditionalData_EstadolIRPF2 | AX1: EditAdditionalData_MinusvaliaRH2
A2: New Hire | B2: Yes | C2: 362 Recruitment (Carolina De La Barrera Crespo (375)) | D2: Czechia | E2: Czechia (+420) | F2: Mobile | G2: Home | H2: Home | I2: Home | J2: =IF(MONTH(TODAY())<10,"0"&MONTH(TODAY())&"/",MONTH(TODAY())&"/") & IF(DAY(TODAY())<10,"0"&DAY(TODAY())&"/",DAY(TODAY())&"/") & YEAR(TODAY()) -> 03/04/2025 | K2: New Hire | L2: Assistant Manager-2 | M2: Fixed Term | N2: DPP/DPC | O2: Full time | P2: 362 Algeciras | Q2: 1 Day | R2: =IF(MONTH(TODAY())<10,"0"&MONTH(TODAY())&"/",MONTH(TODAY())&"/") & IF(DAY(TODAY())<10,"0"&DAY(TODAY())&"/",DAY(TODAY())&"/") & YEAR(TODAY()) -> 03/04/2025 | S2: Accessories | T2: Please select a Spanish Pay Group | U2: 10223439 | V2: Iwona Chrostowska (10223439) | W2: for the purposes of performing any work of casual or seasonal nature | X2: 1st Fixed Term Contract | Y2: Employment Agreement | Z2: =IF(MONTH(TODAY())<10,"0"&MONTH(TODAY())&"/",MONTH(TODAY())&"/") & IF(DAY(TODAY())<10,"0"&DAY(TODAY())&"/",DAY(TODAY())&"/") & YEAR(TODAY()) -> 03/04/2025 | AA2: Defaulted | AB2: Defaulted | AH2: Single | AI2: Father | AJ2: Mobile/Cell | AK2: Social Security Number (NSS) | AL2: Social Security Number (NSS) | AM2: Savings | AN2: N/A | AO2: =IF(MONTH(TODAY()+100)<10,"0"&MONTH(TODAY()+100)&"/",MONTH(TODAY()+100)&"/") & IF(DAY(TODAY()+100)<10,"0"&DAY(TODAY()+100)&"/",DAY(TODAY()+100)&"/") & YEAR(TODAY()+100) -> 06/12/2025 | AP2: Yes | AQ2: Yes | AR2: Střední bez maturity či výučního listu | AS2: stredni bez maturity ci vyucniho listu | AT2: Madrid | AU2: Social Security Number (NSS) | AV2: ID Card (DNI) Number | AW2: Soltero/a, viudo/a, divorciado/a o separado/a legalmente con hijos solteros menores de 18 años o incapacitados judicialmente que conviven exclusivamente con Vd., sin convivir también con el otro progenitor Soltero/a, viudo/a, divorciado/a o separado/a legalmente con hijos solteros menores de 18 años o incapacitados judicialmente que conviven exclusivamente con Vd., sin convivir también con el otro progenitor | AX2: Del 33% hasta el 65%
A3: New Role & New Hire | B3: No | C3: 895 Store Management (Male Teststmanager (10224969)) | D3: Czechia | E3: Czechia (+420) | F3: Landline | G3: Work | H3: Work | I3: Work | J3: =IF(MONTH(TODAY()-10)<10,"0"&MONTH(TODAY()-10)&"/",MONTH(TODAY()-10))&"/" & IF(DAY(TODAY()-10)<10,"0"&DAY(TODAY()-10)&"/",DAY(TODAY()-10)&"/") & YEAR(TODAY()-10) -> 02//22/2025 | L3: Assistant Manager-3 | M3: Intern | N3: Retail Assistant | O3: Part time | Q3: 2 Days | R3: =IF(MONTH(TODAY()+100)<10,"0"&MONTH(TODAY()+100)&"/",MONTH(TODAY()+100)&"/") & IF(DAY(TODAY()+100)<10,"0"&DAY(TODAY()+100)&"/",DAY(TODAY()+100)&"/") & YEAR(TODAY()+100) -> 06/12/2025 | T3: ES Monthly - 15 payments | U3: 10225553 | V3: Kocour Mikeš (10225553) | W3: for the purposes of performing work during the term of office | X3: 2nd Fixed Term Contract | Y3: Agreement to perform work | Z3: =IF(MONTH(TODAY()+100)<10,"0"&MONTH(TODAY()+100)&"/",MONTH(TODAY()+100)&"/") & IF(DAY(TODAY()+100)<10,"0"&DAY(TODAY()+100)&"/",DAY(TODAY()+100)&"/") & YEAR(TODAY()+100) -> 06/12/2025 | AH3: Married | AI3: Mother | AJ3: Telephone - Landline | AK3: ID Card (DNI) Number | AL3: ID Card (DNI) Number | AM3: Checking | AN3: Vseobecne stredni s maturitou | AO3: =IF(MONTH(TODAY()+1000)<10,"0"&MONTH(TODAY()+1000)&"/",MONTH(TODAY()+1000)&"/") & IF(DAY(TODAY()+1000)<10,"0"&DAY(TODAY()+1000)&"/",DAY(TODAY()+1000)&"/") & YEAR(TODAY()+1000) -> 11/29/2027 | AP3: No | AQ3: No | AR3: Střední odborné vzdělání s výučním listem | AS3: stredni odborne vzdelani s vyucnim listem
D4: Poland | E4: Poland (+48) | J4: =IF(MONTH(TODAY()+10)<10,"0"&MONTH(TODAY()+10)&"/",MONTH(TODAY()+10)&"/") & IF(DAY(TODAY()+10)<10,"0"&DAY(TODAY()+10)&"/",DAY(TODAY()+10)&"/") & YEAR(TODAY()+10) -> 03/14/2025 | L4: Test Store Manager-2 | M4: Permanent | N4: Department Manager | Q4: 3 Days | R4: =IF(MONTH(TODAY()+1000)<10,"0"&MONTH(TODAY()+1000)&"/",MONTH(TODAY()+1000)&"/") & IF(DAY(TODAY()+1000)<10,"0"&DAY(TODAY()+1000)&"/",DAY(TODAY()+1000)&"/") & YEAR(TODAY()+1000) -> 11/29/2027 | W4: for the purposes of substituting an employee during his/her excused absence at work | X4: 3rd Fixed Term Contract | Y4: Agreement to complete a job | Z4: =IF(MONTH(TODAY()+1000)<10,"0"&MONTH(TODAY()+1000)&"/",MONTH(TODAY()+1000)&"/") & IF(DAY(TODAY()+1000)<10,"0"&DAY(TODAY()+1000)&"/",DAY(TODAY()+1000)&"/") & YEAR(TODAY()+1000) -> 11/29/2027 | AH4: Not Disclosed | AI4: Spouse | AK4: Alien Identification Number (NIE) | AL4: Alien Identification Number (NIE) | AO4: N/A | AR4: Všeobecné střední s maturitou | AS4: vseobecne stredni s maturitou
D5: Poland | E5: Poland (+48) | L5: N/A | M5: Students | N5: Senior Department Manager | Q5: 4 Days | R5: N/A | W5: No reason necessary | X5: Active | Z5: N/A | AI5: Partner | AK5: Tax Identification Number (NIF) | AR5: Vysokoškolské Bc. | AS5: Vysokoskolske Bc
N6: Supervisor | Q6: 5 Days | X6: Inactive | AR6: Vysokoškolské MUDr., JUDr., Mgr., MgA., Ing. | AS6: vysokoskolske MUDR., JUDr., Mgr., MgA., Ing.
N7: P&C Supervisor | AR7: Vysokoškolské PhDr, PhD, JUDr, MUDr | AS7: vysokoskolske PhDr, PhD, JUDr, MUDr
N8: P&C Assistant | AR8: vyšší odborné DiS | AS8: vyssi odborne DiS
N9: Trainee Manager | AR9: Základní | AS9: Zakladni
N10: Assistant Manager
N11: P&C Manager
N12: Store Manager
N13: Visual Merchandiser Manager
N14: Visual Merchandising Supervisor
N15: Visual Merchandising Assistant
K21: Rehire | U21: 8701839 | V21: Lisanne Kluinhaar (8701839) | W21: Defined contract end date (Determined) | AQ21: Netherlands Retail Assistant
C22: 701 Recruitment (Lisanne Kluinhaar (8701839)) | D22: Netherlands | E22: Netherlands (+31) | K22: Seasonal | W22: Undefined contract end date (Undetermined) | Y22: Part-time( PT ) | AQ22: Netherlands Retail Assistant Cash Office | AR22: Retail Assistant (18)
W23: Intern | Y23: Full-time( FT. ) | AR23: Retail Assistant (19)
C24: Retail - Central & Eastern Europe (Stephen Regan (9910010) (Inherited) | D24: Poland | E24: Poland (+48) | AR24: Retail Assistant (20)
C25: Retail Poland Area: Central Poland (Stephen Regan (9910010) (Inherited)) | D25: Poland | E25: Poland (+48) | AR25: Retail Assistant (21)
AR26: Retail Assistant (22)
AR27: Retail Assistant (23+)
AR28: Retail Assistant (Under 18)

Sheet RC. No
A1: D.O.B | B1: 35139 | C1: 33054 | D1: 31390 | F1: r col b | G1: r col c | H1: r col d
B2: 9603150007 | C2: 9006300006 | D2: 8512090004 | F2: =B2/11 -> 873013637 | G2: =C2/11 -> 818754546 | H2: =D2/11 -> 773826364
B3: =B2+11 -> 9603150018 | C3: =C2+11 -> 9006300017 | D3: =D2+11 -> 8512090015 | F3: =B3/11 -> 873013638 | G3: =C3/11 -> 818754547 | H3: =D3/11 -> 773826365
B4: =B3+11 -> 9603150029 | C4: =C3+11 -> 9006300028 | D4: =D3+11 -> 8512090026 | F4: =B4/11 -> 873013639 | G4: =C4/11 -> 818754548 | H4: =D4/11 -> 773826366
B5: =B4+11 -> 9603150040 | C5: =C4+11 -> 9006300039 | D5: =D4+11 -> 8512090037 | F5: =B5/11 -> 873013640 | G5: =C5/11 -> 818754549 | H5: =D5/11 -> 773826367
B6: =B5+11 -> 9603150051 | C6: =C5+11 -> 9006300050 | D6: =D5+11 -> 8512090048 | F6: =B6/11 -> 873013641 | G6: =C6/11 -> 818754550 | H6: =D6/11 -> 773826368
B7: =B6+11 -> 9603150062 | C7: =C6+11 -> 9006300061 | D7: =D6+11 -> 8512090059 | F7: =B7/11 -> 873013642 | G7: =C7/11 -> 818754551 | H7: =D7/11 -> 773826369
B8: =B7+11 -> 9603150073 | C8: =C7+11 -> 9006300072 | D8: =D7+11 -> 8512090070 | F8: =B8/11 -> 873013643 | G8: =C8/11 -> 818754552 | H8: =D8/11 -> 773826370
B9: =B8+11 -> 9603150084 | C9: =C8+11 -> 9006300083 | D9: =D8+11 -> 8512090081 | F9: =B9/11 -> 873013644 | G9: =C9/11 -> 818754553 | H9: =D9/11 -> 773826371
B10: =B9+11 -> 9603150095 | C10: =C9+11 -> 9006300094 | D10: =D9+11 -> 8512090092 | F10: =B10/11 -> 873013645 | G10: =C10/11 -> 818754554 | H10: =D10/11 -> 773826372
B11: =B10+11 -> 9603150106 | C11: =C10+11 -> 9006300105 | D11: =D10+11 -> 8512090103 | F11: =B11/11 -> 873013646 | G11: =C11/11 -> 818754555 | H11: =D11/11 -> 773826373
B12: =B11+11 -> 9603150117 | C12: =C11+11 -> 9006300116 | D12: =D11+11 -> 8512090114 | F12: =B12/11 -> 873013647 | G12: =C12/11 -> 818754556 | H12: =D12/11 -> 773826374
B13: =B12+11 -> 9603150128 | C13: =C12+11 -> 9006300127 | D13: =D12+11 -> 8512090125 | F13: =B13/11 -> 873013648 | G13: =C13/11 -> 818754557 | H13: =D13/11 -> 773826375
B14: =B13+11 -> 9603150139 | C14: =C13+11 -> 9006300138 | D14: =D13+11 -> 8512090136 | F14: =B14/11 -> 873013649 | G14: =C14/11 -> 818754558 | H14: =D14/11 -> 773826376
... B28: =B27+11 -> 9603150293 | C28: =C27+11 -> 9006300292 | D28: =D27+11 -> 8512090290 | F28: =B28/11 -> 873013663 | G28: =C28/11 -> 818754572 | H28: =D28/11 -> 773826390
B29: =B28+11 -> 9603150304
B30: =B29+11 -> 9603150315
B31: =B30+11 -> 9603150326
B32: =B31+11 -> 9603150337
B33: =B32+11 -> 9603150348
B34: =B33+11 -> 9603150359
B35: =B34+11 -> 9603150370
B36: =B35+11 -> 9603150381
B37: =B36+11 -> 9603150392
B38: =B37+11 -> 9603150403
B39: =B38+11 -> 9603150414
B40: =B39+11 -> 9603150425
... B75: =B74+11 -> 9603150810
B76: =B75+11 -> 9603150821 | X76: New RC Numbers
B77: =B76+11 -> 9603150832 | X77: 9202101337
B78: =B77+11 -> 9603150843 | X78: =SUM(X77)+11 -> 9202101348
B79: =B78+11 -> 9603150854 | X79: =SUM(X78)+11 -> 9202101359
B80: =B79+11 -> 9603150865 | X80: =SUM(X79)+11 -> 9202101370
B81: =B80+11 -> 9603150876 | X81: =SUM(X80)+11 -> 9202101381
B82: =B81+11 -> 9603150887 | X82: =SUM(X81)+11 -> 9202101392
B83: =B82+11 -> 9603150898 | X83: =SUM(X82)+11 -> 9202101403
B84: =B83+11 -> 9603150909 | X84: =SUM(X83)+11 -> 9202101414
B85: =B84+11 -> 9603150920 | X85: =SUM(X84)+11 -> 9202101425
B86: =B85+11 -> 9603150931 | D86: 9603170269 | X86: =SUM(X85)+11 -> 9202101436
D87: =D86+11 -> 9603170280 | F87: 9603170280 | H87: 9603170280 | I87: 9603170291 | J87: 9603170302 | K87: 9603170313 | L87: 9603170324 | M87: 9603170335 | N87: 9603170346 | O87: 9603170357 | P87: 9603170368 | Q87: 9603170379 | R87: 9603170390 | S87: 9603170401 | T87: 9603170412 | X87: =SUM(X86)+11 -> 9202101447
...

Sheet Code_Ranjeeta
B1: Variable Row | C1: Variable Value | D1: Row Number Declaration --------------------------------- intRowProcess = comExcelWorksheet.Range("Process").Row | E1: Value Declaration ------------------------ strProcess = comExcelWorksheet.Cells(intRowProcess, intColTestColumn).Value | F1: Getters
A2: =Test_Data!D3 -> Process | B2: ="Private intRow" & A2 -> Private intRowProcess | C2: ="Private str" & A2 -> Private strProcess | D2: ="intRow" & A2 & " = comExcelWorksheet.Range(""" & A2 & """).Row" -> intRowProcess = comExcelWorksheet.Range("Process").Row | E2: ="str" & A2 & " = comExcelWorksheet.Cells(intRow" & A2 & ", intColTestColumn).Value" -> strProcess = comExcelWorksheet.Cells(intRowProcess, intColTestColumn).Value | F2: ="Public Property Get get" & A2 & "() : get" & A2 & " = str" & A2 & " : End Property" -> Public Property Get getProcess() : getProcess = strProcess : End Property
A3: =Test_Data!D4 -> ExecutionFlag | B3: ="Private intRow" & A3 -> Private intRowExecutionFlag | C3: ="Private str" & A3 -> Private strExecutionFlag | D3: ="intRow" & A3 & " = comExcelWorksheet.Range(""" & A3 & """).Row" -> intRowExecutionFlag = comExcelWorksheet.Range("ExecutionFlag").Row | E3: ="str" & A3 & " = comExcelWorksheet.Cells(intRow" & A3 & ", intColTestColumn).Value" -> strExecutionFlag = comExcelWorksheet.Cells(intRowExecutionFlag, intColTestColumn).Value | F3: ="Public Property Get get" & A3 & "() : get" & A3 & " = str" & A3 & " : End Property" -> Public Property Get getExecutionFlag() : getExecutionFlag = strExecutionFlag : End Property
A4: =Test_Data!D5 -> DataValidationComplete | B4: ="Private intRow" & A4 -> Private intRowDataValidationComplete | C4: ="Private str" & A4 -> Private strDataValidationComplete | D4: ="intRow" & A4 & " = comExcelWorksheet.Range(""" & A4 & """).Row" -> intRowDataValidationComplete = comExcelWorksheet.Range("DataValidationComplete").Row | E4: ="str" & A4 & " = comExcelWorksheet.Cells(intRow" & A4 & ", intColTestColumn).Value" -> strDataValidationComplete = comExcelWorksheet.Cells(intRowDataValidationComplete, intColTestColumn).Value | F4: ="Public Property Get get" & A4 & "() : get" & A4 & " = str" & A4 & " : End Property" -> Public Property Get getDataValidationComplete() : getDataValidationComplete = strDataValidationComplete : End Property
A5: =Test_Data!D6 -> HireNameComplete | B5: ="Private intRow" & A5 -> Private intRowHireNameComplete | C5: ="Private str" & A5 -> Private strHireNameComplete | D5: ="intRow" & A5 & " = comExcelWorksheet.Range(""" & A5 & """).Row" -> intRowHireNameComplete = comExcelWorksheet.Range("HireNameComplete").Row | E5: ="str" & A5 & " = comExcelWorksheet.Cells(intRow" & A5 & ", intColTestColumn).Value" -> strHireNameComplete = comExcelWorksheet.Cells(intRowHireNameComplete, intColTestColumn).Value | F5: ="Public Property Get get" & A5 & "() : get" & A5 & " = str" & A5 & " : End Property" -> Public Property Get getHireNameComplete() : getHireNameComplete = strHireNameComplete : End Property
A6: =Test_Data!D7 -> 0 | B6: ="Private intRow" & A6 -> Private intRow0 | C6: ="Private str" & A6 -> Private str0 | D6: ="intRow" & A6 & " = comExcelWorksheet.Range(""" & A6 & """).Row" -> intRow0 = comExcelWorksheet.Range("0").Row | E6: ="str" & A6 & " = comExcelWorksheet.Cells(intRow" & A6 & ", intColTestColumn).Value" -> str0 = comExcelWorksheet.Cells(intRow0, intColTestColumn).Value | F6: ="Public Property Get get" & A6 & "() : get" & A6 & " = str" & A6 & " : End Property" -> Public Property Get get0() : get0 = str0 : End Property
A7: =Test_Data!D8 -> 0 | B7: ="Private intRow" & A7 -> Private intRow0 | C7: ="Private str" & A7 -> Private str0 | D7: ="intRow" & A7 & " = comExcelWorksheet.Range(""" & A7 & """).Row" -> intRow0 = comExcelWorksheet.Range("0").Row | E7: ="str" & A7 & " = comExcelWorksheet.Cells(intRow" & A7 & ", intColTestColumn).Value" -> str0 = comExcelWorksheet.Cells(intRow0, intColTestColumn).Value | F7: ="Public Property Get get" & A7 & "() : get" & A7 & " = str" & A7 & " : End Property" -> Public Property Get get0() : get0 = str0 : End Property
A8: =Test_Data!D9 -> LastRunErrorMessage | B8: ="Private intRow" & A8 -> Private intRowLastRunErrorMessage | C8: ="Private str" & A8 -> Private strLastRunErrorMessage | D8: ="intRow" & A8 & " = comExcelWorksheet.Range(""" & A8 & """).Row" -> intRowLastRunErrorMessage = comExcelWorksheet.Range("LastRunErrorMessage").Row | E8: ="str" & A8 & " = comExcelWorksheet.Cells(intRow" & A8 & ", intColTestColumn).Value" -> strLastRunErrorMessage = comExcelWorksheet.Cells(intRowLastRunErrorMessage, intColTestColumn).Value | F8: ="Public Property Get get" & A8 & "() : get" & A8 & " = str" & A8 & " : End Property" -> Public Property Get getLastRunErrorMessage() : getLastRunErrorMessage = strLastRunErrorMessage : End Property
A9: =Test_Data!D10 -> DefectDescription | B9: ="Private intRow" & A9 -> Private intRowDefectDescription | C9: ="Private str" & A9 -> Private strDefectDescription | D9: ="intRow" & A9 & " = comExcelWorksheet.Range(""" & A9 & """).Row" -> intRowDefectDescription = comExcelWorksheet.Range("DefectDescription").Row | E9: ="str" & A9 & " = comExcelWorksheet.Cells(intRow" & A9 & ", intColTestColumn).Value" -> strDefectDescription = comExcelWorksheet.Cells(intRowDefectDescription, intColTestColumn).Value | F9: ="Public Property Get get" & A9 & "() : get" & A9 & " = str" & A9 & " : End Property" -> Public Property Get getDefectDescription() : getDefectDescription = strDefectDescription : End Property
A10: =Test_Data!D11 -> AutomationComments | B10: ="Private intRow" & A10 -> Private intRowAutomationComments | C10: ="Private str" & A10 -> Private strAutomationComments | D10: ="intRow" & A10 & " = comExcelWorksheet.Range(""" & A10 & """).Row" -> intRowAutomationComments = comExcelWorksheet.Range("AutomationComments").Row | E10: ="str" & A10 & " = comExcelWorksheet.Cells(intRow" & A10 & ", intColTestColumn).Value" -> strAutomationComments = comExcelWorksheet.Cells(intRowAutomationComments, intColTestColumn).Value | F10: ="Public Property Get get" & A10 & "() : get" & A10 & " = str" & A10 & " : End Property" -> Public Property Get getAutomationComments() : getAutomationComments = strAutomationComments : End Property
A11: =Test_Data!D12 -> QAComments | B11: ="Private intRow" & A11 -> Private intRowQAComments | C11: ="Private str" & A11 -> Private strQAComments | D11: ="intRow" & A11 & " = comExcelWorksheet.Range(""" & A11 & """).Row" -> intRowQAComments = comExcelWorksheet.Range("QAComments").Row | E11: ="str" & A11 & " = comExcelWorksheet.Cells(intRow" & A11 & ", intColTestColumn).Value" -> strQAComments = comExcelWorksheet.Cells(intRowQAComments, intColTestColumn).Value | F11: ="Public Property Get get" & A11 & "() : get" & A11 & " = str" & A11 & " : End Property" -> Public Property Get getQAComments() : getQAComments = strQAComments : End Property
A12: =Test_Data!D13 -> 0 | B12: ="Private intRow" & A12 -> Private intRow0 | C12: ="Private str" & A12 -> Private str0 | D12: ="intRow" & A12 & " = comExcelWorksheet.Range(""" & A12 & """).Row" -> intRow0 = comExcelWorksheet.Range("0").Row | E12: ="str" & A12 & " = comExcelWorksheet.Cells(intRow" & A12 & ", intColTestColumn).Value" -> str0 = comExcelWorksheet.Cells(intRow0, intColTestColumn).Value | F12: ="Public Property Get get" & A12 & "() : get" & A12 & " = str" & A12 & " : End Property" -> Public Property Get get0() : get0 = str0 : End Property
A13: =Test_Data!D14 -> Automation Ref | B13: ="Private intRow" & A13 -> Private intRowAutomation Ref | C13: ="Private str" & A13 -> Private strAutomation Ref | D13: ="intRow" & A13 & " = comExcelWorksheet.Range(""" & A13 & """).Row" -> intRowAutomation Ref = comExcelWorksheet.Range("Automation Ref").Row | E13: ="str" & A13 & " = comExcelWorksheet.Cells(intRow" & A13 & ", intColTestColumn).Value" -> strAutomation Ref = comExcelWorksheet.Cells(intRowAutomation Ref, intColTestColumn).Value | F13: ="Public Property Get get" & A13 & "() : get" & A13 & " = str" & A13 & " : End Property" -> Public Property Get getAutomation Ref() : getAutomation Ref = strAutomation Ref : End Property
A14: =Test_Data!#REF! -> #REF! | B14: ="Private intRow" & A14 -> #REF! | C14: ="Private str" & A14 -> #REF! | D14: ="intRow" & A14 & " = comExcelWorksheet.Range(""" & A14 & """).Row" -> #REF! | E14: ="str" & A14 & " = comExcelWorksheet.Cells(intRow" & A14 & ", intColTestColumn).Value" -> #REF! | F14: ="Public Property Get get" & A14 & "() : get" & A14 & " = str" & A14 & " : End Property" -> #REF!
A15: =Test_Data!#REF! -> #REF! | B15: ="Private intRow" & A15 -> #REF! | C15: ="Private str" & A15 -> #REF! | D15: ="intRow" & A15 & " = comExcelWorksheet.Range(""" & A15 & """).Row" -> #REF! | E15: ="str" & A15 & " = comExcelWorksheet.Cells(intRow" & A15 & ", intColTestColumn).Value" -> #REF! | F15: ="Public Property Get get" & A15 & "() : get" & A15 & " = str" & A15 & " : End Property" -> #REF!
A16: =Test_Data!D15 -> SupervisoryOrganisation_SupervisoryOrganisation | B16: ="Private intRow" & A16 -> Private intRowSupervisoryOrganisation_SupervisoryOrganisation | C16: ="Private str" & A16 -> Private strSupervisoryOrganisation_SupervisoryOrganisation | D16: ="intRow" & A16 & " = comExcelWorksheet.Range(""" & A16 & """).Row" -> intRowSupervisoryOrganisation_SupervisoryOrganisation = comExcelWorksheet.Range("SupervisoryOrganisation_SupervisoryOrganisation").Row | E16: ="str" & A16 & " = comExcelWorksheet.Cells(intRow" & A16 & ", intColTestColumn).Value" -> strSupervisoryOrganisation_SupervisoryOrganisation = comExcelWorksheet.Cells(intRowSupervisoryOrganisation_SupervisoryOrganisation, intColTestColumn).Value | F16: ="Public Property Get get" & A16 & "() : get" & A16 & " = str" & A16 & " : End Property" -> Public Property Get getSupervisoryOrganisation_SupervisoryOrganisation() : getSupervisoryOrganisation_SupervisoryOrganisation = strSupervisoryOrganisation_SupervisoryOrganisation : End Property
A17: =Test_Data!D16 -> LegalNameInformation_Country | B17: ="Private intRow" & A17 -> Private intRowLegalNameInformation_Country | C17: ="Private str" & A17 -> Private strLegalNameInformation_Country | D17: ="intRow" & A17 & " = comExcelWorksheet.Range(""" & A17 & """).Row" -> intRowLegalNameInformation_Country = comExcelWorksheet.Range("LegalNameInformation_Country").Row | E17: ="str" & A17 & " = comExcelWorksheet.Cells(intRow" & A17 & ", intColTestColumn).Value" -> strLegalNameInformation_Country = comExcelWorksheet.Cells(intRowLegalNameInformation_Country, intColTestColumn).Value | F17: ="Public Property Get get" & A17 & "() : get" & A17 & " = str" & A17 & " : End Property" -> Public Property Get getLegalNameInformation_Country() : getLegalNameInformation_Country = strLegalNameInformation_Country : End Property
A18: =Test_Data!D17 -> LegalNameInformation_Prefix | B18: ="Private intRow" & A18 -> Private intRowLegalNameInformation_Prefix | C18: ="Private str" & A18 -> Private strLegalNameInformation_Prefix | D18: ="intRow" & A18 & " = comExcelWorksheet.Range(""" & A18 & """).Row" -> intRowLegalNameInformation_Prefix = comExcelWorksheet.Range("LegalNameInformation_Prefix").Row | E18: ="str" & A18 & " = comExcelWorksheet.Cells(intRow" & A18 & ", intColTestColumn).Value" -> strLegalNameInformation_Prefix = comExcelWorksheet.Cells(intRowLegalNameInformation_Prefix, intColTestColumn).Value | F18: ="Public Property Get get" & A18 & "() : get" & A18 & " = str" & A18 & " : End Property" -> Public Property Get getLegalNameInformation_Prefix() : getLegalNameInformation_Prefix = strLegalNameInformation_Prefix : End Property
A19: =Test_Data!D18 -> LegalNameInformation_GivenName | B19: ="Private intRow" & A19 -> Private intRowLegalNameInformation_GivenName | C19: ="Private str" & A19 -> Private strLegalNameInformation_GivenName | D19: ="intRow" & A19 & " = comExcelWorksheet.Range(""" & A19 & """).Row" -> intRowLegalNameInformation_GivenName = comExcelWorksheet.Range("LegalNameInformation_GivenName").Row | E19: ="str" & A19 & " = comExcelWorksheet.Cells(intRow" & A19 & ", intColTestColumn).Value" -> strLegalNameInformation_GivenName = comExcelWorksheet.Cells(intRowLegalNameInformation_GivenName, intColTestColumn).Value | F19: ="Public Property Get get" & A19 & "() : get" & A19 & " = str" & A19 & " : End Property" -> Public Property Get getLegalNameInformation_GivenName() : getLegalNameInformation_GivenName = strLegalNameInformation_GivenName : End Property
A20: =Test_Data!D19 -> LegalNameInformation_FamilyName | B20: ="Private intRow" & A20 -> Private intRowLegalNameInformation_FamilyName | C20: ="Private str" & A20 -> Private strLegalNameInformation_FamilyName | D20: ="intRow" & A20 & " = comExcelWorksheet.Range(""" & A20 & """).Row" -> intRowLegalNameInformation_FamilyName = comExcelWorksheet.Range("LegalNameInformation_FamilyName").Row | E20: ="str" & A20 & " = comExcelWorksheet.Cells(intRow" & A20 & ", intColTestColumn).Value" -> strLegalNameInformation_FamilyName = comExcelWorksheet.Cells(intRowLegalNameInformation_FamilyName, intColTestColumn).Value | F20: ="Public Property Get get" & A20 & "() : get" & A20 & " = str" & A20 & " : End Property" -> Public Property Get getLegalNameInformation_FamilyName() : getLegalNameInformation_FamilyName = strLegalNameInformation_FamilyName : End Property
A21: =Test_Data!D20 -> ContactInformation_Phone_PhoneNumber | B21: ="Private intRow" & A21 -> Private intRowContactInformation_Phone_PhoneNumber | C21: ="Private str" & A21 -> Private strContactInformation_Phone_PhoneNumber | D21: ="intRow" & A21 & " = comExcelWorksheet.Range(""" & A21 & """).Row" -> intRowContactInformation_Phone_PhoneNumber = comExcelWorksheet.Range("ContactInformation_Phone_PhoneNumber").Row | E21: ="str" & A21 & " = comExcelWorksheet.Cells(intRow" & A21 & ", intColTestColumn).Value" -> strContactInformation_Phone_PhoneNumber = comExcelWorksheet.Cells(intRowContactInformation_Phone_PhoneNumber, intColTestColumn).Value | F21: ="Public Property Get get" & A21 & "() : get" & A21 & " = str" & A21 & " : End Property" -> Public Property Get getContactInformation_Phone_PhoneNumber() : getContactInformation_Phone_PhoneNumber = strContactInformation_Phone_PhoneNumber : End Property
A22: =Test_Data!D21 -> ContactInformation_Phone_PhoneDevice | B22: ="Private intRow" & A22 -> Private intRowContactInformation_Phone_PhoneDevice | C22: ="Private str" & A22 -> Private strContactInformation_Phone_PhoneDevice | D22: ="intRow" & A22 & " = comExcelWorksheet.Range(""" & A22 & """).Row" -> intRowContactInformation_Phone_PhoneDevice = comExcelWorksheet.Range("ContactInformation_Phone_PhoneDevice").Row | E22: ="str" & A22 & " = comExcelWorksheet.Cells(intRow" & A22 & ", intColTestColumn).Value" -> strContactInformation_Phone_PhoneDevice = comExcelWorksheet.Cells(intRowContactInformation_Phone_PhoneDevice, intColTestColumn).Value | F22: ="Public Property Get get" & A22 & "() : get" & A22 & " = str" & A22 & " : End Property" -> Public Property Get getContactInformation_Phone_PhoneDevice() : getContactInformation_Phone_PhoneDevice = strContactInformation_Phone_PhoneDevice : End Property
A23: =Test_Data!D22 -> ContactInformation_Phone_Type | B23: ="Private intRow" & A23 -> Private intRowContactInformation_Phone_Type | C23: ="Private str" & A23 -> Private strContactInformation_Phone_Type | D23: ="intRow" & A23 & " = comExcelWorksheet.Range(""" & A23 & """).Row" -> intRowContactInformation_Phone_Type = comExcelWorksheet.Range("ContactInformation_Phone_Type").Row | E23: ="str" & A23 & " = comExcelWorksheet.Cells(intRow" & A23 & ", intColTestColumn).Value" -> strContactInformation_Phone_Type = comExcelWorksheet.Cells(intRowContactInformation_Phone_Type, intColTestColumn).Value | F23: ="Public Property Get get" & A23 & "() : get" & A23 & " = str" & A23 & " : End Property" -> Public Property Get getContactInformation_Phone_Type() : getContactInformation_Phone_Type = strContactInformation_Phone_Type : End Property
A24: =Test_Data!D23 -> ContactInformation_Address_EffectiveDate | B24: ="Private intRow" & A24 -> Private intRowContactInformation_Address_EffectiveDate | C24: ="Private str" & A24 -> Private strContactInformation_Address_EffectiveDate | D24: ="intRow" & A24 & " = comExcelWorksheet.Range(""" & A24 & """).Row" -> intRowContactInformation_Address_EffectiveDate = comExcelWorksheet.Range("ContactInformation_Address_EffectiveDate").Row | E24: ="str" & A24 & " = comExcelWorksheet.Cells(intRow" & A24 & ", intColTestColumn).Value" -> strContactInformation_Address_EffectiveDate = comExcelWorksheet.Cells(intRowContactInformation_Address_EffectiveDate, intColTestColumn).Value | F24: ="Public Property Get get" & A24 & "() : get" & A24 & " = str" & A24 & " : End Property" -> Public Property Get getContactInformation_Address_EffectiveDate() : getContactInformation_Address_EffectiveDate = strContactInformation_Address_EffectiveDate : End Property
A25: =Test_Data!D24 -> ContactInformation_Address_Country | B25: ="Private intRow" & A25 -> Private intRowContactInformation_Address_Country | C25: ="Private str" & A25 -> Private strContactInformation_Address_Country | D25: ="intRow" & A25 & " = comExcelWorksheet.Range(""" & A25 & """).Row" -> intRowContactInformation_Address_Country = comExcelWorksheet.Range("ContactInformation_Address_Country").Row | E25: ="str" & A25 & " = comExcelWorksheet.Cells(intRow" & A25 & ", intColTestColumn).Value" -> strContactInformation_Address_Country = comExcelWorksheet.Cells(intRowContactInformation_Address_Country, intColTestColumn).Value | F25: ="Public Property Get get" & A25 & "() : get" & A25 & " = str" & A25 & " : End Property" -> Public Property Get getContactInformation_Address_Country() : getContactInformation_Address_Country = strContactInformation_Address_Country : End Property
A26: =Test_Data!#REF! -> #REF! | B26: ="Private intRow" & A26 -> #REF! | C26: ="Private str" & A26 -> #REF! | D26: ="intRow" & A26 & " = comExcelWorksheet.Range(""" & A26 & """).Row" -> #REF! | E26: ="str" & A26 & " = comExcelWorksheet.Cells(intRow" & A26 & ", intColTestColumn).Value" -> #REF! | F26: ="Public Property Get get" & A26 & "() : get" & A26 & " = str" & A26 & " : End Property" -> #REF!
A27: =Test_Data!#REF! -> #REF! | B27: ="Private intRow" & A27 -> #REF! | C27: ="Private str" & A27 -> #REF! | D27: ="intRow" & A27 & " = comExcelWorksheet.Range(""" & A27 & """).Row" -> #REF! | E27: ="str" & A27 & " = comExcelWorksheet.Cells(intRow" & A27 & ", intColTestColumn).Value" -> #REF! | F27: ="Public Property Get get" & A27 & "() : get" & A27 & " = str" & A27 & " : End Property" -> #REF!
A28: =Test_Data!#REF! -> #REF! | B28: ="Private intRow" & A28 -> #REF! | C28: ="Private str" & A28 -> #REF! | D28: ="intRow" & A28 & " = comExcelWorksheet.Range(""" & A28 & """).Row" -> #REF! | E28: ="str" & A28 & " = comExcelWorksheet.Cells(intRow" & A28 & ", intColTestColumn).Value" -> #REF! | F28: ="Public Property Get get" & A28 & "() : get" & A28 & " = str" & A28 & " : End Property" -> #REF!
A29: =Test_Data!D27 -> ContactInformation_Address_PostalCode | B29: ="Private intRow" & A29 -> Private intRowContactInformation_Address_PostalCode | C29: ="Private str" & A29 -> Private strContactInformation_Address_PostalCode | D29: ="intRow" & A29 & " = comExcelWorksheet.Range(""" & A29 & """).Row" -> intRowContactInformation_Address_PostalCode = comExcelWorksheet.Range("ContactInformation_Address_PostalCode").Row | E29: ="str" & A29 & " = comExcelWorksheet.Cells(intRow" & A29 & ", intColTestColumn).Value" -> strContactInformation_Address_PostalCode = comExcelWorksheet.Cells(intRowContactInformation_Address_PostalCode, intColTestColumn).Value | F29: ="Public Property Get get" & A29 & "() : get" & A29 & " = str" & A29 & " : End Property" -> Public Property Get getContactInformation_Address_PostalCode() : getContactInformation_Address_PostalCode = strContactInformation_Address_PostalCode : End Property
A30: =Test_Data!D30 -> ContactInformation_Address_Municipality | B30: ="Private intRow" & A30 -> Private intRowContactInformation_Address_Municipality | C30: ="Private str" & A30 -> Private strContactInformation_Address_Municipality | D30: ="intRow" & A30 & " = comExcelWorksheet.Range(""" & A30 & """).Row" -> intRowContactInformation_Address_Municipality = comExcelWorksheet.Range("ContactInformation_Address_Municipality").Row | E30: ="str" & A30 & " = comExcelWorksheet.Cells(intRow" & A30 & ", intColTestColumn).Value" -> strContactInformation_Address_Municipality = comExcelWorksheet.Cells(intRowContactInformation_Address_Municipality, intColTestColumn).Value | F30: ="Public Property Get get" & A30 & "() : get" & A30 & " = str" & A30 & " : End Property" -> Public Property Get getContactInformation_Address_Municipality() : getContactInformation_Address_Municipality = strContactInformation_Address_Municipality : End Property
A31: =Test_Data!#REF! -> #REF! | B31: ="Private intRow" & A31 -> #REF! | C31: ="Private str" & A31 -> #REF! | D31: ="intRow" & A31 & " = comExcelWorksheet.Range(""" & A31 & """).Row" -> #REF! | E31: ="str" & A31 & " = comExcelWorksheet.Cells(intRow" & A31 & ", intColTestColumn).Value" -> #REF! | F31: ="Public Property Get get" & A31 & "() : get" & A31 & " = str" & A31 & " : End Property" -> #REF!
A32: =Test_Data!D31 -> ContactInformation_Address_District | B32: ="Private intRow" & A32 -> Private intRowContactInformation_Address_District | C32: ="Private str" & A32 -> Private strContactInformation_Address_District | D32: ="intRow" & A32 & " = comExcelWorksheet.Range(""" & A32 & """).Row" -> intRowContactInformation_Address_District = comExcelWorksheet.Range("ContactInformation_Address_District").Row | E32: ="str" & A32 & " = comExcelWorksheet.Cells(intRow" & A32 & ", intColTestColumn).Value" -> strContactInformation_Address_District = comExcelWorksheet.Cells(intRowContactInformation_Address_District, intColTestColumn).Value | F32: ="Public Property Get get" & A32 & "() : get" & A32 & " = str" & A32 & " : End Property" -> Public Property Get getContactInformation_Address_District() : getContactInformation_Address_District = strContactInformation_Address_District : End Property
A33: =Test_Data!D32 -> ContactInformation_Address_Type | B33: ="Private intRow" & A33 -> Private intRowContactInformation_Address_Type | C33: ="Private str" & A33 -> Private strContactInformation_Address_Type | D33: ="intRow" & A33 & " = comExcelWorksheet.Range(""" & A33 & """).Row" -> intRowContactInformation_Address_Type = comExcelWorksheet.Range("ContactInformation_Address_Type").Row | E33: ="str" & A33 & " = comExcelWorksheet.Cells(intRow" & A33 & ", intColTestColumn).Value" -> strContactInformation_Address_Type = comExcelWorksheet.Cells(intRowContactInformation_Address_Type, intColTestColumn).Value | F33: ="Public Property Get get" & A33 & "() : get" & A33 & " = str" & A33 & " : End Property" -> Public Property Get getContactInformation_Address_Type() : getContactInformation_Address_Type = strContactInformation_Address_Type : End Property
A34: =Test_Data!D33 -> ContactInformation_Email_UseFor | B34: ="Private intRow" & A34 -> Private intRowContactInformation_Email_UseFor | C34: ="Private str" & A34 -> Private strContactInformation_Email_UseFor | D34: ="intRow" & A34 & " = comExcelWorksheet.Range(""" & A34 & """).Row" -> intRowContactInformation_Email_UseFor = comExcelWorksheet.Range("ContactInformation_Email_UseFor").Row | E34: ="str" & A34 & " = comExcelWorksheet.Cells(intRow" & A34 & ", intColTestColumn).Value" -> strContactInformation_Email_UseFor = comExcelWorksheet.Cells(intRowContactInformation_Email_UseFor, intColTestColumn).Value | F34: ="Public Property Get get" & A34 & "() : get" & A34 & " = str" & A34 & " : End Property" -> Public Property Get getContactInformation_Email_UseFor() : getContactInformation_Email_UseFor = strContactInformation_Email_UseFor : End Property
A35: =Test_Data!D34 -> ContactInformation_Email_EmailAddress | B35: ="Private intRow" & A35 -> Private intRowContactInformation_Email_EmailAddress | C35: ="Private str" & A35 -> Private strContactInformation_Email_EmailAddress | D35: ="intRow" & A35 & " = comExcelWorksheet.Range(""" & A35 & """).Row" -> intRowContactInformation_Email_EmailAddress = comExcelWorksheet.Range("ContactInformation_Email_EmailAddress").Row | E35: ="str" & A35 & " = comExcelWorksheet.Cells(intRow" & A35 & ", intColTestColumn).Value" -> strContactInformation_Email_EmailAddress = comExcelWorksheet.Cells(intRowContactInformation_Email_EmailAddress, intColTestColumn).Value | F35: ="Public Property Get get" & A35 & "() : get" & A35 & " = str" & A35 & " : End Property" -> Public Property Get getContactInformation_Email_EmailAddress() : getContactInformation_Email_EmailAddress = strContactInformation_Email_EmailAddress : End Property
A36: =Test_Data!D35 -> JobDetails_Type | B36: ="Private intRow" & A36 -> Private intRowJobDetails_Type | C36: ="Private str" & A36 -> Private strJobDetails_Type | D36: ="intRow" & A36 & " = comExcelWorksheet.Range(""" & A36 & """).Row" -> intRowJobDetails_Type = comExcelWorksheet.Range("JobDetails_Type").Row | E36: ="str" & A36 & " = comExcelWorksheet.Cells(intRow" & A36 & ", intColTestColumn).Value" -> strJobDetails_Type = comExcelWorksheet.Cells(intRowJobDetails_Type, intColTestColumn).Value | F36: ="Public Property Get get" & A36 & "() : get" & A36 & " = str" & A36 & " : End Property" -> Public Property Get getJobDetails_Type() : getJobDetails_Type = strJobDetails_Type : End Property
A37: =Test_Data!#REF! -> #REF! | B37: ="Private intRow" & A37 -> #REF! | C37: ="Private str" & A37 -> #REF! | D37: ="intRow" & A37 & " = comExcelWorksheet.Range(""" & A37 & """).Row" -> #REF! | E37: ="str" & A37 & " = comExcelWorksheet.Cells(intRow" & A37 & ", intColTestColumn).Value" -> #REF! | F37: ="Public Property Get get" & A37 & "() : get" & A37 & " = str" & A37 & " : End Property" -> #REF!
A38: =Test_Data!D36 -> JobDetails_HireDate | B38: ="Private intRow" & A38 -> Private intRowJobDetails_HireDate | C38: ="Private str" & A38 -> Private strJobDetails_HireDate | D38: ="intRow" & A38 & " = comExcelWorksheet.Range(""" & A38 & """).Row" -> intRowJobDetails_HireDate = comExcelWorksheet.Range("JobDetails_HireDate").Row | E38: ="str" & A38 & " = comExcelWorksheet.Cells(intRow" & A38 & ", intColTestColumn).Value" -> strJobDetails_HireDate = comExcelWorksheet.Cells(intRowJobDetails_HireDate, intColTestColumn).Value | F38: ="Public Property Get get" & A38 & "() : get" & A38 & " = str" & A38 & " : End Property" -> Public Property Get getJobDetails_HireDate() : getJobDetails_HireDate = strJobDetails_HireDate : End Property
A39: =Test_Data!D37 -> JobDetails_Reason | B39: ="Private intRow" & A39 -> Private intRowJobDetails_Reason | C39: ="Private str" & A39 -> Private strJobDetails_Reason | D39: ="intRow" & A39 & " = comExcelWorksheet.Range(""" & A39 & """).Row" -> intRowJobDetails_Reason = comExcelWorksheet.Range("JobDetails_Reason").Row | E39: ="str" & A39 & " = comExcelWorksheet.Cells(intRow" & A39 & ", intColTestColumn).Value" -> strJobDetails_Reason = comExcelWorksheet.Cells(intRowJobDetails_Reason, intColTestColumn).Value | F39: ="Public Property Get get" & A39 & "() : get" & A39 & " = str" & A39 & " : End Property" -> Public Property Get getJobDetails_Reason() : getJobDetails_Reason = strJobDetails_Reason : End Property
A40: =Test_Data!D38 -> JobDetails_Position | B40: ="Private intRow" & A40 -> Private intRowJobDetails_Position | C40: ="Private str" & A40 -> Private strJobDetails_Position | D40: ="intRow" & A40 & " = comExcelWorksheet.Range(""" & A40 & """).Row" -> intRowJobDetails_Position = comExcelWorksheet.Range("JobDetails_Position").Row | E40: ="str" & A40 & " = comExcelWorksheet.Cells(intRow" & A40 & ", intColTestColumn).Value" -> strJobDetails_Position = comExcelWorksheet.Cells(intRowJobDetails_Position, intColTestColumn).Value | F40: ="Public Property Get get" & A40 & "() : get" & A40 & " = str" & A40 & " : End Property" -> Public Property Get getJobDetails_Position() : getJobDetails_Position = strJobDetails_Position : End Property
...

Sheet Code_11122019_1000
B1: Variable Row | C1: Variable Row Combined | D1: Variable Value | E1: Variable Value Combined | F1: Row Number Declaration --------------------------------- intRowProcess = comExcelWorksheet.Range("Process").Row | G1: Value Declaration ------------------------ strProcess = comExcelWorksheet.Cells(intRowProcess, intColTestColumn).Value | H1: Getters
A2: =Test_Data!D3 -> Process | B2: ="intRow" & A2 & ", " -> intRowProcess, | C2: =B2 -> intRowProcess, | D2: ="str" & A2 & ", " -> strProcess, | E2: =D2 -> strProcess, | F2: ="intRow" & A2 & " = comExcelWorksheet.Range(""" & A2 & """).Row" -> intRowProcess = comExcelWorksheet.Range("Process").Row | G2: ="str" & A2 & " = comExcelWorksheet.Cells(intRow" & A2 & ", intColTestColumn).Value" -> strProcess = comExcelWorksheet.Cells(intRowProcess, intColTestColumn).Value | H2: ="Public Property Get get" & A2 & "() : get" & A2 & " = str" & A2 & " : End Property" -> Public Property Get getProcess() : getProcess = strProcess : End Property
A3: =Test_Data!D4 -> ExecutionFlag | B3: ="intRow" & A3 & ", " -> intRowExecutionFlag, | C3: =C2 &B3 -> intRowProcess, intRowExecutionFlag, | D3: ="str" & A3 & ", " -> strExecutionFlag, | E3: =E2 &D3 -> strProcess, strExecutionFlag, | F3: ="intRow" & A3 & " = comExcelWorksheet.Range(""" & A3 & """).Row" -> intRowExecutionFlag = comExcelWorksheet.Range("ExecutionFlag").Row | G3: ="str" & A3 & " = comExcelWorksheet.Cells(intRow" & A3 & ", intColTestColumn).Value" -> strExecutionFlag = comExcelWorksheet.Cells(intRowExecutionFlag, intColTestColumn).Value | H3: ="Public Property Get get" & A3 & "() : get" & A3 & " = str" & A3 & " : End Property" -> Public Property Get getExecutionFlag() : getExecutionFlag = strExecutionFlag : End Property
A4: =Test_Data!D5 -> DataValidationComplete | B4: ="intRow" & A4 & ", " -> intRowDataValidationComplete, | C4: =C3 &B4 -> intRowProcess, intRowExecutionFlag, intRowDataValidationComplete, | D4: ="str" & A4 & ", " -> strDataValidationComplete, | E4: =E3 &D4 -> strProcess, strExecutionFlag, strDataValidationComplete, | F4: ="intRow" & A4 & " = comExcelWorksheet.Range(""" & A4 & """).Row" -> intRowDataValidationComplete = comExcelWorksheet.Range("DataValidationComplete").Row | G4: ="str" & A4 & " = comExcelWorksheet.Cells(intRow" & A4 & ", intColTestColumn).Value" -> strDataValidationComplete = comExcelWorksheet.Cells(intRowDataValidationComplete, intColTestColumn).Value | H4: ="Public Property Get get" & A4 & "() : get" & A4 & " = str" & A4 & " : End Property" -> Public Property Get getDataValidationComplete() : getDataValidationComplete = strDataValidationComplete : End Property
A5: =Test_Data!D6 -> HireNameComplete | B5: ="intRow" & A5 & ", " -> intRowHireNameComplete, | C5: =C4 &B5 -> intRowProcess, intRowExecutionFlag, intRowDataValidationComplete, intRowHireNameComplete, | D5: ="str" & A5 & ", " -> strHireNameComplete, | E5: =E4 &D5 -> strProcess, strExecutionFlag, strDataValidationComplete, strHireNameComplete, | F5: ="intRow" & A5 & " = comExcelWorksheet.Range(""" & A5 & """).Row" -> intRowHireNameComplete = comExcelWorksheet.Range("HireNameComplete").Row | G5: ="str" & A5 & " = comExcelWorksheet.Cells(intRow" & A5 & ", intColTestColumn).Value" -> strHireNameComplete = comExcelWorksheet.Cells(intRowHireNameComplete, intColTestColumn).Value | H5: ="Public Property Get get" & A5 & "() : get" & A5 & " = str" & A5 & " : End Property" -> Public Property Get getHireNameComplete() : getHireNameComplete = strHireNameComplete : End Property
A6: =Test_Data!D7 -> 0 | B6: ="intRow" & A6 & ", " -> intRow0, | C6: =C5 &B6 -> intRowProcess, intRowExecutionFlag, intRowDataValidationComplete, intRowHireNameComplete, intRow0, | D6: ="str" & A6 & ", " -> str0, | E6: =E5 &D6 -> strProcess, strExecutionFlag, strDataValidationComplete, strHireNameComplete, str0, | F6: ="intRow" & A6 & " = comExcelWorksheet.Range(""" & A6 & """).Row" -> intRow0 = comExcelWorksheet.Range("0").Row | G6: ="str" & A6 & " = comExcelWorksheet.Cells(intRow" & A6 & ", intColTestColumn).Value" -> str0 = comExcelWorksheet.Cells(intRow0, intColTestColumn).Value | H6: ="Public Property Get get" & A6 & "() : get" & A6 & " = str" & A6 & " : End Property" -> Public Property Get get0() : get0 = str0 : End Property
A7: =Test_Data!D8 -> 0 | B7: ="intRow" & A7 & ", " -> intRow0, | C7: =C6 &B7 -> intRowProcess, intRowExecutionFlag, intRowDataValidationComplete, intRowHireNameComplete, intRow0, intRow0, | D7: ="str" & A7 & ", " -> str0, | E7: =E6 &D7 -> strProcess, strExecutionFlag, strDataValidationComplete, strHireNameComplete, str0, str0, | F7: ="intRow" & A7 & " = comExcelWorksheet.Range(""" & A7 & """).Row" -> intRow0 = comExcelWorksheet.Range("0").Row | G7: ="str" & A7 & " = comExcelWorksheet.Cells(intRow" & A7 & ", intColTestColumn).Value" -> str0 = comExcelWorksheet.Cells(intRow0, intColTestColumn).Value | H7: ="Public Property Get get" & A7 & "() : get" & A7 & " = str" & A7 & " : End Property" -> Public Property Get get0() : get0 = str0 : End Property
A8: =Test_Data!D9 -> LastRunErrorMessage | B8: ="intRow" & A8 & ", " -> intRowLastRunErrorMessage, | C8: =C7 &B8 -> intRowProcess, intRowExecutionFlag, intRowDataValidationComplete, intRowHireNameComplete, intRow0, intRow0, intRowLastRunErrorMessage, | D8: ="str" & A8 & ", " -> strLastRunErrorMessage, | E8: =E7 &D8 -> strProcess, strExecutionFlag, strDataValidationComplete, strHireNameComplete, str0, str0, strLastRunErrorMessage, | F8: ="intRow" & A8 & " = comExcelWorksheet.Range(""" & A8 & """).Row" -> intRowLastRunErrorMessage = comExcelWorksheet.Range("LastRunErrorMessage").Row | G8: ="str" & A8 & " = comExcelWorksheet.Cells(intRow" & A8 & ", intColTestColumn).Value" -> strLastRunErrorMessage = comExcelWorksheet.Cells(intRowLastRunErrorMessage, intColTestColumn).Value | H8: ="Public Property Get get" & A8 & "() : get" & A8 & " = str" & A8 & " : End Property" -> Public Property Get getLastRunErrorMessage() : getLastRunErrorMessage = strLastRunErrorMessage : End Property
A9: =Test_Data!D10 -> DefectDescription | B9: ="intRow" & A9 & ", " -> intRowDefectDescription, | C9: =C8 &B9 -> intRowProcess, intRowExecutionFlag, intRowDataValidationComplete, intRowHireNameComplete, intRow0, intRow0, intRowLastRunErrorMessage, intRowDefectDescription, | D9: ="str" & A9 & ", " -> strDefectDescription, | E9: =E8 &D9 -> strProcess, strExecutionFlag, strDataValidationComplete, strHireNameComplete, str0, str0, strLastRunErrorMessage, strDefectDescription, | F9: ="intRow" & A9 & " = comExcelWorksheet.Range(""" & A9 & """).Row" -> intRowDefectDescription = comExcelWorksheet.Range("DefectDescription").Row | G9: ="str" & A9 & " = comExcelWorksheet.Cells(intRow" & A9 & ", intColTestColumn).Value" -> strDefectDescription = comExcelWorksheet.Cells(intRowDefectDescription, intColTestColumn).Value | H9: ="Public Property Get get" & A9 & "() : get" & A9 & " = str" & A9 & " : End Property" -> Public Property Get getDefectDescription() : getDefectDescription = strDefectDescription : End Property
A10: =Test_Data!D11 -> AutomationComments | B10: ="intRow" & A10 & ", " -> intRowAutomationComments, | C10: =C9 &B10 -> intRowProcess, intRowExecutionFlag, intRowDataValidationComplete, intRowHireNameComplete, intRow0, intRow0, intRowLastRunErrorMessage, intRowDefectDescription, intRowAutomationComments, | D10: ="str" & A10 & ", " -> strAutomationComments, | E10: =E9 &D10 -> strProcess, strExecutionFlag, strDataValidationComplete, strHireNameComplete, str0, str0, strLastRunErrorMessage, strDefectDescription, strAutomationComments, | F10: ="intRow" & A10 & " = comExcelWorksheet.Range(""" & A10 & """).Row" -> intRowAutomationComments = comExcelWorksheet.Range("AutomationComments").Row | G10: ="str" & A10 & " = comExcelWorksheet.Cells(intRow" & A10 & ", intColTestColumn).Value" -> strAutomationComments = comExcelWorksheet.Cells(intRowAutomationComments, intColTestColumn).Value | H10: ="Public Property Get get" & A10 & "() : get" & A10 & " = str" & A10 & " : End Property" -> Public Property Get getAutomationComments() : getAutomationComments = strAutomationComments : End Property
A11: =Test_Data!D12 -> QAComments | B11: ="intRow" & A11 & ", " -> intRowQAComments, | C11: =C10 &B11 -> intRowProcess, intRowExecutionFlag, intRowDataValidationComplete, intRowHireNameComplete, intRow0, intRow0, intRowLastRunErrorMessage, intRowDefectDescription, intRowAutomationComments, intRowQAComments, | D11: ="str" & A11 & ", " -> strQAComments, | E11: =E10 &D11 -> strProcess, strExecutionFlag, strDataValidationComplete, strHireNameComplete, str0, str0, strLastRunErrorMessage, strDefectDescription, strAutomationComments, strQAComments, | F11: ="intRow" & A11 & " = comExcelWorksheet.Range(""" & A11 & """).Row" -> intRowQAComments = comExcelWorksheet.Range("QAComments").Row | G11: ="str" & A11 & " = comExcelWorksheet.Cells(intRow" & A11 & ", intColTestColumn).Value" -> strQAComments = comExcelWorksheet.Cells(intRowQAComments, intColTestColumn).Value | H11: ="Public Property Get get" & A11 & "() : get" & A11 & " = str" & A11 & " : End Property" -> Public Property Get getQAComments() : getQAComments = strQAComments : End Property
A12: =Test_Data!D13 -> 0 | B12: ="intRow" & A12 & ", " -> intRow0, | C12: =C11 &B12 -> intRowProcess, intRowExecutionFlag, intRowDataValidationComplete, intRowHireNameComplete, intRow0, intRow0, intRowLastRunErrorMessage, intRowDefectDescription, intRowAutomationComments, intRowQAComments, intRow0, | D12: ="str" & A12 & ", " -> str0, | E12: =E11 &D12 -> strProcess, strExecutionFlag, strDataValidationComplete, strHireNameComplete, str0, str0, strLastRunErrorMessage, strDefectDescription, strAutomationComments, strQAComments, str0, | F12: ="intRow" & A12 & " = comExcelWorksheet.Range(""" & A12 & """).Row" -> intRow0 = comExcelWorksheet.Range("0").Row | G12: ="str" & A12 & " = comExcelWorksheet.Cells(intRow" & A12 & ", intColTestColumn).Value" -> str0 = comExcelWorksheet.Cells(intRow0, intColTestColumn).Value | H12: ="Public Property Get get" & A12 & "() : get" & A12 & " = str" & A12 & " : End Property" -> Public Property Get get0() : get0 = str0 : End Property
A13: =Test_Data!D14 -> Automation Ref | B13: ="intRow" & A13 & ", " -> intRowAutomation Ref, | C13: =C12 &B13 -> intRowProcess, intRowExecutionFlag, intRowDataValidationComplete, intRowHireNameComplete, intRow0, intRow0, intRowLastRunErrorMessage, intRowDefectDescription, intRowAutomationComments, intRowQAComments, intRow0, intRowAutomation Ref, | D13: ="str" & A13 & ", " -> strAutomation Ref, | E13: =E12 &D13 -> strProcess, strExecutionFlag, strDataValidationComplete, strHireNameComplete, str0, str0, strLastRunErrorMessage, strDefectDescription, strAutomationComments, strQAComments, str0, strAutomation Ref, | F13: ="intRow" & A13 & " = comExcelWorksheet.Range(""" & A13 & """).Row" -> intRowAutomation Ref = comExcelWorksheet.Range("Automation Ref").Row | G13: ="str" & A13 & " = comExcelWorksheet.Cells(intRow" & A13 & ", intColTestColumn).Value" -> strAutomation Ref = comExcelWorksheet.Cells(intRowAutomation Ref, intColTestColumn).Value | H13: ="Public Property Get get" & A13 & "() : get" & A13 & " = str" & A13 & " : End Property" -> Public Property Get getAutomation Ref() : getAutomation Ref = strAutomation Ref : End Property
A14: =Test_Data!#REF! -> #REF! | B14: ="intRow" & A14 & ", " -> #REF! | C14: =C13 &B14 -> #REF! | D14: ="str" & A14 & ", " -> #REF! | E14: =E13 &D14 -> #REF! | F14: ="intRow" & A14 & " = comExcelWorksheet.Range(""" & A14 & """).Row" -> #REF! | G14: ="str" & A14 & " = comExcelWorksheet.Cells(intRow" & A14 & ", intColTestColumn).Value" -> #REF! | H14: ="Public Property Get get" & A14 & "() : get" & A14 & " = str" & A14 & " : End Property" -> #REF!
A15: =Test_Data!#REF! -> #REF! | B15: ="intRow" & A15 & ", " -> #REF! | C15: =C14 &B15 -> #REF! | D15: ="str" & A15 & ", " -> #REF! | E15: =E14 &D15 -> #REF! | F15: ="intRow" & A15 & " = comExcelWorksheet.Range(""" & A15 & """).Row" -> #REF! | G15: ="str" & A15 & " = comExcelWorksheet.Cells(intRow" & A15 & ", intColTestColumn).Value" -> #REF! | H15: ="Public Property Get get" & A15 & "() : get" & A15 & " = str" & A15 & " : End Property" -> #REF!
A16: =Test_Data!D15 -> SupervisoryOrganisation_SupervisoryOrganisation | B16: ="intRow" & A16 & ", " -> intRowSupervisoryOrganisation_SupervisoryOrganisation, | C16: =C15 &B16 -> #REF! | D16: ="str" & A16 & ", " -> strSupervisoryOrganisation_SupervisoryOrganisation, | E16: =E15 &D16 -> #REF! | F16: ="intRow" & A16 & " = comExcelWorksheet.Range(""" & A16 & """).Row" -> intRowSupervisoryOrganisation_SupervisoryOrganisation = comExcelWorksheet.Range("SupervisoryOrganisation_SupervisoryOrganisation").Row | G16: ="str" & A16 & " = comExcelWorksheet.Cells(intRow" & A16 & ", intColTestColumn).Value" -> strSupervisoryOrganisation_SupervisoryOrganisation = comExcelWorksheet.Cells(intRowSupervisoryOrganisation_SupervisoryOrganisation, intColTestColumn).Value | H16: ="Public Property Get get" & A16 & "() : get" & A16 & " = str" & A16 & " : End Property" -> Public Property Get getSupervisoryOrganisation_SupervisoryOrganisation() : getSupervisoryOrganisation_SupervisoryOrganisation = strSupervisoryOrganisation_SupervisoryOrganisation : End Property
